Workbook

Sheet README
A1: README — Master Regression Template (มาตรฐานทีม QA)
A2: คู่มือการใช้งาน File และเงื่อนไขการคำนวณอัตโนมัติ — อ่านก่อนเริ่มลงผล | Version เอกสาร 1.0 | อัปเดตล่าสุด: 2026-09-29
A4: 1. โครงสร้าง File
A5: Sheet | B5: หน้าที่
A6: Dashboard | B6: สรุปผลของทั้ง 3 Sheet, Release Decision (READY / NOT READY / NO-GO), Risk Level, Defect Summary, Tester Workload, Module Risk — คำนวณอัตโนมัติ ห้ามแก้ (ยกเว้น Environment Sign-off และ Risk Log)
A7: E2E core flow | B7: Test Scenario หลัก (Flow-based Regression) — QA ลงผลการทดสอบที่นี่
A8: Cards | B8: การ์ด (Linear) ที่ Release ใน Version นี้ + การ์ดที่ต้อง Retest จาก Version ก่อน · Map เข้ากับ Scenario ใน E2E · QA Site ตัดสิน Card Result ที่นี่
A9: Card Test Cases | B9: รายการ Test Case ของการ์ดแบบย่อ (1 แถว = 1 TC: ID, ชื่อ, ผล, Tester, วันที่, Defect ID) — ใช้ดูความคืบหน้า ส่วนรายละเอียด Step อยู่ในไฟล์ TC ของการ์ด
A10: Ownership Matrix | B10: ตารางทีมเจ้าของ ต่อ Module / Feature — PO / BA ดูแล ใช้หาว่า Bug ต้องส่งให้ทีมไหน และเป็นรายชื่อ Module ของ Dashboard หัวข้อ 10
A11: README | B11: คู่มือนี้
A13: 2. Priority และ Severity (มาตรฐานเดียวกันทั้ง File และ Linear)
A14: ค่า | B14: ความหมาย
A15: Severity (ความรุนแรงของ Bug) | B15: Critical / High / Medium / Low — ตาม SOP-QA-CORTEX-01 (Critical = Patient Safety / Financial Leakage / Workflow หยุดชะงัก / Data Corruption)
A16: Priority (ลำดับความสำคัญ) | B16: Urgent / High / Medium / Low — ตรงกับ Priority ใน Linear ใช้กับ Flow Priority (E2E L), Card Priority (Cards F), Bug Priority และ Risk Level
A17: Bug Priority = Severity × Impact | B17: Critical: Urgent Urgent High High · High: Urgent High High Medium · Medium: High High Medium Medium · Low: Medium Medium Low Low (Impact เรียงเป็น Extensive · Significant · Moderate · Minor)
A18: SLA ของ Bug Priority | B18: Urgent = แก้ทันที (Hotfix) · High = แก้ก่อนปิด Sprint · Medium = Sprint ถัดไป · Low = เมื่อมีเวลา / รวมกับงาน UI
A19: Priority ว่าง | B19: นับเป็น Urgent / High ไว้ก่อนเพื่อความปลอดภัย และไฮไลต์แดง — QA Site / BA ต้องกรอกให้ครบภายใน Day 0
A21: 3. กฎการกรอกข้อมูล (สำคัญ)
A22: หัวข้อ | B22: รายละเอียด
A23: ช่องพื้นสีเทา = สูตร | B23: ห้ามพิมพ์หรือ Paste ทับ: E2E Column G, R, W, Y, Z และ D4–D6 | Cards Column G, L–S | Card Test Cases Column C, D | Dashboard ทั้งหมด (ยกเว้นหัวข้อ 4 และ 5)
A24: เพิ่มแถวใหม่ | B24: พิมพ์ต่อท้ายในแถวว่างถัดไป สูตรจะคำนวณให้ทันทีเมื่อใส่ ID ในคอลัมน์ A ห้ามใช้ Insert Row แทรกระหว่างแถว เพราะแถวที่แทรกจะไม่มีสูตร — ถ้าจำเป็นต้องแทรก ให้ Copy ช่องสูตรจากแถวด้านบนลงมา
A25: Copy ข้อมูล | B25: Paste เฉพาะช่องที่ต้องกรอก ห้าม Paste ทั้งแถว เพราะจะทับสูตรในช่องสีเทา
A26: ขอบเขตข้อมูล | B26: สูตรและ Dropdown รองรับถึงแถว 1000 (E2E: แถว 15–1000 | Cards: แถว 4–1000 | Card Test Cases: แถว 4–1000) หากใกล้เต็มให้แจ้งผู้ดูแล File ขยายช่วง
A27: Tested Environment | B27: เลือกที่ E2E › B4 ครั้งเดียวต่อรอบ (demo-x / stg-tmh / stg-sbh / stg-nuh) — 1 File = 1 Environment
A28: Link SOP | B28: วาง URL ที่ E2E › C12 แล้ว Link ที่ A12 จะคลิกได้อัตโนมัติ
A29: โปรแกรมที่รองรับ | B29: Excel 365 / Excel Web — สูตรใช้ LET, FILTER, UNIQUE, SORT, VSTACK, HSTACK, TEXTJOIN ถ้าเปิดด้วย Excel 2019 หรือเก่ากว่าจะขึ้น #NAME? หลีกเลี่ยงการเปิดใน Google Sheets แล้ว Export กลับมาทับ File Master
A30: การป้องกัน (Protect) | B30: E2E, Cards และ Card Test Cases ถูก Protect ไว้ (ไม่มีรหัสผ่าน) — ล็อกเฉพาะ Priority (E2E L, Cards F), TOR (Cards H) และช่องสูตรของ Cards / Card Test Cases | แก้โครงสร้าง: Review › Unprotect Sheet แล้ว Protect กลับ
A32: 4. การลงผลใน E2E core flow
A33: Column | B33: วิธีกรอก
A34: สีหัวตาราง | B34: 🟦 น้ำเงิน (A–L) = Static Prep ที่ QA Site / BA เตรียมไว้ · 🟨 เหลือง (M–V, X) = Execution ที่ QA กรอกระหว่างรัน · ⬛ เทา (R, W, Y, Z) = Auto
A35: A — Scenario ID | B35: รหัส Scenario เช่น SMK-OPD-001 ต้องไม่ซ้ำ และใช้เลขรันจำนวนหลักเท่ากันทุกข้อ
A36: B — Module | B36: ต้องตรงกับชื่อ Module ใน Ownership Matrix (ใช้หา Owner Team, Module ของการ์ด และ Module Risk)
A37: L — Flow Priority | B37: Urgent / High / Medium / Low — QA Site / BA กรอกให้ครบตั้งแต่ Day 0 (ว่าง = ไฮไลต์แดง และนับเป็น Urgent / High) ใช้ร่วมกับ Card Priority ของการ์ดที่ผูกอยู่ เมื่อพบ Bug ระบบใช้ค่าที่สูงที่สุด (Highest Priority Wins)
A38: M — Execution Status | B38: ToDo → Ready for Testing → Testing → Done | Blocked = รันต่อไม่ได้ | Out of Scope / Canceled = ไม่นับในรอบนี้ ห้ามใช้ Passed / Failed ในคอลัมน์นี้ — ผลคุณภาพดูที่ Column W
A39: O — Defect ID | B39: ใส่ ID ของทุก Bug ที่พบใน Scenario นี้ (Issue ของ Site ตาม Case C ในหัวข้อ 8) — ถ้ามีหลาย ID ให้คั่นด้วย , (Risk Log จับคู่ได้เฉพาะช่องที่มี ID เดียว)
A40: P / Q — Severity / Impact | B40: กรอกเมื่อมี Defect ID (ช่องจะเป็นสีแดงอ่อน) — ถ้ายังไม่กรอก Bug Priority จะขึ้น "ระบุ Severity + Impact" และนับเป็น Blocking ไว้ก่อน
A41: R — Bug Priority (Auto) | B41: Severity × Impact → Urgent / High / Medium / Low ตาม Matrix ในหัวข้อ 2
A42: S / T — Root Cause / Defect Status | B42: Root Cause: Config / Master Data / Code Bug | Defect Status: Open (หรือว่าง) = ยังเปิด · Fixed – Retest Passed = ผ่าน Direct Fix + Impact Area แล้ว (Defect ID เก็บไว้เป็นหลักฐาน) ถ้ามีหลาย ID ให้เปลี่ยนเป็น Fixed เมื่อทุก ID ผ่าน Retest แล้วเท่านั้น
A43: U, V, X | B43: Tester | Executed Date (yyyy-mm-dd) | Remark (สรุป Impact Area / เหตุผลที่ Blocked)
A44: W — Overall Verdict (Auto) | B44: 1) Out of Scope / Canceled → Out of Scope 2) Blocked → Blocked 3) มี Bug ที่ยังไม่ Fixed: Flow หรือ Card Priority ใดเป็น Urgent / High / ว่าง → Failed · ทั้งหมด Medium / Low → Conditionally Passed 4) Done → Passed 5) อื่นๆ → Not Run
...

Sheet Regression Plan
A1: ="Regression Plan — "&'E2E core flow'!B1&" · "&'E2E core flow'!B3 -> Regression Plan — Cortex HIS (SBH) · v2.9.0
A2: Auto-linked from 'E2E core flow', 'Cards', 'Card Test Cases' และ Dashboard — กรอกเฉพาะช่องสีเหลือง (ตัวอักษรสีน้ำเงิน)
A3: 1. Test Information
A4: Item | B4: Value | C4: Source
A5: Project Name | B5: ='E2E core flow'!B1 -> Cortex HIS (SBH) | C5: E2E core flow!B1
A6: Test Suite | B6: ='E2E core flow'!B2 -> E2E (Core Flow) | C6: E2E core flow!B2
A7: Build / Version | B7: ='E2E core flow'!B3 -> v2.9.0 | C7: E2E core flow!B3
A8: Environment | B8: ='E2E core flow'!B4 -> demo-x | C8: E2E core flow!B4
A9: Priority | B9: ='E2E core flow'!B5 -> Urgent | C9: E2E core flow!B5
A10: Sprint / Cycle | B10: =IF('E2E core flow'!D1="","(ยังไม่ระบุ)",'E2E core flow'!D1) -> (ยังไม่ระบุ) | C10: E2E core flow!D1
A11: Executed By | B11: =IF('E2E core flow'!D2="","(ยังไม่ระบุ)",'E2E core flow'!D2) -> (ยังไม่ระบุ) | C11: E2E core flow!D2
A12: Executed Date | B12: =IF(OR('E2E core flow'!D3="",'E2E core flow'!D3="yyyy-mm-dd hh:mm"),"(ยังไม่ระบุ)",'E2E core flow'!D3) -> (ยังไม่ระบุ) | C12: E2E core flow!D3
A13: Last Executed Date (Auto) | B13: ='Dashboard Feed'!P8 -> - | C13: วันที่ล่าสุดจาก E2E + Card Test Cases
A14: Test Start Date | C14: Input — วันเริ่มทดสอบ (yyyy-mm-dd)
A15: Duration (Working Days) | B15: 5 | C15: Input — จำนวนวันทำการ (จ.–ศ.)
A16: Test End Date | B16: =IF(OR(B14="",B15=""),"-",WORKDAY(B14,B15-1)) -> - | C16: Start + Duration − 1 (ไม่นับเสาร์–อาทิตย์)
A17: Timeline Status | B17: =IF(OR(B14="",B15=""),"กรอก Start Date",IF(TODAY()<B14,"Not Started",IF(TODAY()>B16,"Ended","In Progress — เหลือ "&NETWORKDAYS(TODAY(),B16)&" วันทำการ"))) -> กรอก Start Date | C17: คำนวณจากวันที่ปัจจุบัน
A19: 2. Regression Scope
A20: Scope | B20: Count | C20: Note
A21: E2E Scenarios – OPD | B21: =COUNTIFS('E2E core flow'!$A$15:$A$1000,"<>",'E2E core flow'!$B$15:$B$1000,"OPD") -> 11 | C21: Module = OPD
A22: E2E Scenarios – IPD | B22: =COUNTIFS('E2E core flow'!$A$15:$A$1000,"<>",'E2E core flow'!$B$15:$B$1000,"IPD") -> 13 | C22: Module = IPD
A23: E2E Scenarios – Other Modules | B23: =B24-B21-B22 -> 7 | C23: Module อื่น
A24: E2E Scenarios – Total | B24: =COUNTIF('E2E core flow'!$A$15:$A$1000,"?*") -> 31 | C24: ทั้งหมดในชีต E2E core flow
A25: Cards (Feature cards) | B25: =COUNTIF(Cards!$A$4:$A$1000,"?*") -> 38 | C25: การ์ดที่ต้องทดสอบใน release นี้
A26: Card Test Cases | B26: =COUNTIF('Card Test Cases'!$A$4:$A$1000,"?*") -> 0 | C26: TC ทั้งหมดในชีต Card Test Cases
A27: Out of Scope / Canceled (E2E) | B27: =COUNTIF('E2E core flow'!$W$15:$W$1000,"Out of Scope") -> 13 | C27: ไม่นับใน Pass Rate
A28: Known Issue (Cards) | B28: =COUNTIF(Cards!$J$4:$J$1000,"Passed with Known Issue") -> 0 | C28: Passed with Known Issue → ต้องแจ้งใน Release Note
A30: 3. Pass / Fail Criteria (Overall Verdict)
A31: Verdict | B31: Condition | C31: Action
A32: NOT READY (NO-GO) | B32: มี Scenario / การ์ด / TC ที่ Failed หรือ Blocked หรือมี Bug Priority Urgent / High ที่ยังไม่ Fixed หรือการ์ด TOR / Urgent-High ยังไม่มีผล | C32: Log Bug / Hotfix ตาม Exit Criteria → Reject Build หากแก้ไม่ทัน
A33: IN PROGRESS | B33: ยังทดสอบไม่ครบ แต่ยังไม่เข้าเงื่อนไข NO-GO | C33: ทดสอบต่อจนครบ
A34: READY (GO) | B34: ทุกส่วนผ่าน (Passed / Cond. Passed) ไม่มี Blocking และผ่านเกณฑ์ข้อ 9 | C34: Accept Build → Release
A35: Current Verdict | B35: =Dashboard!D12 -> NOT READY (NO-GO) | C35: Dashboard › Overall Verdict
A37: 4. Exit Criteria
A38: Item | B38: Value | C38: Source
A39: Exit Criteria | B39: ='E2E core flow'!B6 -> หากพบ Bug Priority Urgent / High ให้ log bug เพื่อแก้ด่วน โดย Developer ต้องส่งมอบแก้ไขภายใน [ระบุเวลา เช่น 2–4 ชม.] มิฉะนั้นจะดำเนินการ Reject Build ทันที | C39: E2E core flow!B6
A41: 5. Execution Status (E2E)
A42: Status | B42: Meaning | C42: Counts toward | D42: Count
A43: ToDo | B43: ยังไม่เริ่มทดสอบ | C43: IN PROGRESS | D43: =COUNTIF('E2E core flow'!$M$15:$M$1000,A43) -> 0
A44: Ready for Testing | B44: พร้อมให้ทดสอบ (Build / ข้อมูลพร้อม) | C44: IN PROGRESS | D44: =COUNTIF('E2E core flow'!$M$15:$M$1000,A44) -> 18
...

Sheet Dashboard
B1: ="Release Dashboard — Regression "&'E2E core flow'!B3&" · "&'E2E core flow'!B1 -> Release Dashboard — Regression v2.9.0 · Cortex HIS (SBH)
B2: Auto-calculated from 'E2E core flow', 'Cards' and 'Card Test Cases'. Do not overwrite formulas.
B4: 1. Process & Progress Funnel
B5: Total Scope | D5: Execution Rate | F5: Completion Rate | I5: Release Readiness / Pass Rate
B6: =C67-C66 -> 18 | D6: =IFERROR((C86+C87+C90)/B6,0) -> 0 | F6: =IFERROR(C90/B6,0) -> 0 | I6: {=_xlfn.LET(_xlpm.p,COUNTIF('E2E core flow'!$W$15:$W$1000,"Passed"),_xlpm.cp,COUNTIF('E2E core flow'!$W$15:$W$1000,"Conditionally Passed"),_xlpm.f,COUNTIF('E2E core flow'!$W$15:$W$1000,"Failed"),IFERROR((_xlpm.p+_xlpm.cp)/(_xlpm.p+_xlpm.cp+_xlpm.f),"No evaluated cases"))} -> No evaluated cases
B8: ="Cards: "&J61&" | Test Cases: "&'Dashboard Feed'!P15&" | Pending Mapping: "&COUNTIF(Cards!$G$4:$G$1000,"Pending Mapping")&" | Out of Scope (excluded): "&C66 -> Cards: 38 | Test Cases: 0 | Pending Mapping: 5 | Out of Scope (excluded): 13 | D8: ="Started "&(C86+C87+C90)&" of "&B6&" (Testing "&C86&" | Blocked "&C87&" | Done "&C90&")" -> Started 0 of 18 (Testing 0 | Blocked 0 | Done 0) | F8: ="Completed (Done) "&C90&" of "&B6 -> Completed (Done) 0 of 18 | I8: {=_xlfn.LET(_xlpm.p,COUNTIF('E2E core flow'!$W$15:$W$1000,"Passed"),_xlpm.cp,COUNTIF('E2E core flow'!$W$15:$W$1000,"Conditionally Passed"),_xlpm.f,COUNTIF('E2E core flow'!$W$15:$W$1000,"Failed"),"Passed "&_xlpm.p&" + Cond. Passed "&_xlpm.cp&" of "&(_xlpm.p+_xlpm.cp+_xlpm.f)&" evaluated (Failed "&_xlpm.f&")")} -> Passed 0 + Cond. Passed 0 of 0 evaluated (Failed 0)
B9: Total test scenarios in this cycle | D9: % of scope started (Testing / Blocked / Done) | F9: % of scope tested to a final result | I9: (Passed + Cond. Passed) / (Passed + Cond. Passed + Failed) — Failed นับทันทีแม้ยังไม่ Done
B10: {=_xlfn.LET(_xlpm.ids,'E2E core flow'!$A$15:$A$1000,_xlpm.pri,'E2E core flow'!$L$15:$L$1000,_xlpm.ver,'E2E core flow'!$W$15:$W$1000,_xlpm.gate,'E2E core flow'!$Z$15:$Z$1000,_xlpm.hi,(_xlpm.pri="Urgent")+(_xlpm.pri="High")+((_xlpm.pri="")*(_xlpm.ids<>"")),_xlpm.fe,SUM((_xlpm.ver="Failed")*(_xlpm.gate<>"Accepted (CF)")),_xlpm.fc,J64,_xlpm.hnr,SUM(_xlpm.hi*(_xlpm.ver="Not Run")),_xlpm.hb,SUM(_xlpm.hi*(_xlpm.ver="Blocked")),_xlpm.hcu,'Dashboard Feed'!P22,_xlpm.lu,'Dashboard Feed'!P25,_xlpm.ub,SUM((_xlpm.gate="Blocking")*(_xlpm.ver<>"Failed")),_xlpm.tb,'Dashboard Feed'!P24,_xlpm.cf,'Dashboard Feed'!P35,_xlpm.ki,C62,_xlpm.kt,'Dashboard Feed'!P36,_xlpm.pr,I6,_xlpm.nogo,_xlpm.fe+_xlpm.hnr+_xlpm.hb+_xlpm.hcu+_xlpm.ub+_xlpm.tb>0,_xlpm.msg,IF(_xlpm.nogo,"NOT READY (NO-GO) - "&_xlfn.TEXTJOIN(" | ",TRUE,IF(_xlpm.fe>0,"Failed (Urgent/High): "&_xlpm.fe&" (Cards affected: "&_xlpm.fc&")",""),IF(_xlpm.hnr+_xlpm.hb>0,"Urgent/High Untested: "&_xlpm.hnr&" | Blocked: "&_xlpm.hb,""),IF(_xlpm.hcu>0,"Cards Pending Result (TOR / Urgent-High): "&_xlpm.hcu,""),IF(_xlpm.ub>0,"Open Urgent/High Bug (no CF): "&_xlpm.ub,""),IF(_xlpm.tb>0,"Cards Failed / Not Tested (TOR / Urgent-High, no CF): "&_xlpm.tb,"")),IF(ISNUMBER(_xlpm.pr),"READY TO RELEASE"&IF(_xlpm.lu>0," (Medium/Low Untested: "&_xlpm.lu&")",""),"NOT READY - ยังไม่มีเคสที่ประเมินผล")),"Release Decision: "&_xlpm.msg&IF(_xlpm.cf>0," | Accepted by CF: "&_xlpm.cf,"")&IF(_xlpm.ki+_xlpm.kt>0," | Known Issues: E2E "&_xlpm.ki&" / Cards "&_xlpm.kt,""))} -> Release Decision: NOT READY (NO-GO) - Urgent/High Untested: 18 | Blocked: 0 | Cards Pending Result (TOR / Urgent-High): 38 | K10: ="Risk Level: "&'Dashboard Feed'!P11 -> Risk Level: Urgent
B11: ★ Regression Result Summary — Overall Verdict (E2E Core Flow · Cards · Card Test Cases)
B12: OVERALL VERDICT | D12: ='Dashboard Feed'!P9 -> NOT READY (NO-GO) | I12: ="Risk Level: "&'Dashboard Feed'!P11&" · "&'Dashboard Feed'!P12 -> Risk Level: Urgent · NO-GO | Not yet evaluated: 18
B15: E2E Core Flow (Scenarios) | E15: Cards (Card Result by QA Site) | H15: Card Test Cases | K15: Open E2E Bugs & Release Blockers
B16: =$K$21 -> IN PROGRESS | E16: =$K$22 -> IN PROGRESS | H16: =$K$23 -> NO DATA | K16: =J170&" Open Bugs · "&(C174+C175)&" Blocking" -> 0 Open Bugs · 0 Blocking
B17: ="Pass Rate "&IFERROR(TEXT($J$21,"0.0%"),"-")&" · Evaluated "&TEXT($I$21,"0.0%") -> Pass Rate - · Evaluated 0.0% | E17: ="Pass Rate "&IFERROR(TEXT($J$22,"0.0%"),"-")&" · Evaluated "&TEXT($I$22,"0.0%") -> Pass Rate - · Evaluated 0.0% | H17: ="Pass Rate "&IFERROR(TEXT($J$23,"0.0%"),"-")&" · Evaluated "&TEXT($I$23,"0.0%") -> Pass Rate - · Evaluated 0.0% | K17: ="Urgent "&J165&" · High "&J166&" · Medium "&J167&" · Low "&J168 -> Urgent 0 · High 0 · Medium 0 · Low 0
B18: ="Passed "&$C$21&" · Cond. "&$D$21&" · Failed "&$E$21&" · Blocked "&$F$21&" · Not Run "&$G$21&" (of "&$H$21&")" -> Passed 0 · Cond. 0 · Failed 0 · Blocked 0 · Not Run 18 (of 18) | E18: ="Passed "&$C$22&" · Cond. "&$D$22&" · Failed "&$E$22&" · Blocked "&$F$22&" · Not Run "&$G$22&" (of "&$H$22&")" -> Passed 0 · Cond. 0 · Failed 0 · Blocked 0 · Not Run 38 (of 38) | H18: ="Passed "&$C$23&" · Cond. "&$D$23&" · Failed "&$E$23&" · Blocked "&$F$23&" · Not Run "&$G$23&" (of "&$H$23&")" -> Passed 0 · Cond. 0 · Failed 0 · Blocked 0 · Not Run 0 (of 0) | K18: ="Blocking: E2E "&C174&" · Cards "&C175&" · Accepted (CF) "&C176 -> Blocking: E2E 0 · Cards 0 · Accepted (CF) 0
B20: Area | C20: Passed | D20: Cond. Passed / Known Issue | E20: Failed | F20: Blocked | G20: Not Run / Pending | H20: Total | I20: % Evaluated | J20: Pass Rate | K20: Area Verdict
B21: E2E Core Flow | C21: =N(D157) -> 0 | D21: =N(E157) -> 0 | E21: =N(F157) -> 0 | F21: =N(G157) -> 0 | G21: =N(I157) -> 18 | H21: =N(C157) -> 18 | I21: =IFERROR((C21+D21+E21)/H21,0) -> 0 | J21: =IFERROR((C21+D21)/(C21+D21+E21),"-") -> - | K21: {=_xlfn.LET(_xlpm.p,N($C$21),_xlpm.cp,N($D$21),_xlpm.f,N($E$21),_xlpm.b,N($F$21),_xlpm.nr,N($G$21),_xlpm.t,N($H$21),IF(_xlpm.t=0,"NO DATA",IF(_xlpm.f>0,"FAILED",IF(_xlpm.b>0,"BLOCKED",IF(_xlpm.nr>0,"IN PROGRESS",IF(_xlpm.cp>0,"COND. PASSED","PASSED"))))))} -> IN PROGRESS
B22: Cards | C22: =N(D159) -> 0 | D22: =N(E159) -> 0 | E22: =N(F159) -> 0 | F22: =N(G159) -> 0 | G22: =N(I159) -> 38 | H22: =N(C159) -> 38 | I22: =IFERROR((C22+D22+E22)/H22,0) -> 0 | J22: =IFERROR((C22+D22)/(C22+D22+E22),"-") -> - | K22: {=_xlfn.LET(_xlpm.p,N($C$22),_xlpm.cp,N($D$22),_xlpm.f,N($E$22),_xlpm.b,N($F$22),_xlpm.nr,N($G$22),_xlpm.t,N($H$22),IF(_xlpm.t=0,"NO DATA",IF(_xlpm.f>0,"FAILED",IF(_xlpm.b>0,"BLOCKED",IF(_xlpm.nr>0,"IN PROGRESS",IF(_xlpm.cp>0,"COND. PASSED","PASSED"))))))} -> IN PROGRESS
B23: Card Test Cases | C23: =N(D160) -> 0 | D23: =N(E160) -> 0 | E23: =N(F160) -> 0 | F23: =N(G160) -> 0 | G23: =N(I160) -> 0 | H23: =N(C160) -> 0 | I23: =IFERROR((C23+D23+E23)/H23,0) -> 0 | J23: =IFERROR((C23+D23)/(C23+D23+E23),"-") -> - | K23: {=_xlfn.LET(_xlpm.p,N($C$23),_xlpm.cp,N($D$23),_xlpm.f,N($E$23),_xlpm.b,N($F$23),_xlpm.nr,N($G$23),_xlpm.t,N($H$23),IF(_xlpm.t=0,"NO DATA",IF(_xlpm.f>0,"FAILED",IF(_xlpm.b>0,"BLOCKED",IF(_xlpm.nr>0,"IN PROGRESS",IF(_xlpm.cp>0,"COND. PASSED","PASSED"))))))} -> NO DATA
B24: Overall (รวม 3 ส่วน) | C24: =SUM(C21:C23) -> 0 | D24: =SUM(D21:D23) -> 0 | E24: =SUM(E21:E23) -> 0 | F24: =SUM(F21:F23) -> 0 | G24: =SUM(G21:G23) -> 56 | H24: =SUM(H21:H23) -> 56 | I24: =IFERROR((C24+D24+E24)/H24,0) -> 0 | J24: =IFERROR((C24+D24)/(C24+D24+E24),"-") -> - | K24: =IF(LEFT('Dashboard Feed'!P9,9)="NOT READY","NO-GO",IF(ISNUMBER(SEARCH("READY",'Dashboard Feed'!P9)),"GO","IN PROGRESS")) -> NO-GO
B59: 2a. Quality Breakdown - E2E Core Flow | I59: 2b. Quality Breakdown - Cards Scope
B60: Overall Verdict | C60: Count | D60: % of Total | I60: Metric | J60: Count | K60: % of Scope
B61: Passed | C61: =COUNTIF('E2E core flow'!$W$15:$W$1000,B61) -> 0 | D61: =IFERROR(C61/$C$67,0) -> 0 | I61: Total Scope (Cards) | J61: =COUNTIF(Cards!$A$4:$A$1000,"?*") -> 38
B62: Conditionally Passed | C62: =COUNTIF('E2E core flow'!$W$15:$W$1000,B62) -> 0 | D62: =IFERROR(C62/$C$67,0) -> 0 | I62: Cards Passed | J62: =COUNTIF(Cards!$G$4:$G$1000,"Passed") -> 0 | K62: =IFERROR(J62/$J$61,0) -> 0
B63: Failed | C63: =COUNTIF('E2E core flow'!$W$15:$W$1000,B63) -> 0 | D63: =IFERROR(C63/$C$67,0) -> 0 | I63: Cards Cond. Passed | J63: =COUNTIF(Cards!$G$4:$G$1000,"Conditionally Passed") -> 0 | K63: =IFERROR(J63/$J$61,0) -> 0
B64: Blocked | C64: =COUNTIF('E2E core flow'!$W$15:$W$1000,B64) -> 0 | D64: =IFERROR(C64/$C$67,0) -> 0 | I64: Cards Failed (via E2E) | J64: =COUNTIF(Cards!$G$4:$G$1000,"Failed") -> 0 | K64: =IFERROR(J64/$J$61,0) -> 0
B65: Not Run | C65: =COUNTIF('E2E core flow'!$W$15:$W$1000,B65) -> 18 | D65: =IFERROR(C65/$C$67,0) -> 0.58064516 | I65: Cards Blocked | J65: =COUNTIF(Cards!$G$4:$G$1000,"Blocked") -> 0 | K65: =IFERROR(J65/$J$61,0) -> 0
B66: Out of Scope / Canceled (excluded) | C66: =COUNTIF('E2E core flow'!$W$15:$W$1000,"Out of Scope") -> 13 | D66: =IFERROR(C66/$C$67,0) -> 0.41935484 | I66: Cards Pending (Not Run / Pending Mapping) | J66: =COUNTIF(Cards!$G$4:$G$1000,"Ready for Testing")+COUNTIF(Cards!$G$4:$G$1000,"Pending Mapping") -> 38 | K66: =IFERROR(J66/$J$61,0) -> 1
B67: Total Scenarios | C67: =COUNTIF('E2E core flow'!$A$15:$A$1000,"?*") -> 31
B68: Critical / High Defects | C68: =G78+G79 -> 0 | D68: =IF(C68>0,"Open Critical / High bugs — Go/No-Go ตัดสินจาก Release Gate","None") -> None
B75: 3. Risk & Action Required
B76: Open E2E Bugs — Severity × Impact (SOP-QA-CORTEX-01 · cell color = Bug Priority) | I76: Bottlenecks - Blocked & Returned Items
B77: Severity \ Impact | C77: Extensive | D77: Significant | E77: Moderate | F77: Minor | G77: Total Open | I77: Item ID | J77: Scenario / Card Title | K77: Status | L77: Owner / Tester | M77: Remark / Reason
B78: Critical | C78: =COUNTIFS('E2E core flow'!$P$15:$P$1000,$B78,'E2E core flow'!$Q$15:$Q$1000,C$77,'E2E core flow'!$W$15:$W$1000,"<>Out of Scope",'E2E core flow'!$T$15:$T$1000,"<>Fixed – Retest Passed") -> 0 | D78: =COUNTIFS('E2E core flow'!$P$15:$P$1000,$B78,'E2E core flow'!$Q$15:$Q$1000,D$77,'E2E core flow'!$W$15:$W$1000,"<>Out of Scope",'E2E core flow'!$T$15:$T$1000,"<>Fixed – Retest Passed") -> 0 | E78: =COUNTIFS('E2E core flow'!$P$15:$P$1000,$B78,'E2E core flow'!$Q$15:$Q$1000,E$77,'E2E core flow'!$W$15:$W$1000,"<>Out of Scope",'E2E core flow'!$T$15:$T$1000,"<>Fixed – Retest Passed") -> 0 | F78: =COUNTIFS('E2E core flow'!$P$15:$P$1000,$B78,'E2E core flow'!$Q$15:$Q$1000,F$77,'E2E core flow'!$W$15:$W$1000,"<>Out of Scope",'E2E core flow'!$T$15:$T$1000,"<>Fixed – Retest Passed") -> 0 | G78: =SUM(C78:F78) -> 0 | I78: {=_xlfn.LET(_xlpm.ns,SUM(--('E2E core flow'!$M$15:$M$1000="Blocked")),_xlpm.nc,SUM(--(((Cards!$G$4:$G$1000="Failed")+(Cards!$G$4:$G$1000="Blocked"))>0)),IF(_xlpm.ns+_xlpm.nc=0,"No blocked or returned items",IF(_xlpm.ns=0,_xlfn._xlws.FILTER(CHOOSE({1,2,3,4,5},Cards!$A$4:$A$1000,Cards!$B$4:$B$1000,"Card: "&Cards!$G$4:$G$1000,IF(Cards!$C$4:$C$1000="","(Owner not assigned)",Cards!$C$4:$C$1000),"Mapped to "&Cards!$E$4:$E$1000),((Cards!$G$4:$G$1000="Failed")+(Cards!$G$4:$G$1000="Blocked"))),IF(_xlpm.nc=0,_xlfn._xlws.FILTER(CHOOSE({1,2,3,4,5},'E2E core flow'!$A$15:$A$1000,'E2E core flow'!$D$15:$D$1000,"Scenario: "&'E2E core flow'!$M$15:$M$1000,IF('E2E core flow'!$U$15:$U$1000="","(Tester not assigned)",'E2E core flow'!$U$15:$U$1000),IF('E2E core flow'!$X$15:$X$1000<>"",'E2E core flow'!$X$15:$X$1000,IF('E2E core flow'!$N$15:$N$1000<>"",'E2E core flow'!$N$15:$N$1000,"Reason not specified"))),'E2E core flow'!$M$15:$M$1000="Blocked"),_xlfn.VSTACK(_xlfn._xlws.FILTER(CHOOSE({1,2,3,4,5},'E2E core flow'!$A$15:$A$1000,'E2E core flow'!$D$15:$D$1000,"Scenario: "&'E2E core flow'!$M$15:$M$1000,IF('E2E core flow'!$U$15:$U$1000="","(Tester not assigned)",'E2E core flow'!$U$15:$U$1000),IF('E2E core flow'!$X$15:$X$1000<>"",'E2E core flow'!$X$15:$X$1000,IF('E2E core flow'!$N$15:$N$1000<>"",'E2E core flow'!$N$15:$N$1000,"Reason not specified"))),'E2E core flow'!$M$15:$M$1000="Blocked"),_xlfn._xlws.FILTER(CHOOSE({1,2,3,4,5},Cards!$A$4:$A$1000,Cards!$B$4:$B$1000,"Card: "&Cards!$G$4:$G$1000,IF(Cards!$C$4:$C$1000="","(Owner not assigned)",Cards!$C$4:$C$1000),"Mapped to "&Cards!$E$4:$E$1000),((Cards!$G$4:$G$1000="Failed")+(Cards!$G$4:$G$1000="Blocked"))))))))} -> No blocked or returned items
B79: High | C79: =COUNTIFS('E2E core flow'!$P$15:$P$1000,$B79,'E2E core flow'!$Q$15:$Q$1000,C$77,'E2E core flow'!$W$15:$W$1000,"<>Out of Scope",'E2E core flow'!$T$15:$T$1000,"<>Fixed – Retest Passed") -> 0 | D79: =COUNTIFS('E2E core flow'!$P$15:$P$1000,$B79,'E2E core flow'!$Q$15:$Q$1000,D$77,'E2E core flow'!$W$15:$W$1000,"<>Out of Scope",'E2E core flow'!$T$15:$T$1000,"<>Fixed – Retest Passed") -> 0 | E79: =COUNTIFS('E2E core flow'!$P$15:$P$1000,$B79,'E2E core flow'!$Q$15:$Q$1000,E$77,'E2E core flow'!$W$15:$W$1000,"<>Out of Scope",'E2E core flow'!$T$15:$T$1000,"<>Fixed – Retest Passed") -> 0 | F79: =COUNTIFS('E2E core flow'!$P$15:$P$1000,$B79,'E2E core flow'!$Q$15:$Q$1000,F$77,'E2E core flow'!$W$15:$W$1000,"<>Out of Scope",'E2E core flow'!$T$15:$T$1000,"<>Fixed – Retest Passed") -> 0 | G79: =SUM(C79:F79) -> 0
B80: Medium | C80: =COUNTIFS('E2E core flow'!$P$15:$P$1000,$B80,'E2E core flow'!$Q$15:$Q$1000,C$77,'E2E core flow'!$W$15:$W$1000,"<>Out of Scope",'E2E core flow'!$T$15:$T$1000,"<>Fixed – Retest Passed") -> 0 | D80: =COUNTIFS('E2E core flow'!$P$15:$P$1000,$B80,'E2E core flow'!$Q$15:$Q$1000,D$77,'E2E core flow'!$W$15:$W$1000,"<>Out of Scope",'E2E core flow'!$T$15:$T$1000,"<>Fixed – Retest Passed") -> 0 | E80: =COUNTIFS('E2E core flow'!$P$15:$P$1000,$B80,'E2E core flow'!$Q$15:$Q$1000,E$77,'E2E core flow'!$W$15:$W$1000,"<>Out of Scope",'E2E core flow'!$T$15:$T$1000,"<>Fixed – Retest Passed") -> 0 | F80: =COUNTIFS('E2E core flow'!$P$15:$P$1000,$B80,'E2E core flow'!$Q$15:$Q$1000,F$77,'E2E core flow'!$W$15:$W$1000,"<>Out of Scope",'E2E core flow'!$T$15:$T$1000,"<>Fixed – Retest Passed") -> 0 | G80: =SUM(C80:F80) -> 0
B81: Low | C81: =COUNTIFS('E2E core flow'!$P$15:$P$1000,$B81,'E2E core flow'!$Q$15:$Q$1000,C$77,'E2E core flow'!$W$15:$W$1000,"<>Out of Scope",'E2E core flow'!$T$15:$T$1000,"<>Fixed – Retest Passed") -> 0 | D81: =COUNTIFS('E2E core flow'!$P$15:$P$1000,$B81,'E2E core flow'!$Q$15:$Q$1000,D$77,'E2E core flow'!$W$15:$W$1000,"<>Out of Scope",'E2E core flow'!$T$15:$T$1000,"<>Fixed – Retest Passed") -> 0 | E81: =COUNTIFS('E2E core flow'!$P$15:$P$1000,$B81,'E2E core flow'!$Q$15:$Q$1000,E$77,'E2E core flow'!$W$15:$W$1000,"<>Out of Scope",'E2E core flow'!$T$15:$T$1000,"<>Fixed – Retest Passed") -> 0 | F81: =COUNTIFS('E2E core flow'!$P$15:$P$1000,$B81,'E2E core flow'!$Q$15:$Q$1000,F$77,'E2E core flow'!$W$15:$W$1000,"<>Out of Scope",'E2E core flow'!$T$15:$T$1000,"<>Fixed – Retest Passed") -> 0 | G81: =SUM(C81:F81) -> 0
B82: Total Open | C82: =SUM(C78:C81) -> 0 | D82: =SUM(D78:D81) -> 0 | E82: =SUM(E78:E81) -> 0 | F82: =SUM(F78:F81) -> 0 | G82: =SUM(G78:G81) -> 0
B83: Urgent = แก้ทันที (Hotfix) · High = ก่อนปิด Sprint · Medium = Sprint ถัดไป · Low = เมื่อมีเวลา — Bug ที่ยังไม่กรอก Impact ไม่ถูกนับในตารางนี้ (ดู 8b แถว "ยังไม่ระบุ")
B84: Execution Status Breakdown
B85: Execution Status | C85: Scenarios | D85: Note
...

Sheet E2E core flow
A1: Project Name: | B1: Cortex HIS (SBH) | C1: Sprint / Cycle:
A2: Test Suite: | B2: E2E (Core Flow) | C2: Executed By:
A3: Build / Version: | B3: v2.9.0 | C3: Executed Date: | D3: yyyy-mm-dd hh:mm
A4: Tested Environment: | B4: demo-x | C4: Execution Summary: | D4: ="Passed: "&COUNTIF($W$15:$W$1000,"Passed")&" | Cond. Passed: "&COUNTIF($W$15:$W$1000,"Conditionally Passed")&" | Failed: "&COUNTIF($W$15:$W$1000,"Failed")&" | Blocked: "&COUNTIF($W$15:$W$1000,"Blocked")&" | Not Run: "&COUNTIF($W$15:$W$1000,"Not Run")&" | Out of Scope: "&COUNTIF($W$15:$W$1000,"Out of Scope") -> Passed: 0 | Cond. Passed: 0 | Failed: 0 | Blocked: 0 | Not Run: 18 | Out of Scope: 13
A5: Priority: | B5: Urgent | C5: Overall Verdict: | D5: {=_xlfn.LET(_xlpm.p,COUNTIF($W$15:$W$1000,"Passed"),_xlpm.cp,COUNTIF($W$15:$W$1000,"Conditionally Passed"),_xlpm.f,COUNTIF($W$15:$W$1000,"Failed"),_xlpm.b,COUNTIF($W$15:$W$1000,"Blocked"),_xlpm.nr,COUNTIF($W$15:$W$1000,"Not Run"), IF(_xlpm.f>0,"Failed",IF(_xlpm.b>0,"Blocked",IF(OR(_xlpm.nr>0,_xlpm.p+_xlpm.cp=0),"Not Run",IF(_xlpm.cp>0,"Conditionally Passed","Passed")))))} -> Not Run
A6: Exit Criteria: | B6: หากพบ Bug Priority Urgent / High ให้ log bug เพื่อแก้ด่วน โดย Developer ต้องส่งมอบแก้ไขภายใน [ระบุเวลา เช่น 2–4 ชม.] มิฉะนั้นจะดำเนินการ Reject Build ทันที | C6: % Release Readiness: | D6: =IFERROR((COUNTIF($W$15:$W$1000,"Passed")+COUNTIF($W$15:$W$1000,"Conditionally Passed"))/(COUNTIF($W$15:$W$1000,"Passed")+COUNTIF($W$15:$W$1000,"Conditionally Passed")+COUNTIF($W$15:$W$1000,"Failed")),0) -> 0
A11: ⚙️ ช่องพื้นสีเทา = ระบบคำนวณอัตโนมัติ (Auto) — ห้ามแก้ไข / ไม่ต้องกรอก
A12: =IF(LEFT(TRIM(C12),4)="http",HYPERLINK(TRIM(C12),"🔗 อ่านกฎการลงผล (SOP)"),"🔗 SOP: ยังไม่ได้ใส่ลิงก์ (วาง URL ที่ C12)") -> 🔗 SOP: ยังไม่ได้ใส่ลิงก์ (วาง URL ที่ C12) | C12: [รอใส่ลิงก์ SOP ของ H LAB จริง] ← วาง URL ทับช่องนี้
A13: Scenario ID / Test Case ID | B13: Module / Flow | C13: Feature / Scenario Scope | D13: Scenario Name / Title | E13: Business Flow / Test Steps | F13: Test Data / Prerequisite | G13: Related Card ID(s) | H13: Expected Result | I13: Test Level | J13: Test Type | K13: Test Intent | L13: Flow Priority | M13: Execution Status | N13: Actual Result | O13: Defect ID / Issue Link | P13: Defect Severity / Blocker? | Q13: Impact | R13: Bug Priority (Auto) | S13: Root Cause | T13: Defect Status | U13: Tester | V13: Executed Date (yyyy-mm-dd) | W13: Overall Verdict (Auto) | X13: Remark / Notes | Y13: Owner Team (Auto) | Z13: Release Gate (Auto)
B14: Dropdown / Text (เช่น OPD, IPD, Billing) | C14: Text (เช่น ลงทะเบียนก่อนเข้าตรวจ OPD) | D14: Text (เช่น ผู้ป่วย Walk-in ทำก่อนคัดกรองเบื้องต้น...) | E14: Multi-line Text (ข้อความระบุ [1], [2], [3]) | F14: Text (เช่น HN ผู้ป่วย, สิทธิการรักษา, User แพทย์) | G14: Formula: Card ID - Title + (Card Priority · TOR | Card Result | TC ผ่าน/ทั้งหมด | Release Gate) ดึงจาก Cards ตาม Map to Scenario ID | H14: Multi-line Text (State change, UI, Database) | I14: Dropdown: Unit, Integration, System, Acceptance | J14: Dropdown: Functional, UI/UX, Security, Performance, Integration | K14: Dropdown: Happy, Unhappy,Edge,Error | L14: Dropdown: Urgent, High, Medium, Low — QA Site / BA กรอกให้ครบตั้งแต่ Day 0 (ว่าง = นับเป็น Urgent / High) · Protect หลัง Day 0 | M14: Dropdown: ToDo, Ready for Testing, Testing, Blocked, Done, Canceled (สถานะการทำงานเท่านั้น — ห้ามมี Passed/Failed) | N14: Text / Log / ข้อความ Error | O14: ใส่ Defect ID ของทุกบั๊กที่พบใน Scenario นี้ (รวมบั๊กจากฟีเจอร์ของการ์ดที่ผูกกับ Scenario) เช่น CTX-3462 | P14: Dropdown: Critical, High, Medium, Low (เว้นว่าง = ไม่พบ Defect) | Q14: Dropdown: Extensive (ทั้ง รพ. / หลายโมดูล) · Significant (หลายหอผู้ป่วย / ทีม) · Moderate (หอผู้ป่วยเดี่ยว / กลุ่มผู้ใช้) · Minor (ผู้ใช้เดี่ยว / เฉพาะกรณี) — กรอกเมื่อมี Defect ID | R14: Formula (ห้ามแก้มือ): Severity × Impact → Urgent / High / Medium / Low (ตรงกับ Priority ใน Linear) ตาม Matrix ใน SOP-QA-CORTEX-01 | S14: Dropdown: Config, Master Data, Code Bug — กรอกเมื่อมี Defect ID | T14: Dropdown: Open / Fixed – Retest Passed — ว่าง = Open | เปลี่ยนเป็น Fixed – Retest Passed เมื่อผ่าน Direct Fix + Impact Area แล้วเท่านั้น | U14: Text (เช่น Harry) | V14: Date (yyyy-mm-dd) — QA กรอกเอง ไม่ใช้สูตร | W14: Formula (ห้ามแก้มือ): Out of Scope/Canceled → Out of Scope | Blocked → Blocked | มีบั๊กที่ยังไม่ Fixed (Defect ID หรือ Severity) → Highest Priority Wins: Flow หรือ Card Priority เป็น Urgent/High/ว่าง → Failed | ทั้งหมด Medium/Low → Conditionally Passed | Done + ไม่มีบั๊ก หรือบั๊ก Fixed – Retest Passed → Passed | อื่นๆ → Not Run | Y14: Formula: ทีมเจ้าของจากชีต Ownership Matrix ตาม Module (คอลัมน์ B) — ใช้ใน Step 2 ของการส่งบั๊ก | Z14: Formula (ห้ามแก้มือ): Bug ที่ยังไม่ Fixed → Blocking (Verdict = Failed หรือ Bug Priority Urgent / High / ยังไม่ระบุ) · Accepted (CF) (มีแถว CAB ใน Risk Log) · Deferrable (ที่เหลือ → Risk Acceptance โดย PO)
A15: SMK-OPD-001 | B15: OPD | C15: ลงทะเบียนก่อนเข้าตรวจ OPD | D15: ผู้ป่วย Walk-in ทำก่อนคัดกรองเบื้องต้น และลงทะเบียนที่เวชระเบียน ก่อนเข้าคิวตรวจ OPD | E15: [1] ค้นหา/สร้าง HN [2] ลงทะเบียน Visit (ระบบตรวจสอบสิทธิอัตโนมัติ หรือ เลือกสิทธิ + คลินิก+แพทย์หรือไม่ระบุแพทย์) + พิมพ์ใบนำทาง [3] ระบบ Generate Visit No. → แสดงรายการที่ Tab "คำขอ Walk-in" หน้า Patient List ของคลินิก | F15: SBH Prod · ที่อยู่ทะเบียนบ้าน (บังคับ): ตำบลปากเพรียว อำเภอเมืองสระบุรี จังหวัดสระบุรี 18000 · สิทธิ H03 - สิทธิ UC เป็นลำดับ 1 (ระบบใส่ H02 - เงินสด เบิกได้ มาให้) · คลินิก 00101 - คลินิกอายุรกรรมโรคทั่วไป (Walk-in ได้แถว "คำขอ Walk-in") | G15: {=IF($A15="","",IFERROR(_xlfn.TEXTJOIN(CHAR(10)&CHAR(10),TRUE,_xlfn._xlws.FILTER("• "&Cards!$A$4:$A$1000&" - "&Cards!$B$4:$B$1000&CHAR(10)&" "&IF(Cards!$F$4:$F$1000="","Priority ?",Cards!$F$4:$F$1000)&IF(Cards!$H$4:$H$1000="Yes"," · TOR",IF(Cards!$H$4:$H$1000=""," · TOR?",""))&" | Result: "&IF(Cards!$J$4:$J$1000="","Pending",Cards!$J$4:$J$1000)&" | TC "&Cards!$P$4:$P$1000&"/"&Cards!$O$4:$O$1000&IF(Cards!$L$4:$L$1000="",""," | Gate: "&Cards!$L$4:$L$1000),(Cards!$A$4:$A$1000<>"")*ISNUMBER(SEARCH($A15,Cards!$E$4:$E$1000)))),"-"))} -> • SBH-2360 - [Registration] [OPD] ใบนำทาง: Form for SBH & improvement Urgent · TOR? | Result: Pending | TC 0/0 | Gate: Pending Result • SBH-2233 - [OPD] [Queue] Queue Improvement Urgent · TOR? | Result: Pending | TC 0/0 | Gate: Pending Result • SBH-1290 - [Registration] ข้อมูลผู้ป่วย ที่อยู่ เช่น ทะเบียนบ้าน ตำบล ถนน หมู่ ควรแยก field ของตัวเอง เพราะใช้นำส่ง 43 แฟ้ม Medium · TOR? | Result: Pending | TC 0/0 | Gate: Pending Result | H15: - ระบบค้นพบประวัติเดิมหรือสร้างรหัส HN ใหม่เข้าระบบได้สำเร็จโดยไม่มี Error - สิทธิการรักษาของผู้ป่วยถูกตรวจสอบและบันทึกถูกต้อง - ระบบทำการสร้างเลข Visit No. ประจำวันขึ้นมาใหม่อัตโนมัติ และสั่งพิมพ์ใบนำทาง (Routing Slip) ข้อมูลครบถ้วน - รายชื่อและ Visit ของผู้ป่วยถูกส่งต่อไปปรากฏทันทีที่หน้า Patient List ของคลินิกเป้าหมาย ภายใต้แท็บ "คำขอ Walk-in" | I15: System | J15: Functional | K15: Happy | M15: Ready for Testing | R15: =IF(OR($A15="",LEN(TRIM($O15))=0),"",IF(OR($P15="",$Q15=""),"ระบุ Severity + Impact",IFERROR(INDEX({"Urgent","Urgent","High","High";"Urgent","High","High","Medium";"High","High","Medium","Medium";"Medium","Medium","Low","Low"},MATCH($P15,{"Critical","High","Medium","Low"},0),MATCH($Q15,{"Extensive","Significant","Moderate","Minor"},0)),"-"))) | W15: =IF($A15="","",IF(OR($M15="Out of Scope",$M15="Canceled"),"Out of Scope",IF($M15="Blocked","Blocked",IF(AND($T15<>"Fixed – Retest Passed",OR(LEN(TRIM($O15))>0,LEN(TRIM($P15))>0)),IF(AND(OR($L15="Medium",$L15="Low"),SUMPRODUCT((Cards!$A$4:$A$1000<>"")*ISNUMBER(SEARCH($A15,Cards!$E$4:$E$1000))*(Cards!$F$4:$F$1000<>"Medium")*(Cards!$F$4:$F$1000<>"Low"))=0),"Conditionally Passed","Failed"),IF($M15="Done","Passed","Not Run"))))) -> Not Run | Y15: {=IF($A15="","",IF(TRIM($B15)="","-",IFERROR(_xlfn.TEXTJOIN(" / ",TRUE,_xlfn.UNIQUE(_xlfn._xlws.FILTER('Ownership Matrix'!$C$5:$C$200,('Ownership Matrix'!$A$5:$A$200=TRIM($B15))*('Ownership Matrix'!$C$5:$C$200<>"")))),"ไม่พบใน Ownership Matrix")))} -> ไม่พบใน Ownership Matrix | Z15: =IF(NOT(AND($A15<>"",$M15<>"Out of Scope",$M15<>"Canceled",$T15<>"Fixed – Retest Passed",OR(LEN(TRIM($O15))>0,LEN(TRIM($P15))>0))),"",IF(OR($W15="Failed",$R15="Urgent",$R15="High",$R15="ระบุ Severity + Impact"),IF(COUNTIFS(Dashboard!$B$105:$B$124,$O15,Dashboard!$I$105:$I$124,"CAB")>0,"Accepted (CF)","Blocking"),"Deferrable"))
A16: SMK-OPD-002 | B16: OPD | C16: พยาบาลคัดกรองผู้ป่วย | D16: ผู้ป่วย Walk-in มายังคลินิก และคัดกรองโดยพยาบาล | E16: [1] พยาบาลเข้าสู่เมนูผู้ป่วยนอก >> เข้าสู่ Service Unit หรือ Location คลินิก >>ค้นหารายชื่อผู้ป่วยหรือ ค้นหาผู้ป่วยตาม HN [2] พยาบาลตรวจสอบ Tab "คำขอ Walk-in" >> กดปุ่ม "แบบคัดกรอง" ในคอลัมน์คัดกรองของแถวผู้ป่วย [3] พยาบาลซักประวัติ และ กรอกฟอร์มคัดกรองบันทึกเอกสารคัดกรอง + สัญญาณชีพ >> บันทึก [4] พยาบาลกดปุ่ม "ลงตาราง" >> เลือกแพทย์ + ประเภทบริการ + ช่วงเวลา >> บันทึก (ระบบเช็คอินให้อัตโนมัติ) [5] พยาบาลกด "พร้อมตรวจ" ที่หน้ารายการผู้ป่วยนอก [6] พยาบาลหน้าห้องเรียกคิวผู้ป่วยพบแพทย์ | F16: หน่วยบริการ แผนกอายุรกรรม · ช่องบริการ ก่อนตรวจ · ลงตาราง: แพทย์ ดร. วิชัย รัตน์ เอื้อเฟื้อ · ประเภทบริการ ตรวจครั้งแรก · ฟอร์มคัดกรอง: Chief Complaint + Present Illness (บังคับ) + Vital Signs ครบ (Temp / BP / PR / RR / SpO2) | G16: {=IF($A16="","",IFERROR(_xlfn.TEXTJOIN(CHAR(10)&CHAR(10),TRUE,_xlfn._xlws.FILTER("• "&Cards!$A$4:$A$1000&" - "&Cards!$B$4:$B$1000&CHAR(10)&" "&IF(Cards!$F$4:$F$1000="","Priority ?",Cards!$F$4:$F$1000)&IF(Cards!$H$4:$H$1000="Yes"," · TOR",IF(Cards!$H$4:$H$1000=""," · TOR?",""))&" | Result: "&IF(Cards!$J$4:$J$1000="","Pending",Cards!$J$4:$J$1000)&" | TC "&Cards!$P$4:$P$1000&"/"&Cards!$O$4:$O$1000&IF(Cards!$L$4:$L$1000="",""," | Gate: "&Cards!$L$4:$L$1000),(Cards!$A$4:$A$1000<>"")*ISNUMBER(SEARCH($A16,Cards!$E$4:$E$1000)))),"-"))} -> • SBH-2457 - [EMR] [Form] ประกอบและปรับแต่ง Form OPD note/Pre-assessment จากการ Restructure EHR base Urgent · TOR? | Result: Pending | TC 0/0 | Gate: Pending Result • SBH-2424 - [Bug][Appointment][Physician Schedule] Restore open-ended routine availability High · TOR? | Result: Pending | TC 0/0 | Gate: Pending Result • SBH-887 - [Pre-Assessment] improvement Urgent · TOR? | Result: Pending | TC 0/0 | Gate: Pending Result | H16: - ผู้ป่วยแสดงในแท็บ "คำขอ Walk-in" และกดปุ่ม "แบบคัดกรอง" แล้วเปิดฟอร์มคัดกรองได้ - ฟอร์มคัดกรองบันทึกข้อมูลสำเร็จ ค่าสัญญาณชีพ (Vital Signs) ถูกบันทึกลงฐานข้อมูลและแสดงผลในชาร์ต - ลงตารางแพทย์สำเร็จ ระบบเช็คอินให้อัตโนมัติ ได้เลขคิวพบแพทย์ และรายชื่อผู้ป่วยย้ายจากแท็บ "คำขอ Walk-in" ไปแท็บ "เช็คอิน" ทันที - เมื่อกด "พร้อมตรวจ" สถานะผู้ป่วยอัปเดตเป็น "พร้อมตรวจ" และไปปรากฏในคิวรอตรวจของห้องตรวจแพทย์ - ระบบคิวแสดงสัญญาณหรือเสียงเรียกคิวผู้ป่วยหน้าห้องตรวจได้ตามลำดับ | I16: System | J16: Functional | K16: Happy | M16: Ready for Testing | R16: =IF(OR($A16="",LEN(TRIM($O16))=0),"",IF(OR($P16="",$Q16=""),"ระบุ Severity + Impact",IFERROR(INDEX({"Urgent","Urgent","High","High";"Urgent","High","High","Medium";"High","High","Medium","Medium";"Medium","Medium","Low","Low"},MATCH($P16,{"Critical","High","Medium","Low"},0),MATCH($Q16,{"Extensive","Significant","Moderate","Minor"},0)),"-"))) | W16: =IF($A16="","",IF(OR($M16="Out of Scope",$M16="Canceled"),"Out of Scope",IF($M16="Blocked","Blocked",IF(AND($T16<>"Fixed – Retest Passed",OR(LEN(TRIM($O16))>0,LEN(TRIM($P16))>0)),IF(AND(OR($L16="Medium",$L16="Low"),SUMPRODUCT((Cards!$A$4:$A$1000<>"")*ISNUMBER(SEARCH($A16,Cards!$E$4:$E$1000))*(Cards!$F$4:$F$1000<>"Medium")*(Cards!$F$4:$F$1000<>"Low"))=0),"Conditionally Passed","Failed"),IF($M16="Done","Passed","Not Run"))))) -> Not Run | Y16: {=IF($A16="","",IF(TRIM($B16)="","-",IFERROR(_xlfn.TEXTJOIN(" / ",TRUE,_xlfn.UNIQUE(_xlfn._xlws.FILTER('Ownership Matrix'!$C$5:$C$200,('Ownership Matrix'!$A$5:$A$200=TRIM($B16))*('Ownership Matrix'!$C$5:$C$200<>"")))),"ไม่พบใน Ownership Matrix")))} -> ไม่พบใน Ownership Matrix | Z16: =IF(NOT(AND($A16<>"",$M16<>"Out of Scope",$M16<>"Canceled",$T16<>"Fixed – Retest Passed",OR(LEN(TRIM($O16))>0,LEN(TRIM($P16))>0))),"",IF(OR($W16="Failed",$R16="Urgent",$R16="High",$R16="ระบุ Severity + Impact"),IF(COUNTIFS(Dashboard!$B$105:$B$124,$O16,Dashboard!$I$105:$I$124,"CAB")>0,"Accepted (CF)","Blocking"),"Deferrable"))
A17: SMK-OPD-003 | B17: OPD | C17: แพทย์ตรวจ + วินิจฉัย + สั่ง Order (Lab/X-ray/ยา) | D17: พยาบาลเรียกคิวตรวจผู้ป่วย OPD และ Order (Lab/X-ray/ยา) | E17: [1] แพทย์เข้าสู่เมนูผู้ป่วยนอก >> เข้าสู่ Service Unit หรือ Location คลินิก [2] แพทย์เลือกผู้ป่วยที่ถูก Assign หรือ ค้นหาผู้ป่วยตาม HN (ผู้ป่วยอยู่สถานะ "พร้อมตรวจ") [3] แพทย์ตรวจสอบ ดูประวัติ + Vital Sign และ บันทึกวินิจฉัย (Diagnosis/ICD-10) ด้วย Template OPD Note [4] แพทย์สั่ง Order (แยก 3 เส้นทางที่อาจเกิดพร้อมกันในเคสเดียว): [4a] ค้นหา Item Lab → เลือก Item → เพิ่มลงตะกร้า [4b] ค้นหา Item X-ray → เลือก Item → เพิ่มลงตะกร้า [4c] ค้นหา Item ยา → เลือก Item → เพิ่มลงตะกร้า [5] กดปุ่ม "ส่งคำสั่ง" (Submit Order ทั้งตะกร้าพร้อมกัน) [6] เปลี่ยนสถานะผู้ป่วย = "พักการตรวจ" [กรณีที่แพทย์มีการสั่ง LAB หรือ รังสี] | F17: Dx M545 - Low back pain (หรือ K30) · ยา MED0000619 PARACETAMOL 500 MG TABLET (ประเภทการใช้ Home med) · Lab LAB0000001 (Glucose) · X-ray IMG0000194 (LEFT ANKLE) | G17: {=IF($A17="","",IFERROR(_xlfn.TEXTJOIN(CHAR(10)&CHAR(10),TRUE,_xlfn._xlws.FILTER("• "&Cards!$A$4:$A$1000&" - "&Cards!$B$4:$B$1000&CHAR(10)&" "&IF(Cards!$F$4:$F$1000="","Priority ?",Cards!$F$4:$F$1000)&IF(Cards!$H$4:$H$1000="Yes"," · TOR",IF(Cards!$H$4:$H$1000=""," · TOR?",""))&" | Result: "&IF(Cards!$J$4:$J$1000="","Pending",Cards!$J$4:$J$1000)&" | TC "&Cards!$P$4:$P$1000&"/"&Cards!$O$4:$O$1000&IF(Cards!$L$4:$L$1000="",""," | Gate: "&Cards!$L$4:$L$1000),(Cards!$A$4:$A$1000<>"")*ISNUMBER(SEARCH($A17,Cards!$E$4:$E$1000)))),"-"))} -> • SBH-2532 - [EMR] [CDSS] - Food drug allergy: เช่น Contrast Media-Seafood/Egg-vaccine Medium · TOR? | Result: Pending | TC 0/0 | Gate: Pending Result • SBH-2457 - [EMR] [Form] ประกอบและปรับแต่ง Form OPD note/Pre-assessment จากการ Restructure EHR base Urgent · TOR? | Result: Pending | TC 0/0 | Gate: Pending Result • SBH-864 - [CPOE] [Order] Form เอกสารประกอบการสั่งยา ปรับให้เป็น Prefill ติ๊กตามสิทธิที่เปิดมา Medium · TOR? | Result: Pending | TC 0/0 | Gate: Pending Result • SBH-498 - [EMR] [Patient History] Label แสดงสถานะ "On Warfarin" บน Patient Banner Medium · TOR? | Result: Pending | TC 0/0 | Gate: Pending Result • SBH-417 - [CPOE] [order] รวมค่าใช้จ่ายผู้ป่วย Urgent · TOR? | Result: Pending | TC 0/0 | Gate: Pending Result • SBH-408 - [EMR] Clinical Summary High · TOR? | Result: Pending | TC 0/0 | Gate: Pending Result | H17: - แพทย์เปิดดูประวัติและ Vital Signs ได้ถูกต้อง และผู้ป่วยอยู่สถานะ "พร้อมตรวจ" - บันทึกผลวินิจฉัยและรหัสโรค ICD-10 ผ่าน Template OPD Note ได้สมบูรณ์ ข้อมูลไม่สูญหาย - ตะกร้า Order รวมทั้ง 3 รายการ (Lab, X-ray, ยา) ได้ถูกต้อง และเมื่อกด Submit ระบบสร้าง Order ID แยกตามแผนกอัตโนมัติ - เนื่องจากมีรายการส่งตรวจ Lab/X-ray สถานะของผู้ป่วยต้องเปลี่ยนเป็น "พักการตรวจ" โดยอัตโนมัติเพื่อรอผลตรวจ | I17: System | J17: Functional | K17: Happy | M17: Ready for Testing | R17: =IF(OR($A17="",LEN(TRIM($O17))=0),"",IF(OR($P17="",$Q17=""),"ระบุ Severity + Impact",IFERROR(INDEX({"Urgent","Urgent","High","High";"Urgent","High","High","Medium";"High","High","Medium","Medium";"Medium","Medium","Low","Low"},MATCH($P17,{"Critical","High","Medium","Low"},0),MATCH($Q17,{"Extensive","Significant","Moderate","Minor"},0)),"-"))) | W17: =IF($A17="","",IF(OR($M17="Out of Scope",$M17="Canceled"),"Out of Scope",IF($M17="Blocked","Blocked",IF(AND($T17<>"Fixed – Retest Passed",OR(LEN(TRIM($O17))>0,LEN(TRIM($P17))>0)),IF(AND(OR($L17="Medium",$L17="Low"),SUMPRODUCT((Cards!$A$4:$A$1000<>"")*ISNUMBER(SEARCH($A17,Cards!$E$4:$E$1000))*(Cards!$F$4:$F$1000<>"Medium")*(Cards!$F$4:$F$1000<>"Low"))=0),"Conditionally Passed","Failed"),IF($M17="Done","Passed","Not Run"))))) -> Not Run | Y17: {=IF($A17="","",IF(TRIM($B17)="","-",IFERROR(_xlfn.TEXTJOIN(" / ",TRUE,_xlfn.UNIQUE(_xlfn._xlws.FILTER('Ownership Matrix'!$C$5:$C$200,('Ownership Matrix'!$A$5:$A$200=TRIM($B17))*('Ownership Matrix'!$C$5:$C$200<>"")))),"ไม่พบใน Ownership Matrix")))} -> ไม่พบใน Ownership Matrix | Z17: =IF(NOT(AND($A17<>"",$M17<>"Out of Scope",$M17<>"Canceled",$T17<>"Fixed – Retest Passed",OR(LEN(TRIM($O17))>0,LEN(TRIM($P17))>0))),"",IF(OR($W17="Failed",$R17="Urgent",$R17="High",$R17="ระบุ Severity + Impact"),IF(COUNTIFS(Dashboard!$B$105:$B$124,$O17,Dashboard!$I$105:$I$124,"CAB")>0,"Accepted (CF)","Blocking"),"Deferrable"))
A18: SMK-OPD-004 | B18: OPD | C18: พยาบาลตรวจสอบ Order และแจ้งผู้ป่วยไปชำระเงิน | D18: พยาบาลตรวจสอบ Order ที่แพทย์สั่ง หรือหากมีคำสั่ง รคส [รคส คือการสั่งแทนแพทย์] และแจ้งผู้ป่วยไปชำระเงินก่อนตรวจ LAB / รังสี (เก็บ Specimen ที่ห้องแล็บหลังเช็คอิน — SMK-OPD-006) | E18: [1] พยาบาลเข้าสู่เมนูผู้ป่วยนอก >> เข้าสู่ Service Unit หรือ Location คลินิก [2] พยาบาลกดเข้าสู่ข้อมูลผู้ป่วย หรือ ค้นหาจาก HN >> กดเข้าประวัติผู้ป่วย>> ตรวจสอบ Order ที่แพทย์สั่ง หรือหากมีคำสั่ง รคส [รคส คือการสั่งแทนแพทย์] [3] พยาบาลแจ้งให้ผู้ป่วยไปชำระเงินก่อน กรณีที่มีการสั่ง LAB หรือ รังสี | F18: บัญชีพยาบาล (role Nurse) | G18: {=IF($A18="","",IFERROR(_xlfn.TEXTJOIN(CHAR(10)&CHAR(10),TRUE,_xlfn._xlws.FILTER("• "&Cards!$A$4:$A$1000&" - "&Cards!$B$4:$B$1000&CHAR(10)&" "&IF(Cards!$F$4:$F$1000="","Priority ?",Cards!$F$4:$F$1000)&IF(Cards!$H$4:$H$1000="Yes"," · TOR",IF(Cards!$H$4:$H$1000=""," · TOR?",""))&" | Result: "&IF(Cards!$J$4:$J$1000="","Pending",Cards!$J$4:$J$1000)&" | TC "&Cards!$P$4:$P$1000&"/"&Cards!$O$4:$O$1000&IF(Cards!$L$4:$L$1000="",""," | Gate: "&Cards!$L$4:$L$1000),(Cards!$A$4:$A$1000<>"")*ISNUMBER(SEARCH($A18,Cards!$E$4:$E$1000)))),"-"))} -> - | H18: - พยาบาลเปิดดู OPD Note ของผู้ป่วยได้ถูกต้อง และมองเห็นข้อความในฟิลด์ "Note to Nurse" กรณีมีการสั่ง รคส อย่างครบถ้วน - รายการ Order Lab และรังสีที่แพทย์สั่งแสดงสถานะเป็น "รอชำระเงิน" หรือ "ยังไม่ได้ชำระ" - ระบบแสดงคำแนะนำ/ข้อความแจ้งเตือนให้ส่งผู้ป่วยไปชำระเงินก่อนเข้ารับการตรวจ Lab/X-ray | I18: System | J18: Functional | K18: Happy | M18: Ready for Testing | R18: =IF(OR($A18="",LEN(TRIM($O18))=0),"",IF(OR($P18="",$Q18=""),"ระบุ Severity + Impact",IFERROR(INDEX({"Urgent","Urgent","High","High";"Urgent","High","High","Medium";"High","High","Medium","Medium";"Medium","Medium","Low","Low"},MATCH($P18,{"Critical","High","Medium","Low"},0),MATCH($Q18,{"Extensive","Significant","Moderate","Minor"},0)),"-"))) | W18: =IF($A18="","",IF(OR($M18="Out of Scope",$M18="Canceled"),"Out of Scope",IF($M18="Blocked","Blocked",IF(AND($T18<>"Fixed – Retest Passed",OR(LEN(TRIM($O18))>0,LEN(TRIM($P18))>0)),IF(AND(OR($L18="Medium",$L18="Low"),SUMPRODUCT((Cards!$A$4:$A$1000<>"")*ISNUMBER(SEARCH($A18,Cards!$E$4:$E$1000))*(Cards!$F$4:$F$1000<>"Medium")*(Cards!$F$4:$F$1000<>"Low"))=0),"Conditionally Passed","Failed"),IF($M18="Done","Passed","Not Run"))))) -> Not Run | Y18: {=IF($A18="","",IF(TRIM($B18)="","-",IFERROR(_xlfn.TEXTJOIN(" / ",TRUE,_xlfn.UNIQUE(_xlfn._xlws.FILTER('Ownership Matrix'!$C$5:$C$200,('Ownership Matrix'!$A$5:$A$200=TRIM($B18))*('Ownership Matrix'!$C$5:$C$200<>"")))),"ไม่พบใน Ownership Matrix")))} -> ไม่พบใน Ownership Matrix | Z18: =IF(NOT(AND($A18<>"",$M18<>"Out of Scope",$M18<>"Canceled",$T18<>"Fixed – Retest Passed",OR(LEN(TRIM($O18))>0,LEN(TRIM($P18))>0))),"",IF(OR($W18="Failed",$R18="Urgent",$R18="High",$R18="ระบุ Severity + Impact"),IF(COUNTIFS(Dashboard!$B$105:$B$124,$O18,Dashboard!$I$105:$I$124,"CAB")>0,"Accepted (CF)","Blocking"),"Deferrable"))
A19: SMK-OPD-005 | B19: OPD | C19: ห้องการเงิน ผู้ป่วยชำระเงิน | D19: ผู้ป่วยชำระเงิน กรณีที่มีการสั่ง LAB หรือ รังสี จากแพทย์ | E19: [1] ค้นหาผู้ป่วยจาก HN [2] ตรวจสอบข้อมูล >> ทำการปิดสิทธิ UC (ระบุเลข End Point) >> ยอดที่เบิกไม่ได้ชำระเป็นเงินสด [3] ห้องการเงินรับชำระเงินเฉพาะรายการจาก LAB หรือ รังสี >> เลือกวิธีการชำระเงิน >> กดชำระเงิน [4] พิมพ์ใบเสร็จรับเงิน | F19: สิทธิ H03 - สิทธิ UC + เงินสด · ปิดสิทธิ UC ด้วยเลข End Point (ประเภทบัตร 60 · Terminal ID / Trace / End Point เลขสุ่ม) · ห้องการเงินชั้น 1 · วิธีชำระ เงินสด | G19: {=IF($A19="","",IFERROR(_xlfn.TEXTJOIN(CHAR(10)&CHAR(10),TRUE,_xlfn._xlws.FILTER("• "&Cards!$A$4:$A$1000&" - "&Cards!$B$4:$B$1000&CHAR(10)&" "&IF(Cards!$F$4:$F$1000="","Priority ?",Cards!$F$4:$F$1000)&IF(Cards!$H$4:$H$1000="Yes"," · TOR",IF(Cards!$H$4:$H$1000=""," · TOR?",""))&" | Result: "&IF(Cards!$J$4:$J$1000="","Pending",Cards!$J$4:$J$1000)&" | TC "&Cards!$P$4:$P$1000&"/"&Cards!$O$4:$O$1000&IF(Cards!$L$4:$L$1000="",""," | Gate: "&Cards!$L$4:$L$1000),(Cards!$A$4:$A$1000<>"")*ISNUMBER(SEARCH($A19,Cards!$E$4:$E$1000)))),"-"))} -> - | H19: - ค้นหา HN แล้วพบเฉพาะรายการค่าใช้จ่ายของ Lab และ รังสี ที่ส่งมาจากห้องตรวจถูกต้อง - ปิดสิทธิ UC ด้วยเลข End Point ได้ถูกต้อง และยอดที่เบิกไม่ได้ชำระเป็นเงินสดได้ (ถ้าสิทธิ UC ครอบคลุมทั้งหมด ยอดต้องชำระเป็น 0) - เมื่อกดรับชำระเงิน ระบบบันทึกยอดเงินเข้าสู่ระบบ Cashier ได้สำเร็จ และพิมพ์ "ใบเสร็จรับเงิน" ที่มีเลขที่ใบเสร็จถูกต้อง - สถานะค่าใช้จ่ายของรายการ Lab/X-ray เปลี่ยนเป็น "ชำระเงินแล้ว (Paid)" ซึ่งปลดล็อกให้ห้อง Lab สามารถกดรับตรวจได้ | I19: System | J19: Functional | K19: Happy | M19: Ready for Testing | R19: =IF(OR($A19="",LEN(TRIM($O19))=0),"",IF(OR($P19="",$Q19=""),"ระบุ Severity + Impact",IFERROR(INDEX({"Urgent","Urgent","High","High";"Urgent","High","High","Medium";"High","High","Medium","Medium";"Medium","Medium","Low","Low"},MATCH($P19,{"Critical","High","Medium","Low"},0),MATCH($Q19,{"Extensive","Significant","Moderate","Minor"},0)),"-"))) | W19: =IF($A19="","",IF(OR($M19="Out of Scope",$M19="Canceled"),"Out of Scope",IF($M19="Blocked","Blocked",IF(AND($T19<>"Fixed – Retest Passed",OR(LEN(TRIM($O19))>0,LEN(TRIM($P19))>0)),IF(AND(OR($L19="Medium",$L19="Low"),SUMPRODUCT((Cards!$A$4:$A$1000<>"")*ISNUMBER(SEARCH($A19,Cards!$E$4:$E$1000))*(Cards!$F$4:$F$1000<>"Medium")*(Cards!$F$4:$F$1000<>"Low"))=0),"Conditionally Passed","Failed"),IF($M19="Done","Passed","Not Run"))))) -> Not Run | Y19: {=IF($A19="","",IF(TRIM($B19)="","-",IFERROR(_xlfn.TEXTJOIN(" / ",TRUE,_xlfn.UNIQUE(_xlfn._xlws.FILTER('Ownership Matrix'!$C$5:$C$200,('Ownership Matrix'!$A$5:$A$200=TRIM($B19))*('Ownership Matrix'!$C$5:$C$200<>"")))),"ไม่พบใน Ownership Matrix")))} -> ไม่พบใน Ownership Matrix | Z19: =IF(NOT(AND($A19<>"",$M19<>"Out of Scope",$M19<>"Canceled",$T19<>"Fixed – Retest Passed",OR(LEN(TRIM($O19))>0,LEN(TRIM($P19))>0))),"",IF(OR($W19="Failed",$R19="Urgent",$R19="High",$R19="ระบุ Severity + Impact"),IF(COUNTIFS(Dashboard!$B$105:$B$124,$O19,Dashboard!$I$105:$I$124,"CAB")>0,"Accepted (CF)","Blocking"),"Deferrable"))
A20: SMK-OPD-006 | B20: OPD | C20: ผู้ป่วยไปยังห้อง LAB เพื่อเก็บ Specimen | D20: ผู้ป่วยไปยังห้อง LAB เพื่อเก็บ Specimen ที่ Center LAB ชั้น 3 และส่ง Specimen ไปห้องปฏิบัติการ ชั้น 6 | E20: [1] ค้นหาผู้ป่วยจาก HN >> เจ้าหน้าที่ Center LAB ชั้น 3 กด "เช็คอิน" (เลือกประเภทคิว) และรับคิว LAB [2] ผู้ป่วยเก็บ Specimen ที่ Center LAB ชั้น 3 >> เจ้าหน้าที่ LAB พิมพ์สติ๊กเกอร์ติดหลอดเลือด/ปัสสาวะ >> กด "เก็บแล้ว" [3] เจ้าหน้าที่ Center LAB ชั้น 3 ส่ง Specimen ไปยังห้องปฏิบัติการชั้น 6 >> ห้องปฏิบัติการชั้น 6 กด "รับแล้ว" [4] เจ้าหน้าที่ห้องปฏิบัติการ ชั้น 6 ตรวจสอบ Specimen และนำเข้าเครื่องวิเคราะห์ >> รายงานผล LAB เอง (ยังไม่เชื่อมต่อระบบ LIS) และกดยืนยันผล (Approve) [5] ผล LAB แสดงในระบบของผู้ป่วย | F20: Lab LAB0000001 (Glucose) · ห้องปฏิบัติการ ชั้น 6 · ยังไม่เชื่อมต่อ LIS — ห้องแล็บลงผลเอง | G20: {=IF($A20="","",IFERROR(_xlfn.TEXTJOIN(CHAR(10)&CHAR(10),TRUE,_xlfn._xlws.FILTER("• "&Cards!$A$4:$A$1000&" - "&Cards!$B$4:$B$1000&CHAR(10)&" "&IF(Cards!$F$4:$F$1000="","Priority ?",Cards!$F$4:$F$1000)&IF(Cards!$H$4:$H$1000="Yes"," · TOR",IF(Cards!$H$4:$H$1000=""," · TOR?",""))&" | Result: "&IF(Cards!$J$4:$J$1000="","Pending",Cards!$J$4:$J$1000)&" | TC "&Cards!$P$4:$P$1000&"/"&Cards!$O$4:$O$1000&IF(Cards!$L$4:$L$1000="",""," | Gate: "&Cards!$L$4:$L$1000),(Cards!$A$4:$A$1000<>"")*ISNUMBER(SEARCH($A20,Cards!$E$4:$E$1000)))),"-"))} -> - | H20: - เจ้าหน้าที่ Center Lab ชั้น 3 เช็คอินรับคิวได้ และพิมพ์สติกเกอร์บาร์โค้ด HN/Lab No. ออกมาติดหลอดส่งตรวจได้ถูกต้อง - เมื่อกดเปลี่ยนสถานะเป็น "เก็บแล้ว" ข้อมูลวิ่งไปปรากฏที่หน้าจอห้องปฏิบัติการ ชั้น 6 - ห้องปฏิบัติการ ชั้น 6 สามารถกดยืนยันสถานะ "รับแล้ว" ได้ถูกต้อง - เมื่อกรอกและบันทึกผล Lab สถานะในระบบอัปเดตเป็น "เสร็จสิ้น (Completed / Approved)" - ผลการตรวจ Lab ไหลเข้าสู่ระบบ EMR ของผู้ป่วยทันที และแสดงผลพร้อมให้แพทย์เปิดดูในห้องตรวจ | I20: System | J20: Functional | K20: Happy | M20: Ready for Testing | R20: =IF(OR($A20="",LEN(TRIM($O20))=0),"",IF(OR($P20="",$Q20=""),"ระบุ Severity + Impact",IFERROR(INDEX({"Urgent","Urgent","High","High";"Urgent","High","High","Medium";"High","High","Medium","Medium";"Medium","Medium","Low","Low"},MATCH($P20,{"Critical","High","Medium","Low"},0),MATCH($Q20,{"Extensive","Significant","Moderate","Minor"},0)),"-"))) | W20: =IF($A20="","",IF(OR($M20="Out of Scope",$M20="Canceled"),"Out of Scope",IF($M20="Blocked","Blocked",IF(AND($T20<>"Fixed – Retest Passed",OR(LEN(TRIM($O20))>0,LEN(TRIM($P20))>0)),IF(AND(OR($L20="Medium",$L20="Low"),SUMPRODUCT((Cards!$A$4:$A$1000<>"")*ISNUMBER(SEARCH($A20,Cards!$E$4:$E$1000))*(Cards!$F$4:$F$1000<>"Medium")*(Cards!$F$4:$F$1000<>"Low"))=0),"Conditionally Passed","Failed"),IF($M20="Done","Passed","Not Run"))))) -> Not Run | Y20: {=IF($A20="","",IF(TRIM($B20)="","-",IFERROR(_xlfn.TEXTJOIN(" / ",TRUE,_xlfn.UNIQUE(_xlfn._xlws.FILTER('Ownership Matrix'!$C$5:$C$200,('Ownership Matrix'!$A$5:$A$200=TRIM($B20))*('Ownership Matrix'!$C$5:$C$200<>"")))),"ไม่พบใน Ownership Matrix")))} -> ไม่พบใน Ownership Matrix | Z20: =IF(NOT(AND($A20<>"",$M20<>"Out of Scope",$M20<>"Canceled",$T20<>"Fixed – Retest Passed",OR(LEN(TRIM($O20))>0,LEN(TRIM($P20))>0))),"",IF(OR($W20="Failed",$R20="Urgent",$R20="High",$R20="ระบุ Severity + Impact"),IF(COUNTIFS(Dashboard!$B$105:$B$124,$O20,Dashboard!$I$105:$I$124,"CAB")>0,"Accepted (CF)","Blocking"),"Deferrable"))
A21: SMK-OPD-007 | B21: OPD | C21: ผู้ป่วยไปยังห้องรังสี (X-ray) เพื่อถ่ายภาพ + รังสีแพทย์อ่านผล | D21: ผู้ป่วยไปห้องรังสีเพื่อถ่ายภาพ X-ray ตาม Order ที่ชำระเงินแล้ว และรังสีแพทย์รายงานผลกลับเข้า EMR ของผู้ป่วย | E21: [1] เจ้าหน้าที่ห้องรังสีเข้าเมนู ห้องรังสี >> เลือกห้อง >> Tab "รอ Check-in" >> ค้นหาผู้ป่วยจาก HN [2] เจ้าหน้าที่กด "เช็คอิน" >> เลือกประเภทคิว (คิวรังสี) >> กด "ยืนยัน" (+ พิมพ์ใบยินยอม ถ้ามี) >> ได้เลขคิวรังสี [3] เจ้าหน้าที่กด "เริ่มถ่ายภาพ" >> กด "ถ่ายภาพแล้ว" >> เลือกแพทย์ผู้อ่านผล >> สถานะ "รออ่านผล" [4] รังสีแพทย์เปิดรายละเอียดรังสี >> บันทึกรายงานผลตรวจทางรังสี (Findings + Impression) >> กด "บันทึก" [5] ผลรังสีแสดงในระบบของผู้ป่วย (เมนู Imaging result) | F21: X-ray IMG0000194 (LEFT ANKLE) · ประเภทคิว คิวรังสี | G21: {=IF($A21="","",IFERROR(_xlfn.TEXTJOIN(CHAR(10)&CHAR(10),TRUE,_xlfn._xlws.FILTER("• "&Cards!$A$4:$A$1000&" - "&Cards!$B$4:$B$1000&CHAR(10)&" "&IF(Cards!$F$4:$F$1000="","Priority ?",Cards!$F$4:$F$1000)&IF(Cards!$H$4:$H$1000="Yes"," · TOR",IF(Cards!$H$4:$H$1000=""," · TOR?",""))&" | Result: "&IF(Cards!$J$4:$J$1000="","Pending",Cards!$J$4:$J$1000)&" | TC "&Cards!$P$4:$P$1000&"/"&Cards!$O$4:$O$1000&IF(Cards!$L$4:$L$1000="",""," | Gate: "&Cards!$L$4:$L$1000),(Cards!$A$4:$A$1000<>"")*ISNUMBER(SEARCH($A21,Cards!$E$4:$E$1000)))),"-"))} -> - | H21: - Order X-ray ที่ชำระเงินแล้วแสดงในแท็บ "รอ Check-in" ของห้องรังสีครบถ้วน - กดเช็คอินสำเร็จ ได้เลขคิวรังสี และ Status Log เปลี่ยนเป็น "Check-in" - สถานะงานรังสีเปลี่ยนตามลำดับถูกต้อง: เริ่มถ่ายภาพ > ถ่ายภาพเสร็จสิ้น > รออ่านผล - รังสีแพทย์บันทึกรายงานผลสำเร็จ สถานะงานเป็น "เสร็จสิ้น" และ Status Log บันทึกเป็น "อ่านผล" - ผลรังสีแสดงในเมนู Imaging result ของ EMR พร้อมให้แพทย์เปิดดูในห้องตรวจ | I21: System | J21: Functional | K21: Happy | M21: Ready for Testing | R21: =IF(OR($A21="",LEN(TRIM($O21))=0),"",IF(OR($P21="",$Q21=""),"ระบุ Severity + Impact",IFERROR(INDEX({"Urgent","Urgent","High","High";"Urgent","High","High","Medium";"High","High","Medium","Medium";"Medium","Medium","Low","Low"},MATCH($P21,{"Critical","High","Medium","Low"},0),MATCH($Q21,{"Extensive","Significant","Moderate","Minor"},0)),"-"))) | W21: =IF($A21="","",IF(OR($M21="Out of Scope",$M21="Canceled"),"Out of Scope",IF($M21="Blocked","Blocked",IF(AND($T21<>"Fixed – Retest Passed",OR(LEN(TRIM($O21))>0,LEN(TRIM($P21))>0)),IF(AND(OR($L21="Medium",$L21="Low"),SUMPRODUCT((Cards!$A$4:$A$1000<>"")*ISNUMBER(SEARCH($A21,Cards!$E$4:$E$1000))*(Cards!$F$4:$F$1000<>"Medium")*(Cards!$F$4:$F$1000<>"Low"))=0),"Conditionally Passed","Failed"),IF($M21="Done","Passed","Not Run"))))) -> Not Run | Y21: {=IF($A21="","",IF(TRIM($B21)="","-",IFERROR(_xlfn.TEXTJOIN(" / ",TRUE,_xlfn.UNIQUE(_xlfn._xlws.FILTER('Ownership Matrix'!$C$5:$C$200,('Ownership Matrix'!$A$5:$A$200=TRIM($B21))*('Ownership Matrix'!$C$5:$C$200<>"")))),"ไม่พบใน Ownership Matrix")))} -> ไม่พบใน Ownership Matrix | Z21: =IF(NOT(AND($A21<>"",$M21<>"Out of Scope",$M21<>"Canceled",$T21<>"Fixed – Retest Passed",OR(LEN(TRIM($O21))>0,LEN(TRIM($P21))>0))),"",IF(OR($W21="Failed",$R21="Urgent",$R21="High",$R21="ระบุ Severity + Impact"),IF(COUNTIFS(Dashboard!$B$105:$B$124,$O21,Dashboard!$I$105:$I$124,"CAB")>0,"Accepted (CF)","Blocking"),"Deferrable"))
A22: SMK-OPD-008 | B22: OPD | C22: แพทย์กรอกข้อมูล Diagnosis + แจ้งผล หลังจากได้รับผล LAB หรือ รังสี | D22: แพทย์กรอกข้อมูล OPD Note เพิ่มเติม + แจ้งผล LAB หรือ รังสี | E22: [1] พยาบาลเรียกคิวพบแพทย์ [2] แพทย์เข้าสู่เมนูผู้ป่วยนอก >> เข้าสู่ Service Unit หรือ Location คลินิก [3] เลือกข้อมูลผู้ป่วย หรือ ค้นหาผู้ป่วยตาม HN และกดเปลี่ยนสถานะจาก "พักการตรวจ" เป็น "พร้อมตรวจ" [4] แพทย์เปิดดูผล LAB หรือ ภาพรังสี ที่รายงานผลกลับมา [5] แพทย์กรอกข้อมูล OPD Note เพิ่มเติม + วินิจฉัยโรค (Diagnosis) ขั้นสุดท้าย [6] แพทย์สั่งยา (กรณีต้องให้ยาเพิ่ม) และกดส่ง Order [7] แพทย์สร้างนัดหมายติดตามอาการ (เมนูขวา "สร้างนัดหมาย" >> คลินิก + แพทย์ + ประเภทบริการ + วัน / ช่วงเวลา >> Submit) [8] แพทย์สร้างใบรับรองแพทย์ (เมนูขวา "ใบรับรองแพทย์" >> เลือกแบบเอกสาร >> กรอกข้อมูล >> บันทึก) [9] แพทย์เปลี่ยนสถานะผู้ป่วยเป็น "ตรวจเสร็จ" | F22: นัดหมาย: ประเภทบริการ ติดตามอาการ · ระยะเวลา 2 สัปดาห์ (คลินิก 00101 · ดร. วิชัย รัตน์ เอื้อเฟื้อ) · ใบรับรองแพทย์ลาป่วย | G22: {=IF($A22="","",IFERROR(_xlfn.TEXTJOIN(CHAR(10)&CHAR(10),TRUE,_xlfn._xlws.FILTER("• "&Cards!$A$4:$A$1000&" - "&Cards!$B$4:$B$1000&CHAR(10)&" "&IF(Cards!$F$4:$F$1000="","Priority ?",Cards!$F$4:$F$1000)&IF(Cards!$H$4:$H$1000="Yes"," · TOR",IF(Cards!$H$4:$H$1000=""," · TOR?",""))&" | Result: "&IF(Cards!$J$4:$J$1000="","Pending",Cards!$J$4:$J$1000)&" | TC "&Cards!$P$4:$P$1000&"/"&Cards!$O$4:$O$1000&IF(Cards!$L$4:$L$1000="",""," | Gate: "&Cards!$L$4:$L$1000),(Cards!$A$4:$A$1000<>"")*ISNUMBER(SEARCH($A22,Cards!$E$4:$E$1000)))),"-"))} -> • SBH-916 - [EMR][LAB Result] search by item ได้แล้ว ต้องการ search and filter by Group ด้วย Low · TOR? | Result: Pending | TC 0/0 | Gate: Pending Result | H22: - สถานะผู้ป่วยสามารถเปลี่ยนจาก "พักการตรวจ" กลับมาเป็น "พร้อมตรวจ" ได้สมบูรณ์ - ผลการตรวจ Lab/ภาพรังสี แสดงผลบนจอแพทย์ได้อย่างถูกต้อง ครบถ้วน - แพทย์บันทึก OPD Note เพิ่มเติม สั่ง Order ยา และกดส่งคำสั่งเข้าสู่ระบบห้องยาได้สำเร็จ - ข้อมูลการทำนัดหมายถูกบันทึกลงปฏิทินนัด และระบบสามารถสร้างพร้อมพิมพ์ "ใบรับรองแพทย์" ได้ถูกต้องตามเทมเพลต - เปลี่ยนสถานะเป็น "ตรวจเสร็จ" แล้ว ผู้ป่วยย้ายไปช่องบริการ "หลังตรวจ" ของรายการผู้ป่วยนอก | I22: System | J22: Functional | K22: Happy | M22: Ready for Testing | R22: =IF(OR($A22="",LEN(TRIM($O22))=0),"",IF(OR($P22="",$Q22=""),"ระบุ Severity + Impact",IFERROR(INDEX({"Urgent","Urgent","High","High";"Urgent","High","High","Medium";"High","High","Medium","Medium";"Medium","Medium","Low","Low"},MATCH($P22,{"Critical","High","Medium","Low"},0),MATCH($Q22,{"Extensive","Significant","Moderate","Minor"},0)),"-"))) | W22: =IF($A22="","",IF(OR($M22="Out of Scope",$M22="Canceled"),"Out of Scope",IF($M22="Blocked","Blocked",IF(AND($T22<>"Fixed – Retest Passed",OR(LEN(TRIM($O22))>0,LEN(TRIM($P22))>0)),IF(AND(OR($L22="Medium",$L22="Low"),SUMPRODUCT((Cards!$A$4:$A$1000<>"")*ISNUMBER(SEARCH($A22,Cards!$E$4:$E$1000))*(Cards!$F$4:$F$1000<>"Medium")*(Cards!$F$4:$F$1000<>"Low"))=0),"Conditionally Passed","Failed"),IF($M22="Done","Passed","Not Run"))))) -> Not Run | Y22: {=IF($A22="","",IF(TRIM($B22)="","-",IFERROR(_xlfn.TEXTJOIN(" / ",TRUE,_xlfn.UNIQUE(_xlfn._xlws.FILTER('Ownership Matrix'!$C$5:$C$200,('Ownership Matrix'!$A$5:$A$200=TRIM($B22))*('Ownership Matrix'!$C$5:$C$200<>"")))),"ไม่พบใน Ownership Matrix")))} -> ไม่พบใน Ownership Matrix | Z22: =IF(NOT(AND($A22<>"",$M22<>"Out of Scope",$M22<>"Canceled",$T22<>"Fixed – Retest Passed",OR(LEN(TRIM($O22))>0,LEN(TRIM($P22))>0))),"",IF(OR($W22="Failed",$R22="Urgent",$R22="High",$R22="ระบุ Severity + Impact"),IF(COUNTIFS(Dashboard!$B$105:$B$124,$O22,Dashboard!$I$105:$I$124,"CAB")>0,"Accepted (CF)","Blocking"),"Deferrable"))
