Workbook

Sheet Scenario-OPD-Doctor
A1: Case_id | B1: Use case Scenario | C1: Test case ID | D1: Test Step | E1: Status test | H1: NOTE
E2: Pass | F2: Fail | G2: N/A
A3: PHY-OPD-001 | B3: การให้บริการคนไข้ก่อนพบแพทย์
A4: OPD/EMR | B4: ดูข้อมูลผล IMG
B5: ตรวจสอบข้อมูลผล IMG | D5: 1. เลือกดูเมนู Imaging result ที่ Side bar ทางซ้ายมือ 2. ระบบจะแสดงข้อมูลขึ้นมา 3. สามารถใช้ Fillter เพื่อทำการกรองข้อมูล
A6: OPD/EMR | B6: ดูข้อมูลผล LAB
B7: ตรวจสอบข้อมูลผล LAB | D7: 1. เลือกดูเมนู Lab Result ที่ Side bar ทางซ้ายมือ 2. ระบบจะแสดงข้อมูลขึ้นมา 3. สามารถใช้ Fillter เพื่อทำการกรองข้อมูล
B8: เปรียบเทียบผล LAB | D8: 1. เลือกดูเมนู Lab Result หรือ ประวัติ Patho ที่ Side bar ทางซ้ายมือ 2. ระบบจะแสดงข้อมูลขึ้นมา 3. กดปุ่ม แบบเปรียบเทียบ เพื่อทำการเปรียบเทียบผล LAB กับผลครั้งก่อนๆ 4. ระบบแสดงผล LAB เปรียบเทียบกัน
B9: ตรวจสอบข้อมูลผล LAB (Patho) | D9: 1. เลือกดูเมนู ประวัติ Patho ที่ Side bar ทางซ้ายมือ 2. ระบบจะแสดงข้อมูลขึ้นมา 3. สามารถเลือกดูชุดข้อมูลต้องการได้
A10: OPD/EMR | B10: ดูข้อมูลการคัดกรองของพยาบาล
B11: ดูข้อมูลการคัดกรองของพยาบาล | D11: 1. เลือกดูเมนู ฟอร์มคัดกรอง ที่ Side bar ทางซ้ายมือ 2. ระบบจะแสดงข้อมูลของ ฟอร์มคัดกรองขึ้นมา
A12: OPD/EMR | B12: ดูข้อมูลประวัติการรักษาของคนไข้
B13: ตรวจสอบข้อมูล ประวัติการรักษา | D13: 1. เลือกดูเมนู ประวัติการรักษา ที่ Side bar ทางซ้ายมือ 2. ระบบจะแสดงข้อมูลของ ประวัติการรักษา ขึ้นมาสามารถตรวจสอบข้อมูลได้ตามราย Visit
B14: ตรวจสอบข้อมูลประจำตัวของคนไข้ (Patient Banner) | D14: 1. ข้อมูลประจำตัวของคนไข้ จะแสดงอยู่บน Banner ด้านบนสุดโดยจะประกอบไปด้วยข้อมูลดังนี้ 1.1. ข้อมูลผู้ป่วย 1.2. ข้อมูลการแพ้ 1.3. ข้อมูล U/D 1.4. ข้อมูล เชื้อดื้อยา 1.5. ข้อมูล Vital sign 1.6. ข้อมูล น้ำหนัก ส่วนสูง
A15: OPD/EMR | B15: การดูข้อมูล Med reconcile
B16: ตรวจสอบข้อมูลประวัติยาเดิมของคนไข้ | D16: 1. เลือกดูเมนู Reconclie med ที่ Side bar ทางขวามือ 2. ระบบจะแสดงหน้าข้อมูลของ Reconclie med ขึ้นมา | I16: mock ข้อมูล
A17: OPD/EMR | B17: จัดการข้อควรระวัง (Flag Manament)
B18: ตรวจสอบรายการข้อควรระวัง | D18: 1. เลือกดูเมนู ข้อพึงระวัง ที่ Side bar ทางซ้ายมือ 2. ระบบจะแสดงหน้ากรอกข้อมูลของ ข้อควรระวัง 5. ระบบแสดงข้อมูลข้อควรระวัง | I18: mock ข้อมูล
B19: เพิ่ิ่มรายการข้อควรระวัง | D19: 1. เลือกดูเมนู ข้อพึงระวัง ที่ Side bar ทางซ้ายมือ 2. ระบบจะแสดงหน้ากรอกข้อมูลของ ข้อควรระวัง 3. คลิก "เพิ่มFlag" 4. กรอกข้อมูลที่ต้องการลงไป 5. กดบันทึก 5. ระบบจะแสดงข้อมูลข้อพึงระวังของคนไข้บน Patient banner
B20: แก้ไข/ลบข้อควรระวัง | D20: 1. เลือกดูเมนู ข้อพึงระวัง ที่ Side bar ทางซ้ายมือ 2. ระบบจะแสดงหน้ากรอกข้อมูลของ ข้อควรระวัง 3.. แก้ไข หรือ ลบ Flag 4. กดบันทึก 5. ระบบจะแก้ไขข้อมูลข้อพึงระวัง หรือลบออกจาก Patient banner
A21: PHY-OPD-002 | B21: การให้บริการคนไข้ขณะพบแพทย์
A22: OPD/EMR | B22: การลง OPD Note
B23: การลงข้อมูลการรักษา | D23: 1. กดเลือกคนไข้ที่พร้อมตัวจากหน้า รายการผู้ป่วยนอก ที่สถานะพร้อมตรวจ 2. ระบบจะแสดง OPD Note ขึ้นมา 3. ลงข้อมูลการรักษา 4. ลง diagnosis 5. บันทึกข้อมูล 6. ระบบแสดงข้อมูล OPD Note ที่บันทึก
A24: OPD/CPOE | B24: การ Order, View, Edit, Delete, (ยา/เวชภัณฑ์)
B25: สั่งยา | D25: 1. กดเลือกคนไข้ที่พร้อมตัวจากหน้า รายการผู้ป่วยนอก ที่สถานะพร้อมตรวจ 2. ระบบจะแสดง Section ในส่วนของการ Order ขึ้นมา 3. ทำการสั่งยา 4. เลือกสั่งยา Home med หรือ In hospital 5. ระบุวิธีการใช้ยา / จำนวนยาที่จ่าย / หมายเหตุอื่นๆ 6. กดปุ่ม เพิ่ม order
B26: สั่งยาพร้อมนัดหมาย | D26: 1. กดเลือกคนไข้ที่พร้อมตัวจากหน้า รายการผู้ป่วยนอก ที่สถานะพร้อมตรวจ 2. ระบบจะแสดง Section ในส่วนของการ Order ขึ้นมา 3. คลิกค้นหาวันนัด 4. เลือกวันที่และSlotเวลา 5. ค้นหารายการยา 6. จำนวนวันที่ใช้จะแสดงสอดคล้องกับจำนวนวันที่นัด
B27: สั่งยา Stat | D27: 1. เลือกสั่งยาเป็น order stat 2. ระบุวิธีการใช้ยา / จำนวนยาที่จ่าย / หมายเหตุอื่นๆ 3. กดปุ่ม เพิ่ม order 4. ระบบจะแสดงรายการยาที่สั่ง พร้อม สถานะ Stat
B28: สั่งยา นอกบัญชียาหลัก หรือยาประเภทอื่นๆ (A-F) | D28: 1. ระบบสามารถแสดงบัญชียาของรายการยาที่สั่งได้ 2. เมื่อทำการสั่งยา ระบบนำราคาไปคำนวณได้ถูกต้องสัมพันธ์กับสิทธิ์การรักษาของคนไข้
B29: สั่งยา ที่ต้องมีเอกสารประกอบการสั่งยา | D29: 1. ระบบสามารถทำการตั้งค่ายาที่ต้องมีเอกสารประกอบได้จากหน้าการจัดการการสั่งยา 1.1 DUE 1.2 PA 2. เมื่อสั่งยาที่ตั้งค่าเป็นยาที่ต้องการเอกสาร ระบบสามารถ alert แจ้งเตือนว่ามีเอกสารที่เกี่ยวข้อง 3. สามารถ Link / เรียกดูเอกสารที่เกี่ยวข้องกับยานั้นได้ 4. สามารถ print/บันทึกข้อมูลลงไปในระบบได้ 5. สามารถเรียกดู order เก่าที่มีการบันทึกเอกสารไว้ได้ | I29: เช็คเอกสาร ว่ามันคือ เอกสารตัวไหน
B30: การแจ้งเตือนการสั่งยาที่คนไข้แพ้ตามประวัติ | D30: 1. เมื่อสั่งยาที่คนไข้แพ้ ระบบสามารถแสดง alert ได้ 2. test ยาที่ related / VTM group ใกล้เคียง 3. เมื่อยืนยันการสั่งยาจะสามารถสั่งได้ โดยจะต้องระบุเหตุผลก่อนเท่านั้น
B31: การแจ้งเตือนการสั่งยาซ้ำ | D31: 1. เมื่อสั่งยาซ้ำ ระบบสามารถแสดง alert ได้ 2. test ยาที่ related / VTM group ใกล้เคียง 3. เมื่อยืนยันการสั่ง ยาจะสามารถสั่งได้ โดยจะต้องระบุเหตุผลก่อนเท่านั้น
B32: การแจ้งเตือนการสั่งยา Interaction | D32: 1. สั่งยา Med0000003 2. สั่งยา Med0000007 3. ระบบจะ alert แจ้งเตือน การใช้ยาคู่ปฏิกิริยา 4. หากต้องการสั่งจะต้องกรอกเหตุผลการสั่งลงไป
B33: Remed | D33: 1. กดเลือกคนไข้ที่พร้อมตัวจากหน้า รายการผู้ป่วยนอก ที่สถานะพร้อมตรวจ 2. ระบบจะแสดง Section ในส่วนของการ Order ขึ้นมา 3. คลิกปุ่มRemed 4. เลือกVisit และยาที่ต้องการRemed 5. ตกลง ยาที่เลือกจะแสดงในOrder Basket
A34: OPD/CPOE | B34: การ Order, View, Edit, Delete, (LAB)
B35: สั่ง LAB ต้องการทราบผลภายในวันที่สั่ง | D35: 1. ค้นหารายการ lab ที่ต้องการสั่งใน order seach 2. ระบบจะแสดงรายการที่กำหนดไว้ 3. เลือก Priority และ วันที่ต้องการทราบผลเป็นวันนี้ 4. ระบบจะแสดงข้อมูลตามที่ได้เลือกไว้ ในส่วนของ วันที่ต้องการทราบหากเลือกเป็นวันนี้ ระบบจะไม่ให้เลือกวันที่ 5. กดปุ่มเพิ่ม order ระบบจะเพิ่มการสั่งลงในระบบ 6. กดปุ่ม Sign เพื่อทำการส่งการสั่งไปยังห้องปฏิบัติการ
B36: สั่ง LAB ต้องการทราบผลภายในวันที่ต้องการ | D36: 1. ค้นหารายการ lab ที่ต้องการสั่งใน order seach 2. ระบบจะแสดงรายการที่กำหนดไว้ 3. เลือก Priority และ วันที่ต้องการทราบผลเป็นวันอื่น และเลือกวันที่ต้องการ 4. ระบบจะแสดงข้อมูลตามที่ได้เลือกไว้ 5. กดปุ่มเพิ่ม order ระบบจะเพิ่มการสั่งลงในระบบ 6. กดปุ่ม Sign เพื่อทำการส่งการสั่งไปยังห้องปฏิบัติการ
B37: Order Check list | D37: 1. กดเลือกคนไข้ที่พร้อมตัวจากหน้า รายการผู้ป่วยนอก ที่สถานะพร้อมตรวจ 2. ระบบจะแสดง Section ในส่วนของการ Order ขึ้นมา 3. คลิกปุ่มChecklist 4. Check เลือกรายการLab 5. ตกลง รายการที่เลือกจะแสดงในOrder Basket
A38: OPD/CPOE | B38: การ Order, View, Edit, Delete, (IMG)
B39: สั่ง IMG ต้องการทราบผลภายในวันที่สั่ง | D39: 1. ค้นหารายการ Img ที่ต้องการสั่งใน order seach 2. ระบบจะแสดงรายการที่กำหนดไว้ 3. เลือก Priority และ วันที่ต้องการทราบผลเป็นวันนี้ 4. ระบบจะแสดงข้อมูลตามที่ได้เลือกไว้ ในส่วนของ วันที่ต้องการทราบหากเลือกเป็นวันนี้ ระบบจะไม่ให้เลือกวันที่ 5. กดปุ่มเพิ่ม order ระบบจะเพิ่มการสั่งลงในระบบ 6. กดปุ่ม Sign เพื่อทำการส่งการสั่งไปยังห้องปฏิบัติการ
B40: สั่ง IMG ต้องการทราบผลภายในวันที่ต้องการ | D40: 1. ค้นหารายการ Img ที่ต้องการสั่งใน order seach 2. ระบบจะแสดงรายการที่กำหนดไว้ 3. เลือก Priority และ วันที่ต้องการทราบผลเป็นวันอื่น และเลือกวันที่ต้องการ 4. ระบบจะแสดงข้อมูลตามที่ได้เลือกไว้ 5. กดปุ่มเพิ่ม order ระบบจะเพิ่มการสั่งลงในระบบ 6. กดปุ่ม Sign เพื่อทำการส่งการสั่งไปยังห้องปฏิบัติการ
...

Sheet Scenario-OPD-Nurse
A1: Case_id | B1: Use case Scenario | C1: Test case ID | D1: Test Step | E1: Status test | H1: NOTE
E2: Pass | F2: Fail | G2: N/A
A3: N-OPD-001 | B3: การให้บริการคนไข้ก่อนพบแพทย์ (การจัดการคนไข้ Walk in)
A4: OPD | B4: การจัดการผู้ป่วย Walk-in | D4: 1. กดปุ่มเมนูมุมบนขวา เลือกผู้ป่วยนอก และ รายการผู้ป่วย Walk-in request 2. ระบบจะแสดงรายการคนไข้ที่มีการ Walk-in เข้ามาในระบบ 3. ทำการ assign แพทย์ที่คนไข้จะได้เข้ารับการตรวจในวันนี้
B5: สร้างนัดหมายคนไข้ (กรณีคนไข้ไม่ได้เข้ารับการตรวจในวันนั้นๆ) | D5: 1. เลือกดูเมนู สร้างนัดหมาย ที่ Side bar ทางขวามือ 2. ระบบจะแสดงข้อมูลหน้าสร้างนัดหมายขึ้นมา 3. เลือก คลินิก แพทย์ ประเภทการนัดหมาย แล้ว Slot ที่ต้องการ 4. กดบันทึก 5. ระบบจะบันทึกนัดหมายของคนไข้
A6: N-OPD-002 | B6: การให้บริการคนไข้ก่อนพบแพทย์
A7: OPD/EMR | B7: ดูข้อมูลผล IMG
B8: ตรวจสอบข้อมูลผล IMG | D8: 1. เลือกดูเมนู Imaging result ที่ Side bar ทางซ้ายมือ 2. ระบบจะแสดงข้อมูลขึ้นมา 3. สามารถใช้ Fillter เพื่อทำการกรองข้อมูล
A9: OPD/EMR | B9: ดูข้อมูลผล LAB
B10: ตรวจสอบข้อมูลผล LAB | D10: 1. เลือกดูเมนู Lab Result ที่ Side bar ทางซ้ายมือ 2. ระบบจะแสดงข้อมูลขึ้นมา 3. สามารถใช้ Fillter เพื่อทำการกรองข้อมูล
B11: เปรียบเทียบผล LAB | D11: 1. เลือกดูเมนู Lab Result หรือ ประวัติ Patho ที่ Side bar ทางซ้ายมือ 2. ระบบจะแสดงข้อมูลขึ้นมา 3. กดปุ่ม แบบเปรียบเทียบ เพื่อทำการเปรียบเทียบผล LAB กับผลครั้งก่อนๆ 4. ระบบแสดงผล LAB เปรียบเทียบกัน
B12: ตรวจสอบข้อมูลผล LAB (Patho) | D12: 1. เลือกดูเมนู ประวัติ Patho ที่ Side bar ทางซ้ายมือ 2. ระบบจะแสดงข้อมูลขึ้นมา 3. สามารถเลือกดูชุดข้อมูลต้องการได้
A13: OPD/EMR | B13: การคัดกรองของพยาบาล
B14: เพิ่มการคัดกรองของพยาบาล | D14: 1. เลือกดูเมนู ฟอร์มคัดกรอง ที่ Side bar ทางขวามือ 2. ระบบจะแสดง ฟอร์มคัดกรองขึ้นมา 3. กรอกข้อมูลการคัดกรองลงไป 4. บันทึกข้อมูล 5. ระบบแสดงข้อมูลที่ได้ทำการบันทึกลงไป 6. สามารถ add attach file/outside document ได้
B15: การทำ med reconcile | D15: 1. เลือกดูเมนู reconcile med ที่ Side bar ทางขวามือ 2. ระบบจะแสดง ฟอร์ม reconcile med ขึ้นมา 3. กรอกข้อมูลรายการยาลงไป -3.1 ยาที่มีในระบบ 3.2 ยาที่ไม่มีในระบบ (free text) 4. บันทึกข้อมูล รายการยา/วิธีใช้/จำนวนคงเหลือ/หน่วย 5. สามารถเรียกดูข้อมูลที่ได้ทำการบันทึกลงไป
A16: OPD/EMR | B16: ดูข้อมูลประวัติการรักษาของคนไข้
B17: ตรวจสอบข้อมูล ประวัติการรักษา | D17: 1. เลือกดูเมนู ประวัติการรักษา ที่ Side bar ทางซ้ายมือ 2. ระบบจะแสดงข้อมูลของ ประวัติการรักษา ขึ้นมาสามารถตรวจสอบข้อมูลได้ตามราย Visit
B18: ตรวจสอบข้อมูลประจำตัวของคนไข้ (Patient Banner) | D18: 1. ข้อมูลประจำตัวของคนไข้ จะแสดงอยู่บน Banner ด้านบนสุดโดยจะประกอบไปด้วยข้อมูลดังนี้ 1.1. ข้อมูลผู้ป่วย 1.2. ข้อมูลการแพ้ 1.3. ข้อมูล U/D 1.4. ข้อมูล เชื้อดื้อยา 1.5. ข้อมูล Vital sign 1.6. ข้อมูล น้ำหนัก ส่วนสูง
A19: OPD/EMR | B19: ดูข้อมูลประวัติการแพ้
B20: ตรวจสอบข้อมูล ประวัติการแพ้ | D20: 1. เลือกดูเมนู ประวัติการแพ้ ที่ Side bar ทางซ้ายมือ 2. ระบบจะแสดงข้อมูลของ ประวัติการแพ้ของคนไข้ 3. โดยเรียงลำดับจากการแพ้ที่ Active และตามด้วย Serverity
A21: N-OPD-003 | B21: การให้บริการคนไข้ระหว่างพบแพทย์
A22: OPD/CPOE | B22: การ Order, View, Edit, Delete, (ยา/เวชภัณฑ์)
B23: Order รคส. | D23: 1. กดเลือกคนไข้ที่พร้อมตัวจากหน้า รายการผู้ป่วยนอก ที่สถานะพร้อมตรวจ 2. ระบบจะแสดง Section ในส่วนของการ Order ขึ้นมา 3. ระบุแพทย์ผู้สั่ง 4. ทำการสั่งยา
B24: สั่งยากลับบ้าน | D24: 1. กดเลือกคนไข้ที่พร้อมตัวจากหน้า รายการผู้ป่วยนอก ที่สถานะพร้อมตรวจ 2. ระบบจะแสดง Section ในส่วนของการ Order ขึ้นมา 3. ทำการสั่งยา
B25: สั่งยา Stat | D25: 1. เลือกสั่งยาเป็น order stat 2. ระบุวิธีการใช้ยา / จำนวนยาที่จ่าย / หมายเหตุอื่นๆ 3. กดปุ่ม เพิ่ม order 4. ระบบจะแสดงรายการยาที่สั่ง พร้อม สถานะ Stat
B26: สั่งยา นอกบัญชียาหลัก หรือยาประเภทอื่นๆ (A-F) | D26: 1. ระบบสามารถแสดงบัญชียาของรายการยาที่สั่งได้ 2. เมื่อทำการสั่งยา ระบบนำราคาไปคำนวณได้ถูกต้องสัมพันธ์กับสิทธิ์การรักษาของคนไข้
B27: สั่งยาที่ต้องมีเอกสารประกอบการสั่งยา | D27: 1. ระบบสามารถทำการตั้งค่ายาที่ต้องมีเอกสารประกอบได้จากหน้าการจัดการการสั่งยา 1.1 DUE 1.2 PA 2. เมื่อสั่งยาที่ตั้งค่าเป็นยาที่ต้องการเอกสาร ระบบสามารถ alert แจ้งเตือนว่ามีเอกสารที่เกี่ยวข้อง 3. สามารถ Link / เรียกดูเอกสารที่เกี่ยวข้องกับยานั้นได้ 4. สามารถ print/บันทึกข้อมูลลงไปในระบบได้ 5. สามารถเรียกดู order เก่าที่มีการบันทึกเอกสารไว้ได้
B28: การแจ้งเตือนการสั่งยาที่คนไข้แพ้ตามประวัติ | D28: 1. เมื่อสั่งยาที่คนไข้แพ้ ระบบสามารถแสดง alert ได้ 2. test ยาที่ related / ATC group ใกล้เคียง 3. เมื่อยืนยันการสั่ง ยาจะสามารถสั่งได้ โดยจะต้องระบุเหตุผลก่อนเท่านั้น
B29: การแจ้งเตือนการสั่งยาซ้ำ (Duplication alert) | D29: 1. เมื่อสั่งยาซ้ำ ระบบสามารถแสดง alert ได้ 2. test ยาที่ related / ATC group ใกล้เคียง 3. เมื่อยืนยันการสั่ง ยาจะสามารถสั่งได้ โดยจะต้องระบุเหตุผลก่อนเท่านั้น
B30: การแจ้งเตือนการสั่งยา Interaction | D30: 1. สั่งยา Med0000003 2. สั่งยา Med0000007 3. ระบบจะ alert แจ้งเตือน การใช้ยาคู่ปฏิกิริยา 4. หากต้องการสั่งจะต้องกรอกเหตุผลการสั่งลงไป
B31: Remed | D31: 1. กดเลือกคนไข้ที่พร้อมตัวจากหน้า รายการผู้ป่วยนอก ที่สถานะพร้อมตรวจ 2. ระบบจะแสดง Section ในส่วนของการ Order ขึ้นมา 3. คลิกปุ่มRemed 4. เลือกVisit และยาที่ต้องการRemed 5. ตกลง ยาที่เลือกจะแสดงในOrder Basket
A32: OPD/CPOE | B32: การ Order, View, Edit, Delete, (LAB)
B33: สั่ง LAB ต้องการทราบผลภายในวันที่สั่ง | D33: 1. ค้นหารายการ lab ที่ต้องการสั่งใน order seach 2. ระบบจะแสดงรายการที่กำหนดไว้ 3. เลือก Priority และ วันที่ต้องการทราบผลเป็นวันนี้ 4. ระบบจะแสดงข้อมูลตามที่ได้เลือกไว้ ในส่วนของ วันที่ต้องการทราบหากเลือกเป็นวันนี้ ระบบจะไม่ให้เลือกวันที่ 5. กดปุ่มเพิ่ม order ระบบจะเพิ่มการสั่งลงในระบบ 6. กดปุ่ม Sign เพื่อทำการส่งการสั่งไปยังห้องปฏิบัติการ
B34: สั่ง LAB ต้องการทราบผลภายในวันที่ต้องการ | D34: 1. ค้นหารายการ lab ที่ต้องการสั่งใน order seach 2. ระบบจะแสดงรายการที่กำหนดไว้ 3. เลือก Priority และ วันที่ต้องการทราบผลเป็นวันอื่น และเลือกวันที่ต้องการ 4. ระบบจะแสดงข้อมูลตามที่ได้เลือกไว้ 5. กดปุ่มเพิ่ม order ระบบจะเพิ่มการสั่งลงในระบบ 6. กดปุ่ม Sign เพื่อทำการส่งการสั่งไปยังห้องปฏิบัติการ
B35: Order Check list | D35: 1. กดเลือกคนไข้ที่พร้อมตัวจากหน้า รายการผู้ป่วยนอก ที่สถานะพร้อมตรวจ 2. ระบบจะแสดง Section ในส่วนของการ Order ขึ้นมา 3. คลิกปุ่มChecklist 4. Check เลือกรายการLab/Imaging 5. ตกลง รายการที่เลือกจะแสดงในOrder Basket
A36: OPD/CPOE | B36: การ Order, View, Edit, Delete, (IMG)
B37: สั่ง IMG ต้องการทราบผลภายในวันที่สั่ง | D37: 1. ค้นหารายการ Img ที่ต้องการสั่งใน order seach 2. ระบบจะแสดงรายการที่กำหนดไว้ 3. เลือก Priority และ วันที่ต้องการทราบผลเป็นวันนี้ 4. ระบบจะแสดงข้อมูลตามที่ได้เลือกไว้ ในส่วนของ วันที่ต้องการทราบหากเลือกเป็นวันนี้ ระบบจะไม่ให้เลือกวันที่ 5. กดปุ่มเพิ่ม order ระบบจะเพิ่มการสั่งลงในระบบ 6. กดปุ่ม Sign เพื่อทำการส่งการสั่งไปยังห้องปฏิบัติการ
B38: สั่ง IMG ต้องการทราบผลภายในวันที่ต้องการ | D38: 1. ค้นหารายการ Img ที่ต้องการสั่งใน order seach 2. ระบบจะแสดงรายการที่กำหนดไว้ 3. เลือก Priority และ วันที่ต้องการทราบผลเป็นวันอื่น และเลือกวันที่ต้องการ 4. ระบบจะแสดงข้อมูลตามที่ได้เลือกไว้ 5. กดปุ่มเพิ่ม order ระบบจะเพิ่มการสั่งลงในระบบ 6. กดปุ่ม Sign เพื่อทำการส่งการสั่งไปยังห้องปฏิบัติการ
B39: Order Check list | D39: 1. กดเลือกคนไข้ที่พร้อมตัวจากหน้า รายการผู้ป่วยนอก ที่สถานะพร้อมตรวจ 2. ระบบจะแสดง Section ในส่วนของการ Order ขึ้นมา 3. คลิกปุ่มChecklist 4. Check เลือกรายการImaging 5. ตกลง รายการที่เลือกจะแสดงในOrder Basket
A40: OPD/CPOE | B40: การ Order, View, Edit, Delete, (หัตถการ)
...

Sheet Scenario-Inventory
A1: Case_id | B1: TOR_ID | C1: Use case Scenario | D1: Test case ID | E1: Test Step | F1: Status test | I1: NOTE | K1: Result Test Version 1.12.13 | L1: Note
F2: Pass | G2: Fail | H2: N/A
A3: PHA-INV-001 | B3: 4.9.21.1 / 4.9.21.6 | C3: สร้างใบยาในระบบ และ ระบบคลังทำการตัด Stock รายการยานั้นๆ
A4: OPD/CPOE | C4: สร้้าง Order ยา
C5: สั่่งยา | E5: 1. เลือกเมนู OPD Note 2. ระบบจะแสดงหน้าต่าง OPD ขึ้นมา 3. เลื่อนลงไป Section: Order 4. กรอกชื่อยาในช่อง Order Search 5. กรอกข้อมูลการใช้ยา 6. เพิ่มยาลงตะกร้า 7. กดปุ่มส่งคำสั่ง | K5: สร้างใบยาในระบบ และ ระบบคลังทำการตัด Stock รายการยานั้นๆ.mp4
A6: OPD/PHA | C6: สร้างใบยาตัด Stock
C7: สร้างใบยา | E7: 1. ไปที่เมนูห้องยา 2. เลือกห้องยาชั้น 1 3. เลือกคนไข้ที่จะสร้างใบยา 4. เลือกรายการยาที่จะสร้างใบยา 5. กดปุ่มสร้างใบยา
C8: จัดยา | E8: 1. เลือกรายการยาที่จะสร้างใบยา 2. กดปุ่มสร้างใบยา 3. กดปุ่มจัดยาแล้ว
C9: จ่ายยา | E9: 1. กดปุ่มยืนยันรอจ่าย 2. เลือก 3จุด ด้านหลังรายการยา 3. เลือก ยืนยันจ่ายยา
A10: PHA-INV-002 | B10: 4.9.21.2 | C10: เบิกของจากคลังใหญ่ไปคลังย่อย
A11: PHA/INV | C11: สร้างใบขอเบิกจากคลังต้นทาง
C12: สร้างใบขอเบิกไปยังคลังย่อย | E12: 1. เข้าเมนู เบิกโอน >> ขอเบิก (ต้นทาง) 2. กดปุ่ม สร้างใบขอเบิก 3. เลือกคลังต้นทาง (คลังใหญ่) >> กดปุ่ม OK 4. กดปุ่ม เพิ่มสินค้า 4. ค้นหาและเลือกรายการสินค้า พร้อมระบุจำนวนที่ขอเบิก 5. กดปุ่ม บันทึกออกใบขอเบิก 6. ระบบแสดงใบขอเบิกพร้อมเลขที่เอกสาร และสถานะ ขอเบิก | K12: สร้างใบขอเบิกไปยังคลังย่อย.mp4
C13: ดึงรายการที่ถึงจุดสั่งซื้อเข้าใบขอเบิกอัตโนมัติ | E13: 1. เข้าเมนู เบิกโอน >> ขอเบิก (ต้นทาง) 2. กดปุ่ม สร้างใบขอเบิก 3. เลือกคลังต้นทาง (คลังใหญ่) >> กดปุ่ม OK 4. กดปุ่ม แสดงรายการที่ถึงจุดสั่งชื้อ 4. ค้นหาและเลือกรายการสินค้า พร้อมระบุจำนวนที่ขอเบิก 5. กดปุ่ม บันทึกออกใบขอเบิก 6. ระบบแสดงใบขอเบิกพร้อมเลขที่เอกสาร และสถานะ ขอเบิก | J13: Mock Data ให้ขึ้นสีเหลืองไว้ | K13: ดึงรายการที่ถึงจุดสั่งซื้อเข้าใบขอเบิกอัตโนมัติ.mp4
C14: พิมพ์ใบขอเบิกจากคลัง | E14: 1. เปิดใบขอเบิกที่สร้างไว้ 2. กดปุ่ม พิมพ์ใบขอเบิก 3. ระบบแสดงใบขอเบิกจากคลัง พร้อมเลขที่เอกสาร หน่วยขอเบิก-หน่วยจ่าย และรายการสินค้า | K14: พิมพ์ใบขอเบิกจากคลัง.mp4
A15: PHA/INV | C15: โอนสินค้าระหว่างคลัง
C16: โอนสินค้าจากคลังใหญ่ไปคลังย่อย | E16: 1. เข้าเมนู เบิกโอน >> โอนระหว่างคลัง (ต้นทาง) 2. กดปุ่ม สร้างใบโอน 3. เลือกคลังต้นทาง (คลังใหญ่) >> กดปุ่ม OK 4. กดปุ่ม เพิ่มสินค้า 4. ค้นหาและเลือกรายการสินค้า พร้อมระบุจำนวนที่โอนในแต่ล่ะ Lot 5. กดปุ่ม บันทึกโอนออกจากคลัง 6. ระบบแสดงใบโอนพร้อมเลขที่เอกสาร และสถานะ โอนระหว่างคลัง | K16: โอนสินค้าจากคลังใหญ่ไปคลังย่อย.mp4
C17: ตรวจสอบยอดคงเหลือคลังต้นทางหลังโอน | E17: 1. เข้าเมนู ภาพรวม 2. ค้นหาสินค้าที่โอนออกไป 3. ตรวจสอบยอดคงเหลือลดลงตรงตามจำนวนที่โอน 4. เปิด Stock Card ของสินค้า 5. ระบบแสดง movement ประเภทโอนออก พร้อมเลขที่ใบโอน | K17: ตรวจสอบยอดคงเหลือคลังต้นทางหลังโอน.mp4 | L17: Bug ไม่สามารถพิมพ์ใบ Stock Card ได้ | M17: ตรวจสอบยอดคงเหลือคลังต้นทางหลังโอน Fix.mp4
A18: PHA/INV | C18: รับเข้าที่คลังปลายทาง
C19: คลังย่อยรับเข้าสินค้าที่โอนมา | E19: 1. เข้าเมนู รับเข้า >> รับเข้าระหว่างคลัง (โอนเข้า) 2. เลือกรายการที่รอรับเข้า 3. ตรวจสอบจำนวนและ Lot แล้วกดปุ่ม รับเข้าจากเบิก/โอน 4. ยอดคงเหลือของคลังย่อยเพิ่มขึ้นตามจำนวนที่รับ | K19: คลังย่อยรับเข้าสินค้าที่โอนมา.mp4
A20: PHA-INV-003 | B20: 4.9.21.3 | C20: อนุมัติหรือปฏิเสธคำขอการเบิกสินค้า
A21: PHA/INV | C21: ตรวจสอบใบขอเบิกที่รอจ่าย
C22: ตรวจสอบรายการใบขอเบิกที่รออนุมัติ | E22: 1. เข้าเมนู จ่ายออก >> จ่ายตามใบขอเบิก 2. กดปุ่ม ค้นหา 3. ระบบแสดง ใบขอเบิกพร้อมสถานะ ขอเบิก 4. เลือกรายการ ขอเบิกเพื่อดูรายการสินค้า จำนวนที่ขอ และยอดคงคลัง | K22: ตรวจสอบรายการใบขอเบิกที่รออนุมัติ.mp4
A23: PHA/INV | C23: อนุมัติคำขอเบิก
C24: อนุมัติและจ่ายเต็มจำนวน | E24: 1. เข้าเมนู จ่ายออก >> จ่ายตามใบขอเบิก 2. กดปุ่ม ค้นหา 3. ระบบแสดง ใบขอเบิกพร้อมสถานะ ขอเบิก 4. เลือกรายการ ขอเบิกเพื่อดูรายการสินค้า จำนวนที่ขอ และยอดคงคลัง 5. ระบุจำนวนที่จ่าย (จ่ายเต็มจำนวน) 6. กดปุ่ม บันทึกจ่ายออกจากคลัง | K24: อนุมัติและจ่ายเต็มจำนวน.mp4
C25: อนุมัติแบบจ่ายบางส่วน (ค้างจ่าย) | E25: 1. เข้าเมนู จ่ายออก >> จ่ายตามใบขอเบิก 2. กดปุ่ม ค้นหา 3. ระบบแสดง ใบขอเบิกพร้อมสถานะ ขอเบิก 4. เลือกรายการ ขอเบิกเพื่อดูรายการสินค้า จำนวนที่ขอ และยอดคงคลัง 5. ระบุจำนวนที่จ่าย (ระบุไม่ครบตามจำนวนที่ขอเบิก) 6. กดปุ่ม บันทึกจ่ายออกจากคลัง | J25: **ต้องกด จ่ายบางส่วน** | K25: อนุมัติแบบจ่ายบางส่วน (ค้างจ่าย).mp4
C26: กรณียอดคงคลังไม่พอ | E26: 1. เข้าเมนู จ่ายออก >> จ่ายตามใบขอเบิก 2. กดปุ่ม ค้นหา 3. ระบบแสดง ใบขอเบิกพร้อมสถานะ ขอเบิก 4. เลือกรายการ ขอเบิกเพื่อดูรายการสินค้า จำนวนที่ขอ และยอดคงคลัง 5. ระบุจำนวนที่จ่าย (ระบุไม่ครบตามจำนวนที่ขอเบิก) 6. กดปุ่ม บันทึกจ่ายออกจากคลัง | J26: **ต้องกด จ่ายบางส่วน** | K26: กรณียอดคงคลังไม่พอ.mp4
A27: PHA/INV | C27: ปฏิเสธคำขอเบิก
C28: ปฏิเสธ / ยกเลิกใบขอเบิก | E28: ปฏิเสธ รับของระหว่างคลัง 1. เข้าเมนู รับเข้า >> รับเข้าระหว่างคลัง(โอนเข้า) 1. เปิดใบขอเบิกที่มีสถานะ จ่ายออกจากการเบิก 2. กดปุ่ม ปฏิเสธรับเข้าจากเบิก/โอน 3. กดปุ่ม YES 5. สถานะเปลี่ยนเป็น ปฏิเสธรับเข้าจากเบิก และยอดคงเหลือไม่ถูกตัด | K28: ปฏิเสธ ยกเลิกใบขอเบิก.mp4
A29: PHA-INV-004 | B29: 4.9.21.4 / 4.9.21.5 | C29: รับของเข้าคลังตามรายที่เบิก (มีทั้งหมด 3 วิธี)
A30: PHA/INV | C30: วิธีที่ 1 รับเข้าจากใบสั่งซื้อ (PO)
C31: สร้างเอกสาร PR และ อนุมัติเอกสาร PR | E31: 1. เข้าเมนู จัดชื้อ >> ขอซื้อ (PR) 2. กดปุ่ม สร้างใบสั่งชื้อ 3. ระบุผู้จำหน่าย 3. กดปุ่ม เพิ่มสินค้า 4. เลือกรายการสินค้า >> กดปุ่ม เลือก 5. ระบุจำนวนขอชื้อ, ของแถม, Vat, ราคาทุน/หน่วยชื้อ, ผู้ผลิต, เหตุผลในการขอชื้อ, หมายเหตุ 6. กดบันทึกออกใบขอชื้อ 7. เลือกเอกสาร PR 8. กดปุ่ม อนุมัติใบขอชื้อ | K31: สร้างเอกสาร PR และ อนุมัติเอกสาร PR.mp4
C32: สร้างเอกสาร PO | E32: 1. เข้าเมนู จัดชื้อ >> สั่งซื้อ (PO) 2. กดปุ่ม สร้างใบสั่งชื้อ 3. กดปุ่ม รายการใบขอสั่งชื้อ 4. กดปุ่ม ค้นหา 5. เลือกรายการเอกสาร PR (ที่อนุมัติแล้ว) >> เลือก 6. กดปุ่ม บันทึกออกใบสั่งชื้อ 7. กดปุ่ม Yes | K32: สร้างเอกสาร PO.mp4
C33: รับเข้าตาม PO เต็มจำนวน | E33: 1. เข้าเมนู รับเข้า >> รับเข้าจากการสั่งชื้อ(PO) 2. เลือกรายการเอกสาร PO 3. กดติ๊กหน้ารายการที่จะรับเข้า 4. ระบุ Lot No., รับเข้า, รับเข้าของแถม(ถ้ามี) (กรอกรับเต็มจำนวน) 5. บันทึกรับเข้าคลัง 7. รายการจะแสดงสถานะเปลี่ยนจาก สั่งชื้อ เป็น รับเข้า | K33: รับเข้าตาม PO เต็มจำนวน.mp4
C34: รับเข้าตาม PO บางส่วน (ค้างรับ) | E34: 1. เข้าเมนู รับเข้า >> รับเข้าจากการสั่งชื้อ(PO) 2. เลือกรายการเอกสาร PO 3. กดติ๊กหน้ารายการที่จะรับเข้า 4. ระบุ Lot No., รับเข้า, รับเข้าของแถม(ถ้ามี) (กรอกรับไม่เต็มจำนวน) 5. บันทึกรับเข้าคลัง 7. รายการจะยังคงแสดงสถานะเป็น สั่งชื้อ | K34: รับเข้าตาม PO บางส่วน (ค้างรับ).mp4
C35: พิมพ์ใบรับเข้าสินค้า | E35: 1. เข้าเมนู รับเข้า >> รับเข้าจากการสั่งชื้อ(PO) 2. เลือกรายการเอกสาร PO 3. กดปุ่ม พิมพ์ใบรับเข้าสินค้า | K35: พิมพ์ใบรับเข้าสินค้า.mp4
A36: PHA/INV | C36: วิธีที่ 2 รับเข้าจากการโอนระหว่างคลัง
C37: รับเข้าสินค้าที่คลังอื่นโอนมา | E37: 1. เข้าเมนู รับเข้า >> รับเข้าระหว่างคลัง (โอนเข้า) 2. ระบบแสดงรายการทั้งหมด 3. เลือกรายการที่จะรับเข้า 4. ตรวจสอบจำนวนและ Lot >> กดปุ่ม รับเข้าจากเบิก/โอน 5. สถานะเปลี่ยนเป็น รับจากการโอนระหว่างคลัง และยอดคงเหลือเพิ่มขึ้น | K37: รับเข้าสินค้าที่คลังอื่นโอนมา.mp4
C38: พิมพ์ใบรับโอน | E38: 1. เข้าเมนู รับเข้า >> รับเข้าระหว่างคลัง (โอนเข้า) 2. ระบบแสดงรายการทั้งหมด 3. เลือกรายการที่ รับจากการโอนระหว่างคลัง 4. กดปุ่ม พิมพ์ใบรับเข้าจากการเบิก/โอน | K38: พิมพ์ใบรับโอน.mp4
A39: PHA/INV | C39: วิธีที่ 3 รับเข้าจากช่องทางอื่น (บริจาค / เร่งด่วน / อื่นๆ)
C40: สร้างใบรับเข้าแบบบริจาค | E40: 1. เข้าเมนู รับเข้า >> รับเข้าวิธีอื่นๆ (บริจาค/เร่งด่วน/อื่นๆ) 2. ระบบแสดงรายการทั้งหมด 3. กดปุ่ม สร้างใบสั่งชื้อด้วยวิธีอื่นๆ 4. ระบุ ประเภทการรับเข้า (ระบุ รับเข้าจากยาบริจาค) 5. กดปุ่ม เพิ่มสินค้า 6. เลือกรายการสินค้า >> กดปุ่ม เลือก 7. ระบุ Lot, จำนวนรับเข้า 8. กดปุ่ม บันทึกรอรับเข้า | K40: สร้างใบรับเข้าแบบบริจาค.mp4
...

Sheet Mock-Data Inventory
A2: สถานะยา | B2: ชื่อสถานะ | C2: Code | D2: Drug Name
A3: สีเขียว | B3: เกินจุดสูงสุด | C3: med0000028 | D3: ACTEMRA (tocilizumab 80 mg/4 mL) concentrate for solution for infusion
A4: สีเหลือง | B4: ถึงจุดสั่งชื้อ | C4: med0000006 | D4: UTO LINCOMYCIN (lincomycin 3 g/10 mL) solution for injection
A5: สีส้ม | B5: ต่ำกว่าจุดวิกฤต | C5: med0000015 | D5: THENOX (enoxaparin sodium 60 mg/0.6 mL) solution for injection
A6: สีแดง | B6: หมดคลัง | C6: MED0000247 | D6: liposomal AMPHOTERICIN B 50 MG (UC)
A7: สีฟ้า | B7: รอรับเข้า | C7: med0000033 | D7: ARCONA (60 MG) (etoricoxib 60 mg) film-coated tablet
A8: สีม่วง | B8: ใกล้หมดอายุ | C8: med0000027 | D8: ACTEMRA (tocilizumab 400 mg/20 mL) concentrate for solution for infusion
A9: สีขาว | B9: มีพอใช้งาน | C9: med0000004 | D9: FELDENE (piroxicam 500 mg/100 g) gel
A13: User | B13: HN | C13: FName | D13: LName
A14: 1 | B14: 6903474 | C14: Test | D14: Inventory01
A15: 2 | B15: 6903475 | C15: Test | D15: Inventory02
A18: ยาสำหรับใช้ทดสอบ
A19: Code | B19: Drug Name
A20: MED0000323 | B20: VINCRISTINE SULFATE 2 MG/2 ML INJECTION
A21: MED0000278 | B21: SOFOSBUVIR 400 MG +LEDIPASVIR 90 MG TABLET (UC/SS)
A22: 1153035 | B22: COVID-19 VACCINE, 5 ML INJECTION (AZ) - ต่างชาติ

Sheet Scenario- ER
A1: Case_id | B1: TOR_ID | C1: Use case Scenario | D1: Test case ID | E1: Test Step | F1: Status test | I1: NOTE | J1: Pass/Fail
F2: Pass | G2: Fail | H2: N/A
A3: UAT-ER-01 | B3: 4.9.8.1.1 4.9.8.1.2 4.9.8.1.3 4.9.8.2.1 4.9.8.2 (1.9.2.4) 4.9.8.4.2 4.9.8.5 (1.9.5.1) 4.9.8.7.2 4.9.8.8.3 4.9.8.9.1 | C3: ผู้ป่วยมี HN เดิม ตรวจแล้วจำหน่าย แยกตามประเภท Disposition | M3: 1. ต้องเพื่ม MOPH Refer เพิ่มแล้ว 2. ประวัติแพ้ยา เพื่มแล้ว
A4: ER/REG | C4: เปิด Visit ER สิทธิ์ UC
C5: ค้นหาผู้ป่วยด้วย HN / ชื่อ / เลขบัตร | E5: 1. เข้าแอป ห้องฉุกเฉิน >> แดชบอร์ด >> กด "+ คัดกรอง" >> เลือก "ผู้ป่วยมี HN" แล้วค้นหาผู้ป่วยรายเดียวกันทีละวิธี: HN · ชื่อ-สกุล · เลขบัตรประชาชน 2. ผลที่ควรเห็น: ทุกวิธีพบผู้ป่วยรายเดียวกัน | I5: ผู้ทำ: เวชระเบียน | M5: 1. การเงินไม่สามารถปิด Visit ได้ ต้องให้แก้ก่อน 2. Lab Result ไม่สามารถส่งกลับมาได้
C6: ตรวจข้อมูลผู้ป่วยก่อนเปิด Visit | E6: 1. เลือกผู้ป่วย แล้วดูข้อมูลเบื้องต้นก่อนเปิด Visit 2. ผลที่ควรเห็น: เห็นชื่อ-สกุล รูปถ่าย | I6: ผู้ทำ: เวชระเบียน
C7: เปิด Visit ER | E7: 1. ในหน้าต่าง "เปิด Visit ER" เลือกสิทธิการรักษา แล้วกด "ยืนยันเปิด visit" 2. ผลที่ควรเห็น: ขึ้นข้อความ "สร้าง Visit สำเร็จ" และหัวจอผู้ป่วยแสดงเลข EN ของการมาครั้งนี้ | I7: ผู้ทำ: เวชระเบียน
A8: ER/TRIAGE | C8: คัดกรอง (Triage)
C9: กรอกฟอร์มคัดกรองให้ครบ | E9: 1. ในขั้น "1 Triage" กรอกฟอร์มคัดกรองให้ครบ: วิธีนำส่ง (วิธีการมาถึง) · รูปแบบเข้ารับบริการ · สัญญาณชีพ · Pain Score · อาการนำ · แพ้ยา .GCS .MEWS 2. ผลที่ควรเห็น: กรอกได้ครบทุกหัวข้อ และระบบคำนวณ MEWS จากสัญญาณชีพให้อัตโนมัติ | I9: ผู้ทำ: พยาบาลคัดกรอง
C10: เลือกระดับความเร่งด่วน (ESI) | E10: 1. ดูระดับความเร่งด่วน (ESI) ที่ระบบแนะนำ แล้วเลือกระดับที่เหมาะสม 2. ผลที่ควรเห็น: ระบบแสดงระดับที่แนะนำ ผู้ใช้เลือกเองได้ และระบบเลือกโซนที่แนะนำตามระดับให้ (แก้ได้) | I10: ผู้ทำ: พยาบาลคัดกรอง
C11: เลือกโซนและบันทึกคัดกรอง | E11: 1. ตรวจโซน แล้วกด "บันทึก" 2. ผลที่ควรเห็น: หน้าเปลี่ยนเป็น Overview แสดงระดับความเร่งด่วนและโซน · ผู้ป่วยขึ้นในคอลัมน์โซนนั้นบน ER Dashboard | I11: ผู้ทำ: พยาบาลคัดกรอง
A12: ER/EMR | C12: ตรวจรักษา
C13: เปิดผู้ป่วยจาก ER Dashboard | E13: 1. เปิด ER Dashboard แล้วคลิกผู้ป่วยจากรายการบนบอร์ด (Whiteboard) 2. ผลที่ควรเห็น: เข้าหน้าข้อมูลการรับบริการและการรักษาของผู้ป่วยรายนั้นได้ | I13: ผู้ทำ: แพทย์ ER
C14: บันทึก ER Physician Note | E14: 1. เปิดหน้าผู้ป่วย >> ER Physician Note (จากแท็บด้านขวา) บันทึกผลการตรวจ แล้วบันทึก 2. ผลที่ควรเห็น: บันทึกสำเร็จ เปิดดูซ้ำแล้วข้อมูลยังอยู่ | I14: ผู้ทำ: แพทย์ ER
C15: บันทึกประวัติแพ้ยา | E15: 1. แท็บด้านขวา >> บันทึกการแพ้ >> กรอกข้อมูลการแพ้ยา >> กด "บันทึก" 2. ผลที่ควรเห็น: ระบบแสดงรายการแพ้ยาที่ Banner ของผู้ป่วย | I15: ผู้ทำ: แพทย์ ER
C16: ขอ Consult แพทย์เฉพาะทาง | E16: 1. ขอ Consult แพทย์เฉพาะทาง: ใน Section Consult ของฟอร์มฝั่ง ER เลือก "ขอปรึกษาไปยังคลินิก" กรอกรายละเอียด แล้วบันทึก 2. ผลที่ควรเห็น: คำขอ Consult ถูกส่ง และแสดงในรายการ Consult ว่ามาจาก ER | I16: ผู้ทำ: แพทย์ ER
C17: ตอบ Consult | E17: 1. เปิดคำขอ Consult ที่มาจาก ER แล้วตอบคำปรึกษาในช่อง "คำตอบ" 2. ผลที่ควรเห็น: บันทึกคำตอบได้ | I17: ผู้ทำ: แพทย์เฉพาะทาง
C18: ดูคำตอบ Consult | E18: 1. กลับมาดูที่หน้าผู้ป่วย ER 2. ผลที่ควรเห็น: เห็นคำตอบจากแพทย์เฉพาะทาง | I18: ผู้ทำ: แพทย์ ER
C19: สั่ง Order | E19: 1. ไปที่แท๊บขวา >> เลือก "One Day Order" >> เพิ่มรายการยา/LAB/IMAGING/Activity 2. เพิ่มลงตะกร้า >> กดปุ่ม "ส่งคำสั่ง" 3. ผลที่ควรเห็น: แสดงรายการที่หน้า Order Summary | I19: ผู้ทำ: แพทย์ ER
A20: กรณี 1.1 | C20: กรณี 1.1 กลับบ้านปกติ (Disposition) — ผู้ป่วยรายที่ 1
C21: เริ่ม Disposition และกรอกข้อมูลในเอกสาร | E21: 1. Patient Card >> แท็บด้านขวา >> Disposition >> เริ่มจำหน่าย >> เลือก With Approval 2. กรอกข้อมูลที่เป็น Required Field ทั้งหมด 3. ผลที่ควรเห็น: สถานะ Disposition เป็น DRAFT | I21: ผู้ทำ: แพทย์ ER
C22: ลงนามเอกสาร Disposition | E22: 1. กดปุ่ม "ลงนาม" (Sign) เอกสาร Disposition 2. ผลที่ควรเห็น: เอกสารแสดงสถานะลงนามแล้ว | I22: ผู้ทำ: แพทย์ ER
C23: ออกใบรับรองแพทย์ | E23: 1. ออกใบรับรองแพทย์ได้ 2. ผลที่ควรเห็น: สามารถออกเอกสารใบรับรองแพทย์ได้ | I23: ผู้ทำ: แพทย์ ER
A24: กรณี 1.2 | C24: กรณี 1.2 ปฏิเสธการรักษา — ผู้ป่วยรายที่ 2
C25: เริ่ม Disposition แบบ ปฏิเสธการรักษา | E25: 1. ผู้ป่วยขอกลับ: Patient Card >> แท็บด้านขวา >> Disposition >> เริ่มจำหน่าย >> เลือก Against Advice 2. กรอกข้อมูลที่เป็น Required Field ทั้งหมด 3. ผลที่ควรเห็น: สถานะ Disposition เป็น DRAFT | I25: ผู้ทำ: แพทย์ ER
C26: ลงนามเอกสาร Disposition | E26: 1. กดปุ่ม "ลงนาม" (Sign) เอกสาร Disposition 2. ผลที่ควรเห็น: เอกสารแสดงสถานะลงนามแล้ว | I26: ผู้ทำ: แพทย์ ER
A27: กรณี 1.3 | C27: กรณี 1.3 ลงนาม แล้วพบข้อมูลผิด (Reopen) — ใช้ผู้ป่วยจากกรณี 1.1 ต่อได้
C28: Reopen Disposition ที่ ลงนาม แล้ว | E28: 1. เปิด Disposition ของผู้ป่วยกรณี 1.1 ที่ ลงนาม แล้ว พบว่าข้อมูลผิด กดปุ่ม "Reopen" 2. ผลที่ควรเห็น: สามารถดำเนินการแก้ไขข้อมูลที่ต้องการได้ | I28: ผู้ทำ: แพทย์ ER
C29: แก้ข้อมูลและ ลงนาม ใหม่ | E29: 1. แก้ข้อมูลให้ถูกต้อง แล้ว ลงนาม ใหม่ 2. ผลที่ควรเห็น: ลงนาม สำเร็จ ข้อมูลเป็นค่าที่แก้แล้ว | I29: ผู้ทำ: แพทย์ ER
C30: ตรวจผู้ทำและเวลาการ Disposition | E30: 1. ดูข้อมูลการ Disposition 2. ผลที่ควรเห็น: ระบบเก็บชื่อผู้ทำและเวลาของการ Disposition | I30: ผู้ทำ: แพทย์ ER
A31: UAT-ER-02 | B31: 4.9.8.1.3 | C31: ผู้ป่วยใหม่ไม่มี HN มา ER ครั้งแรก
A32: ER/REG | C32: เปิด Visit ER
C33: ลงทะเบียนผู้ป่วยใหม่ (สร้าง HN) | E33: 1. ห้องฉุกเฉิน >> แดชบอร์ด >> กด "+ คัดกรอง" >> เลือก "ผู้ป่วยใหม่" กรอกเลขบัตรประชาชน · ชื่อ · นามสกุล · เพศ · วันเกิด . บันทึกรูปภาพด้วย แล้วกด "ลงทะเบียนผู้ป่วย" 2. ผลที่ควรเห็น: ลงทะเบียนสำเร็จ ได้ HN ใหม่ (ไม่ต้องกรอกที่อยู่ก็ลงทะเบียนได้) | I33: ผู้ทำ: เวชระเบียน
C34: เปิด Visit ER | E34: 1. เปิด Visit ER: เลือกสิทธิการรักษา แล้วกด "ยืนยันเปิด visit" 2. ผลที่ควรเห็น: ขึ้นข้อความ "สร้าง Visit สำเร็จ" และได้เลข EN | I34: ผู้ทำ: เวชระเบียน
A35: ER/TRIAGE | C35: คัดกรอง (Triage)
C36: คัดกรองและเลือกโซน | E36: 1. กรอกฟอร์มคัดกรอง (สัญญาณชีพ · GCS · อาการสำคัญ ฯลฯ) เลือกระดับความเร่งด่วนและโซน แล้วกด "บันทึก" 2. ผลที่ควรเห็น: ผู้ป่วยขึ้นในคอลัมน์โซนที่เลือกบน ER Dashboard และแสดงระดับความเร่งด่วน | I36: ผู้ทำ: พยาบาลคัดกรอง
C37: พิมพ์ป้ายปลายเตียง | E37: 1. หน้า Overview >> แท็บด้านขวา >> พิมพ์ป้ายปลายเตียง 2. ผลที่ควรเห็น: ได้ป้ายปลายเตียงที่มีชื่อผู้ป่วย เลข EN และวันเวลา | I37: ผู้ทำ: พยาบาลคัดกรอง
A38: ER/EMR | C38: ตรวจรักษา
C39: บันทึก ER Physician Note | E39: 1. เปิดหน้าผู้ป่วย >> ER Physician Note (จากแท็บด้านขวา) บันทึกผลการตรวจ แล้วบันทึก 2. ผลที่ควรเห็น: บันทึกสำเร็จ เปิดดูซ้ำแล้วข้อมูลยังอยู่ | I39: ผู้ทำ: แพทย์ ER
A40: ER/DISP | C40: จำหน่าย (Disposition)
...

Sheet ER Issue
A1: Found date | C1: Issue | D1: Module | E1: Solution | F1: Card | G1: Status | H1: ENV. | I1: Dev Status | J1: QA Status
A2: 244623 | B2: 1 | C2: การเงินไม่สามารถปิด Visit ได้ ต้องให้แก้ก่อน | D2: Cashier | E2: ให้เฟรมแก้ให้เพื่อ UAT ก่อน | G2: Done
A3: 244623 | B3: 2 | C3: บัตร Queue ปริ้นเปนภาษาอังกฤษ | D3: ER | E3: ภาษาหลักคนไข้เป็นภาษาอังกฤษ | G3: Done | H3: PRD
A4: 244623 | B4: 3 | C4: ยังออก ผล Lab ไม่ได้ | D4: Lab | E4: ให้เฟรมแก้ให้เพื่อ UAT ก่อน | G4: Done | H4: PRD
A5: 244623 | B5: 4 | C5: ชื่อผู้บันทึก Discharge เป็นภาษาต่างด้าว | D5: ER | E5: รอดิวเอาขึ้น | G5: Done | H5: PRD
A6: 244623 | B6: 5 | C6: CPR Progression : ติด Text แดง + Save ไม่ได้ | D6: ER | E6: - [SBH-2390: \[Bug \] \[ CPR Progression \] SPH Prod](https://linear.app/cortexcloud/issue/SBH-2390/bug-cpr-progression-sph-prod) | G6: Done | H6: PRD
A7: 244623 | B7: 6 | C7: บันทึกแพ้ยาไม่ได้ > ค้นหาชื่อยาไม่เจอ | D7: Med | E7: แก้แล้ว | G7: Done | H7: PRD
A8: 244623 | B8: 7 | C8: บันทึก Med Reconcile ไม่ได้ | D8: Med | E8: แก้แล้ว | G8: Done | H8: PRD
A9: 244624 | B9: 8 | C9: คนไข้ไป OPD | D9: ER | E9: รอ Build | G9: Done | H9: PRD
A10: 244624 | B10: 9 | C10: Nurse Task list รับงาน > Activity ไม่ได้ | D10: ER | E10: รอแก้ | G10: Done | I10: Deploy ขึ้น SBH แล้ว
A11: 244624 | B11: 10 | C11: บัตร คิว แสดง ความรุนแรง แทน ESI | D11: ER | E11: แก้แล้ว | G11: Done | H11: PRD
A12: 244624 | B12: 11 | C12: Consult แสดงชื่อ แผนกต้นทางผิด | D12: Consult | E12: แก้ Data base | G12: Done | H12: PRD
A13: 244627 | B13: 12 | C13: Treatment Timeline | D13: ER | E13: CPR ต้อง เปิด View ได้ | F13: [SBH-2442: \[ER \] \[ Treatment Timeline \] CPR progression](https://linear.app/cortexcloud/issue/SBH-2442/er-treatment-timeline-cpr-progression) | G13: Done | H13: Dev-X | I13: Modern ดูให้อยู่
A14: 244627 | B14: 13 | C14: GCS | D14: ER | G14: Done | H14: PRD
A15: 244627 | B15: 14 | C15: เพิ่ม Menu บน Disposition | D15: ER | E15: เพิ่ม Menu | G15: Done | H15: Dev-X
A16: 244627 | B16: 15 | C16: Re-Open visit to ER | D16: ER | G16: Done | H16: Dev-X
A17: 244627 | B17: 16 | C17: Order set ER 1 | D17: ER | E17: เพิ่ม Order Set | G17: pending | H17: PRD
A18: 244627 | B18: 17 | C18: Order set CPR 1 | D18: ER | E18: เพิ่ม Order Set | G18: pending | H18: PRD
A19: 244627 | B19: 18 | C19: บัตร ปชช | D19: ER | E19: อ่านบัตร ประชาชน | G19: Done | H19: Dev-x
A20: 244627 | B20: 19 | C20: Save รูปภาพ | D20: ER | E20: Save รูปภาพ ผู้ป่วยใหม่ | G20: Done | H20: Dev-x
A21: 244627 | B21: 20 | C21: โรงพยาบาล ต้นทาง ถูก แต่ SBH PRD ไม่มี Code | D21: ER | E21: Work around - เลือก รพ ที่มี Code ตอนเปิด Visit ER | G21: Done | H21: PRD
A22: 244627 | B22: 21 | C22: ผู้ป่วยรับ Refer มา ยังไม่ไป Discharge | D22: ER | E22: หลุดเงื่อนไข | G22: pending | H22: PRD
A23: 244627 | B23: 22 | C23: MOPH Refer -> ติดประกันสังคม | D23: ER | E23: ทำได้แล้ว | G23: Done | H23: PRD
A24: 244627 | B24: 23 | C24: ผู้ป่วยรับ Refer มา ยังไม่ไป Discharge | D24: ER | E24: หลุดเงื่อนไข | G24: pending | H24: PRD
A25: 244627 | B25: 24 | C25: MOPH Refer -> ติดประกันสังคม | D25: ER | E25: ทำได้แล้ว | G25: Done | H25: PRD
A26: 244630 | B26: 25 | C26: Disposition -> สามารถเปิด ประวัติ History ได้ | D26: ER | F26: SBH-2462: [ER] [ Disposition ] แสดง Disposition From ย้อนหลัง​ | G26: pending | K26: SBH-2462 [ER] [ Disposition ] แสดง Disposition From ย้อนหลัง
A27: 244627 | B27: 26 | C27: Treatment Timeline | D27: ER | E27: เพิ่มความรุนแรง ของการ | F27: SBH-2482: [ER ] [ Treatment Timeline ] แสดงความรุนแรงของ ESI Level​ | G27: pending | H27: PRD | K27: SBH-2482 [ER ] [ Treatment Timeline ] แสดงความรุนแรงของ ESI Level
A28: 244630 | B28: 27 | C28: ป้ายปลายเตียง | D28: ER | E28: HN , DOB | F28: SBH-2471 [ER][Triage] Add patient age and HN to bedside name badge | G28: Done | K28: SBH-2471 [ER][Triage] Add patient age and HN to bedside name badge
A29: 244630 | B29: 28 | C29: CPR Progression : | D29: ER | G29: pending
A31: Feedback | H31: Dev Status | I31: QA Status
A32: 1 | C32: Note Nurse คล้ายๆ กับ Progress Note แต่เป็น AIE form แล้วขอเมนูด้านขวา 1 อันถ้าเป็นไปได้ | E32: มีของบน Dev-X แต่บัค | G32: แก้ก่อน UAT | H32: Done | J32: [SBH-2441: \[ER \] Nursing Record](https://linear.app/cortexcloud/issue/SBH-2441/er-nursing-record)
A33: 2 | C33: ขอเพิ่มรูปบาดแผล | E33: Done | G33: Done
A34: 3 | C34: ปุ่มบันทึก ฝั่งพยาบาลอยากให้ลอยแบบหมอ | E34: Done: Control C ได้ที่ PE | G34: แก้ก่อน UAT | H34: Done | I34: Done on Dev-X
A35: 4 | C35: อยากเก็บประวัติของแต่ล่ะโซนคนไข้ | E35: พี่เจไม่เคลีย_พี่มดจะเพิ่ม ESI Score บน Treament Time line ไว้ตรงคัดกรองครั้งแรกกับ Retriage | G35: แก้ก่อน UAT | H35: รอ Assign
A36: 5 | C36: คนไข้มี 3 สถานะ 1. ก่อนรักษา 2. กำลังรักษา 3. รักษาแล้ว | E36: Comment จากพี่เบียร์ | G36: Done
A37: 6 | C37: หมอไม่กรอก Disposition แต่ขอย้ายคนไข้มาที่โซนรอจำหน่ายเลยได้ไหม แล้วค่อย | E37: Comment จากพี่เบียร์ | G37: Done
A38: 7 | C38: บริเวณโซน อยากให้แก้จากคำว่า "ใช้" เป็นอื่น | D38: Panding | E38: แก้ไขเป็น In use | G38: รอ | J38: [SBH-2443: \[ER\] triage - Revise wording in select zone](https://linear.app/cortexcloud/issue/SBH-2443/er-triage-revise-wording-in-select-zone)
A39: 8 | C39: Vital Sign Overview ควรซ่อนได้ | E39: ตัดทิ้ง | G39: แก้ก่อน UAT | H39: Done | I39: Done on Dev-X
A40: 9 | C40: Vital Sign แก้ไขเวลาเกินค่ามาตราฐาน | E40: แก้ไข | G40: แก้ก่อน UAT | H40: Done | J40: [SBH-2456: \[ER \] \[ V/S \] Form - Section Vital Sign](https://linear.app/cortexcloud/issue/SBH-2456/er-vs-form-section-vital-sign)
A41: 10 | C41: Vital Sign อยากให้แสดงรอบล่าสุด | E41: Comment จากพี่เบียร์ | G41: Done
...

Sheet Mock-Data ER
A2: Code | B2: Type | D2: พยาบาลที่จะเข้าร่วมทั้งหมด | G2: หมอยังไม่ระบุจำนวน | J2: ข้อ | K2: HN | L2: สถานะและเงื่อนไข
A3: ACT0005007 | B3: ค่าห้อง | D3: 7ตค68 (8-12น.) | J3: 1 | K3: 0 | L3: ยังไม่มี Visit ER, สิทธิ UC. รายแรกต้องมีรูปถ่ายและประวัติแพ้ยาเดิม (กรณี 1.3 Reopen ใช้รายเดียวกับ 1.1)
A4: MED0000260 | B4: ยา | D4: 1.นางกรองแก้ว วัชรินทร์รัตน์ | J4: 2 | K4: 0 | L4: ข้อมูลผู้ป่วยใหม่ 1 ชุด เลขบัตรประชาชนไม่ซ้ำ และมีรูป
A5: MED0000619 | B5: ยา | D5: 2.นส.แพรวพรรณ รอดศรี | J5: 3 | K5: 0 | L5: สร้างเป็นผู้ป่วยระบุตัวตนไม่ได้ตอนเล่น
A6: MSP0000331 | B6: เวชภัณฑ์ | D6: 3.นายปรีชา ทิศลี | J6: 4 | K6: 1 | L6: อยู่ใน ER แล้ว คัดกรองและตรวจแล้ว มี Order Lab / IMG รอผล เพราะข้อนี้เริ่มที่ Disposition แบบ Admission
A7: MSP0002576 | B7: เวชภัณฑ์ | J7: 5 | K7: 1 | L7: เปิด Visit ER แล้ว ยังไม่คัดกรอง กรณีย่อยละ 1 ราย
A8: LAB0000931 | B8: blood | D8: 7ตค69(13-16น.) | J8: 6 | K8: 0 | L8: คัดกรองแล้ว อยู่ในโซน
A9: LAB0000001 | B9: lab | D9: 1.นส.ทัศณีย์ ประสงค์ | J9: 7 | K9: 0 | L9: ข้อมูลผู้ป่วย 2 ชุดไว้เพิ่มในเหตุการณ์
A10: LAB0000077 | B10: lab | D10: 2.นส.ปทุมทิพย์ เกตุบุญมี | J10: 8 | K10: 0 | L10: คัดกรองแล้ว รอตรวจในโซน ต้องเตรียมล่วงหน้านานพอให้เวลารอเกินเป้าหมาย
A11: LAB0000092 | B11: lab | D11: 3.นส.นนทลี เปรี่ยมสูงเนิน | J11: 9 | K11: 0 | L11: มี Order จากแพทย์จนเกิดงานพยาบาล อย่างน้อย 1 งานสถานะ "รอรับงาน" และ 1 งานสถานะ "กำลังทำ"
A12: IMG0000194 | B12: img | J12: 10 | K12: 1 | L12: ยังไม่มี Visit ER (ใช้เป็นคนที่เปิดผิด)
A13: IMG0000420 | B13: img | D13: 8ตค69(8-12น.) | J13: 11 | K13: 0 | L13: เปิด Visit ER แล้ว ยังไม่คัดกรอง
A14: ACT0005224 | B14: activity | D14: 1.นส.จุฬารัตน์ เอี่ยมสอาด | J14: 12 | K14: 0 | L14: รายงาน ใช้ข้อมูลจากข้ออื่น
A15: ACT0005570 | B15: activity | D15: 2.นส.สุภาพร ฉายาวาศ | J15: 13 | K15: 1 | L15: มี Visit เปิดอยู่ที่ OPD ในวันนั้น
A16: ACT0005702 | B16: activity | D16: 3.นส.สุพิชชาพร ปิ่นน้อย | J16: 14 | K16: 1 | L16: รายการ Refer ในระบบ MOPH Refer ที่ส่งมา รพ.สระบุรี 1 รายการ
A17: ACT0004968 | B17: activity
A18: ACT0000062 | B18: activity | D18: 8ตค69(13-16น.)
A19: ACT0004961 | B19: activity | D19: 1.นางณัฐนันท์ มาลา | J19: 7 เช้า | K19: 5
A20: ACT0004939 | B20: activity | D20: 2.นส.โชติกา ธนาภัคนรกุล
A21: ACT0004950 | B21: activity | D21: 3.นส.อภิญญาใจคง
A22: ACT0004729 | B22: activity
A23: ACT0005733 | B23: activity
A24: ACT0006013 | B24: activity
A25: ACT0005729 | B25: activity

Sheet List Flow E2E For BizSim
A2: Use case Scenario
A3: Case_Id | B3: Senario | C3: Status test | F3: NOTE
C4: Pass | D4: Fail | E4: N/A
A5: Appointment | B5: กลุ่ม Appointment - คนไข้มีนัดหมายล่วงหน้า (10 UC)
A6: APM-OPD-001 | B6: คนไข้มีนัดเข้ารับบริการปกติ (พบแพทย์ > ทำนัด FU > การเงิน > รับยา > กลับบ้าน) | D6: Fail | F6: 1. Paint Scroe ตกขอบ 2. บันทึกแล้วไม่ Save ให้ หรือ ช้า 3. หน้านัดหมายไม่ควรสั่งยาได้ (พยาบาลสั่งได้) 4. เช็คอีกทีว่าแก้ไข สั่งยา แต่ขึ้นเป็นหมวด Procedure (ใบนัดหมาย) 5. ไม่สามารถปริ้นบัตรคิวได้ {"error":{"class":"NotFound","message":"print template not found"}} 6. ไม่สามารถ Discharge ได้ - "message": "ErrSomeProductIsNotFound", 7. ขาดรวมปุ่ม ปริ้นเอกสารต่างๆ 8. ไม่สามารถชำระได้เนื่องจากไม่มี Queue การเงิน 9. ห้องการเงินไม่มีรายการคนไข้ขึ้น (ต่อเนื่องจากข้อ 8)
A7: APM-OPD-002 | B7: คนไข้มีนัดเข้ารับบริการปกติ มีตรวจ LAB / IMG ก่อนพบแพทย์ | D7: Fail | F7: 1. ไม่สามารถสร้าง Order Imaging วันอื่นๆ ได้ 2. ในกรณีมีนัดหมายทำ Lab และ รังสี ยังไม่มีใบนำทาง 3. Lab มีกรายการนัดหมายแต่ไม่สามารถทำอะไรต่อได่ 4. X-Ray ไม่มีรายการขึ้นในกรณีที่เพิ่ม Order ผ่าน Appointment
A8: APM-OPD-003 | B8: คนไข้มีนัด เข้าพบแพทย์ แล้วแพทย์สั่งตรวจ LAB / IMG อ่านผลภายในวัน | D8: Fail | F8: 1. Lab ไม่สามารถส่งผลกลับมาได้
A9: APM-OPD-004 | B9: คนไข้มีนัด แพทย์สั่งตรวจ LAB / IMG อ่านผลภายในวัน (ฝากแพทย์ท่านอื่นอ่านผล) | D9: Fail | F9: 1. ไม่สามารถพิมพ์ใบคำสั่ง Imaging ได้ "class": "ServiceUnavailable", - "message": "imaging order document template is unavailable: record not found" Lab: 2. ไม่สามารถพิมพ์ป้ายติด Speciment ได้ {"error":{"class":"NotFound","message":"print template not found"}} 3. ไม่สามารถส่งผล Lab กลับมาได้ Imaging 4. ไม่สามารถพิมพ์ใบยิมยอมได้ไม่มี Template 5. แพทย์ ไม่สามารถพิมพ์ สรุป ได้ "class": "IllegalArgumentException", "message": "Template not found: tmh_opd_summary", "detail": "INVALID_REQUEST" 6. ไม่สามารถพิิมพ์ใบสรุปใบให้คำปรึกษาได้ (ไม่มี Template) 7. ไม่สามารถพิมพ์ฟอร์มตอบกลับการให้คำปรึกษา (ไม่มี Template) 8. ไม่สามารถพิมพ์ OPD Slip (ไม่มี Template) - น่าจะหาย 9. ต้อง Mapping คำศัพท์เพิ่มเติม 10. ยังไม่สามารถพิมพ์ฉลากยาได้ 11. ยังไม่มีฉลากยา ภาษาอังกฤษ + พิมพ์ใบส่งไปรษณีย์ | G9: Note!! ยังต้องคุยเรื่อง Queue ทั้ง Lab / X-ray ต้องมีใบคิวยังไงออกที่ไหน
A10: APM-OPD-005 | B10: คนไข้มีนัด ไม่มียากลับบ้าน | D10: Fail | G10: Note!! ถ้าไม่สั่งยาคิวการเงินต้องออกยังไง
A11: APM-OPD-006 | B11: คนไข้มีนัด มียา co-pay / ยาที่ต้องมีเอกสารประกอบการสั่ง (DUE, PA) / CDSS แจ้งเตือน > จ่ายเงิน > รับยา | D11: Fail
A12: APM-OPD-007 | B12: คนไข้มีนัด หมอสั่งยา Stat > จ่ายค่ายา > ฉีดยา > จ่ายเงิน > รับยากลับบ้าน | D12: Fail
A13: APM-OPD-008 | B13: คนไข้มีนัด พบแพทย์ ทำหัตถการ (ภายในวัน / สั่งล่วงหน้า) > การเงิน > ห้องยา | D13: Fail
A14: APM-OPD-009 | B14: คนไข้มีนัด พบแพทย์ หมอสั่ง Refill ยา | E14: N/A | F14: 1. ยังอยู่ในช่วง Inprogress
A15: APM-OPD-010 | B15: คนไข้ขอใบรับรองแพทย์ชนิดต่างๆ | C15: Pass
A16: Walk in | B16: กลุ่ม Walk in - คนไข้ไม่มีนัด หรือมาไม่ตรงนัด (5 UC)
A17: WLK-OPD-001 | B17: คนไข้ Walk in พบแพทย์ | D17: Fail
A18: WLK-OPD-002 | B18: คนไข้ Walk in ไม่ได้พบแพทย์ ทำนัดหมายแทน | C18: Pass
A19: WLK-OPD-003 | B19: คนไข้มีนัด แต่มาไม่ตรงนัด | D19: Fail
A20: WLK-OPD-004 | B20: คนไข้มาเจาะเลือดล่วงหน้า (ก่อนวันนัดพบแพทย์) | D20: Fail | F20: 1. ยังไม่สามารถพิมพ์ใบนำทางได้ 2. ยังไม่สามารถส่งผลเล็ปกลับได้
A21: WLK-OPD-005 | B21: คนไข้มาตรวจ IMG ล่วงหน้า (ก่อนวันนัดพบแพทย์) | D21: Fail | F21: 1. ไม่สามารถทำ Imaging ล่วงหน้าได้ ไม่มีรายการให้เปิด Visit ล่วงหน้าเหมือน Lab
A22: Refill | B22: กลุ่ม Refill ยา - คนไข้มารับยาตามแผน Refill (2 UC)
A23: RFL-OPD-001 | B23: คนไข้มารับยา Refill ตรงวัน | E23: N/A | F23: 1. ยังอยู่ในช่วง Inprogress
A24: RFL-OPD-002 | B24: คนไข้มารับยา Refill ไม่ตรงวัน (มาก่อน / เลยกำหนด) | E24: N/A | F24: 1. ยังอยู่ในช่วง Inprogress
A25: Injection | B25: กลุ่มมีนัดฉีดยา / ทำแผล ไม่พบแพทย์ (1 UC)
A26: INJ-OPD-001 | B26: คนไข้มีนัดฉีดยา / ทำแผล ไม่พบแพทย์ | D26: Fail | F26: 1. ยังติดปัญหาไม่สามารถเปิด Visit คนไข้ไปห้องหัตการโดยไม่พบแพทย์ได้
A27: Admit | B27: กลุ่ม Admit - คนไข้ OPD ต้องนอนโรงพยาบาล (3 UC)
A28: ADM-OPD-001 | B28: คนไข้ Admit | C28: Pass
A29: ADM-OPD-002 | B29: คนไข้ Admit สั่งตรวจก่อนขึ้น ward | D29: Fail
A30: ADM-OPD-003 | B30: คนไข้ Admit ย้ายค่าใช้จ่ายจาก OPD ไป IPD | C30: Pass
A31: ODS | B31: กลุ่ม ODS - หัตถการ One Day Surgery (2 UC)
A32: ODS-OPD-001 | B32: คนไข้มาตรวจ หมอสั่ง ODS ภายในวัน | D32: Fail
A33: ODS-OPD-002 | B33: หมอนัดมาทำ ODS วันอื่น | E33: N/A | F33: 1. ไม่สามารถ Check-in ห้อง OR (ไม่มี Queue Type)
A34: Inventory | B34: กลุ่มคลังยา - scenario เดิมของ sheet Scenario-OPD E2E (1 UC)
A35: PHA-INV-001 | B35: สร้างใบยาในระบบ และ ระบบคลังทำการตัด Stock รายการยานั้นๆ | C35: Pass

Sheet Scenario-OPD BizSim
A1: Case_id | B1: TOR_ID | C1: Use case Scenario | D1: Test case ID | E1: Test Step | F1: Status test | I1: NOTE
F2: Pass | G2: Fail | H2: N/A
A3: Appointment | C3: กลุ่ม Appointment - คนไข้มีนัดหมายล่วงหน้า
A4: APM-OPD-001 | C4: คนไข้มีนัดเข้ารับบริการปกติ (พบแพทย์ > ทำนัด FU > การเงิน > รับยา > กลับบ้าน)
A5: OPD/REG | C5: เปิด Visit ตามนัดหมาย | E5: 1. เข้าแอพ เวชระเบียน > ค้นหาผู้ป่วย 2. กรอก HN แล้วกด Enter 3. กดปุ่ม + Visit ใหม่ มุมขวาบน 4. ตรวจสอบข้อมูลนัดหมายของวันนี้ที่ระบบแสดง 5. ยืนยันสิทธิการรักษา 6. กดปุ่ม สร้าง 7. ตรวจสอบว่าได้เลข VN พิมพ์ใบนำทาง และได้เลขคิวห้องตรวจ | F5: Pass
A6: OPD/EMR | C6: พยาบาลคัดกรองก่อนพบแพทย์ | E6: 1. เปิดผู้ป่วยจากหน้า รายการผู้ป่วยนอก 2. บันทึกสัญญาณชีพ (V/S) 3. เลือกดูเมนู ฟอร์มคัดกรอง ที่ Side bar ทางขวามือ 4. กรอกข้อมูลการคัดกรองและบันทึก 5. ตรวจสอบว่าค่า Vital sign แสดงบน Patient Banner | F6: Pass | I6: Note 1. Paint Scroe ตกขอบ
A7: OPD/EMR | C7: แพทย์เรียกคิวและลง OPD Note | E7: 1. กดเลือกคนไข้จากหน้า รายการผู้ป่วยนอก ที่สถานะพร้อมตรวจ 2. ระบบจะแสดง OPD Note ขึ้นมา 3. ลงข้อมูลการรักษา 4. ลง diagnosis 5. บันทึกข้อมูล | G7: No Pass | I7: 1. ภาพ Body Chart ไม่มาแสดง (แสดงแล้ว) 2. บันทึกแล้วไม่ Save ให้ หรือ ช้า
A8: OPD/CPOE | C8: แพทย์สั่งยากลับบ้าน (Home med) | E8: 1. ระบบจะแสดง Section ในส่วนของการ Order ขึ้นมา 2. ทำการสั่งยา เลือก Home med 3. ระบุวิธีการใช้ยา / จำนวนยาที่จ่าย / หมายเหตุอื่นๆ 4. กดปุ่ม เพิ่ม order 5. กดปุ่ม Sign เพื่อส่งคำสั่งไปห้องยา | F8: Pass
A9: OPD/EMR | C9: แพทย์ทำนัดหมาย FU และกดตรวจเสร็จ | E9: 1. เลือกดูเมนู สร้างนัดหมาย ที่ Side bar ทางขวามือ 2. เลือก คลินิก แพทย์ ประเภทการนัดหมาย แล้ว Slot ที่ต้องการ 3. กดบันทึก 4. ตรวจสอบนัดหมายที่เมนู ประวัติการนัดหมาย 5. กดปุ่มตรวจเสร็จ | F9: Pass | I9: หน้านัดหมายไม่ควรสั่งยาได้ (พยาบาลสามารถสั่งยาได้) **เช็คอีกทีว่าแก้ไข สั่งยา แต่ขึ้นเป็นหมวด Procedure
A10: OPD | C10: พยาบาล Discharge และปริ้นบัตรคิว | E10: 1. กดเลือกคนไข้จากหน้า รายการผู้ป่วยนอก ที่สถานะ ตรวจเสร็จ 2. เลือกประเภทการ Discharge เป็น กลับบ้าน 3. ปริ้นท์บัตรคิว การเงิน / ห้องยา ที่หน้า Discharge summary 4. ปริ้นท์บัตรนัดที่เมนู ประวัตินัดหมาย ที่ side bar ซ้ายมือ | G10: No Pass | I10: 1. ไม่สามารถปริ้นบัตรคิวได้ {"error":{"class":"NotFound","message":"print template not found"}} 2. ไม่สามารถ Discharge ได้ - "message": "ErrSomeProductIsNotFound", 3. ขาดรวมปุ่ม ปริ้นเอกสารต่างๆ 4. ไม่สามารถชำระได้เนื่องจากไม่มี Queue การเงิน
A11: OPD/PHA | C11: ห้องยาสร้างใบยาก่อนชำระเงิน | E11: 1. ไปที่เมนูห้องยา > เลือกห้องยาชั้น 1 2. เลือกคนไข้และรายการยา แล้วกดปุ่มสร้างใบยา | F11: Pass
A12: OPD/CASH | C12: คนไข้ชำระเงินที่การเงิน | E12: 1. เข้าหน้าการเงิน (Cashier) แล้วเปิดรายการของผู้ป่วยจากคิวการเงิน 2. ตรวจสอบ / แก้ไข Chart item สิทธิการรักษา และส่วนลด 3. สร้าง invoice 4. รับชำระเงินและออกใบเสร็จ 5. ปิดสิทธิ์ผ่าน EDC / End point | G12: No Pass | I12: 1. ไม่สามารถชำระได้เนื่องจากไม่มี Queue การเงิน
A13: OPD/PHA | C13: ห้องยาจัดยา เรียกคิว และจ่ายยา | E13: 1. ไปที่เมนูห้องยา > เลือกห้องยาชั้น 1 2. เลือกคนไข้และรายการยา 3. กดปุ่มจัดยาแล้ว 4. กดปุ่มยืนยันรอจ่าย 5. เรียกคิวคนไข้ที่ห้องยา 6. เลือก 3จุด ด้านหลังรายการยา แล้วเลือก ยืนยันจ่ายยา | F13: Pass
A14: APM-OPD-002 | C14: คนไข้มีนัดเข้ารับบริการปกติ มีตรวจ LAB / IMG ก่อนพบแพทย์
A15: OPD/REG | C15: เปิด Visit ตามนัด และ Check-in ห้อง Lab / Img | E15: 1. เปิด Visit ตามนัดหมาย จนได้เลข VN 2. พิมพ์ใบนำทาง 3. กด Check-in ห้อง Lab / Img 4. ตรวจสอบเลขคิว Lab/X-ray ที่ระบบออกให้ 5. ตรวจสอบว่ารายการเข้าสู่ Worklist ของห้อง Lab/X-ray/Img | G15: No Pass | I15: 1. ไม่สามารถสร้าง Order Imaging วันอื่นๆ ได้ 2. ในกรณีมีนัดหมายทำ Lab และ รังสี ยังไม่มีใบนำทาง 3. Lab มีกรายการนัดหมายแต่ไม่สามารถทำอะไรต่อได่ 4. X-Ray ไม่มีรายการขึ้นในกรณีที่เพิ่ม Order ผ่าน Appointment
A16: OPD/LAB | C16: ห้อง Lab / Img รับรายการและออกผล | E16: 1. เข้า Cortex Worklist ของห้อง Lab/X-ray/Img 2. เลือกรายการผู้ป่วยแล้วกด Check-in 3. เก็บ Specimen และพิมพ์ Sticker (LN) ติด Tube (เฉพาะ Lab) 4. กด Run Lab / IMG ส่งไปยัง LIS / RIS 5. รับผลกลับเข้าระบบ 6. ให้แพทย์ Authorize ผล จนสถานะเป็นเสร็จสิ้น | G16: Block
A17: OPD/EMR | C17: พยาบาลคัดกรองและเช็คสถานะผล Lab / Img | E17: 1. บันทึกสัญญาณชีพ (V/S) และฟอร์มคัดกรอง 2. เลือกดูเมนู Lab Result / Imaging result ที่ Side bar ทางซ้ายมือ 3. ตรวจสอบว่าสถานะผลตรงกับสถานะจริงในห้อง Lab 4. ส่งผู้ป่วยเข้าคิวห้องตรวจ | G17: Block
A18: OPD/EMR | C18: แพทย์ดูผล Lab / IMG แล้วตรวจ | E18: 1. เรียกคิวผู้ป่วยเข้าห้องตรวจ 2. เลือกดูเมนู Lab Result และ Imaging result ที่ Side bar ทางซ้ายมือ 3. ตรวจสอบว่าผลตรงกับที่ห้อง Lab ส่งมา 4. ลง OPD Note และ diagnosis | G18: Block | M18: ตรวจสอบยอดคงเหลือคลังต้นทางหลังโอน Fix.mp4
A19: OPD/CPOE | C19: แพทย์สั่งยากลับบ้านและทำนัด FU | E19: 1. สั่งยา Home med และกด Sign 2. สร้างนัดหมาย FU 3. กดปุ่มตรวจเสร็จ | G19: Block
A20: OPD | C20: พยาบาล Discharge และปริ้นบัตรคิว | E20: 1. เลือกประเภทการ Discharge เป็น กลับบ้าน 2. ปริ้นท์บัตรคิว การเงิน / ห้องยา ที่หน้า Discharge summary 3. ปริ้นท์บัตรนัด | G20: Block
A21: OPD/CASH | C21: คนไข้ชำระเงิน (รวมค่า Lab / IMG) | E21: 1. เปิดรายการของผู้ป่วยจากคิวการเงิน 2. ตรวจสอบว่าค่า Lab / IMG ถูกรวมใน Chart item 3. สร้าง invoice และรับชำระเงิน 4. ปิดสิทธิ์ผ่าน EDC / End point | G21: Block
A22: OPD/PHA | C22: ห้องยาจัดยาและจ่ายยา | E22: 1. สร้างใบยา > จัดยา > ยืนยันรอจ่าย 2. เรียกคิวคนไข้ 3. ยืนยันจ่ายยา | G22: Block
A23: APM-OPD-003 | C23: คนไข้มีนัด เข้าพบแพทย์ แล้วแพทย์สั่งตรวจ LAB / IMG อ่านผลภายในวัน
A24: OPD/REG | C24: เปิด Visit ตามนัดหมาย | E24: 1. ค้นหาผู้ป่วยด้วย HN 2. กดปุ่ม + Visit ใหม่ และตรวจสอบนัดหมายของวันนี้ 3. ยืนยันสิทธิการรักษา แล้วกดปุ่ม สร้าง 4. พิมพ์ใบนำทางและเลขคิวห้องตรวจ | F24: Pass
A25: OPD/EMR | C25: พยาบาลคัดกรองและแพทย์ตรวจ | E25: 1. บันทึก V/S และฟอร์มคัดกรอง 2. แพทย์เรียกคิวผู้ป่วยเข้าห้องตรวจ 3. ลงข้อมูลการรักษาและ diagnosis ใน OPD Note | F25: Pass
A26: OPD/CPOE | C26: แพทย์สั่ง LAB ต้องการทราบผลภายในวันที่สั่ง | E26: 1. ค้นหารายการ lab ที่ต้องการสั่งใน order search 2. ระบบจะแสดงรายการที่กำหนดไว้ 3. เลือก Priority และ วันที่ต้องการทราบผลเป็นวันนี้ 4. ระบบจะไม่ให้เลือกวันที่เมื่อเลือกเป็นวันนี้ 5. กดปุ่มเพิ่ม order 6. กดปุ่ม Sign เพื่อส่งการสั่งไปยังห้องปฏิบัติการ | F26: Pass
A27: OPD/CPOE | C27: แพทย์สั่ง IMG ต้องการทราบผลภายในวันที่สั่ง | E27: 1. ค้นหารายการ Img ที่ต้องการสั่งใน order search 2. เลือก Priority และ วันที่ต้องการทราบผลเป็นวันนี้ 3. กดปุ่มเพิ่ม order 4. กดปุ่ม Sign เพื่อส่งการสั่งไปยังห้องปฏิบัติการ | F27: Pass
A28: OPD/LAB | C28: ห้อง Lab / Img ทำรายการและส่งผลกลับ | E28: 1. Check-in ผู้ป่วยที่ Cortex Worklist 2. เก็บ Specimen และพิมพ์ Sticker (เฉพาะ Lab) / ฉายรังสี (IMG) 3. กด Run Lab / IMG ส่งไปยัง LIS / RIS 4. รับผลกลับเข้าระบบ 5. แพทย์ Authorize ผล | G28: No Pass | I28: 1. Lab ไม่สามารถส่งผลกลับมาได้
A29: OPD/EMR | C29: แพทย์อ่านผลและสรุปการรักษาภายในวัน | E29: 1. เรียกคนไข้กลับเข้าห้องตรวจ 2. เปิดดูผล Lab / IMG ที่ส่งกลับมา 3. ลง diagnosis เพิ่มเติมใน OPD Note 4. สั่งยากลับบ้าน 5. ทำนัดหมาย FU 6. กดปุ่มตรวจเสร็จ | F29: Pass
A30: OPD | C30: พยาบาล Discharge และปริ้นบัตรคิว | E30: 1. Discharge เป็น กลับบ้าน 2. ปริ้นท์บัตรคิว การเงิน / ห้องยา 3. ปริ้นท์บัตรนัด | G30: No Pass
A31: OPD/CASH | C31: คนไข้ชำระเงิน | E31: 1. ตรวจสอบว่าค่า Lab / IMG ที่สั่งภายในวันถูกรวมใน Chart item 2. สร้าง invoice และรับชำระเงิน 3. ปิดสิทธิ์ผ่าน EDC / End point | F31: Pass
A32: OPD/PHA | C32: ห้องยาจัดยาและจ่ายยา | E32: 1. สร้างใบยา > จัดยา > ยืนยันรอจ่าย 2. เรียกคิวคนไข้ 3. ยืนยันจ่ายยา | G32: No Pass
A33: APM-OPD-004 | C33: คนไข้มีนัด แพทย์สั่งตรวจ LAB / IMG อ่านผลภายในวัน (ฝากแพทย์ท่านอื่นอ่านผล)
A34: OPD/REG | C34: เปิด Visit ตามนัดหมาย | E34: 1. ค้นหาผู้ป่วยและกดปุ่ม + Visit ใหม่ 2. ตรวจสอบนัดหมายของวันนี้ ยืนยันสิทธิ แล้วกดปุ่ม สร้าง 3. พิมพ์ใบนำทางและเลขคิวห้องตรวจ | F34: Pass
A35: OPD/EMR | C35: พยาบาลคัดกรองและแพทย์เจ้าของไข้ตรวจ | E35: 1. บันทึก V/S และฟอร์มคัดกรอง 2. แพทย์เรียกคิวและลง OPD Note | F35: Pass
A36: OPD/CPOE | C36: แพทย์เจ้าของไข้สั่ง LAB / IMG อ่านผลภายในวัน | E36: 1. ค้นหารายการ lab / img ใน order search 2. เลือก Priority และวันที่ต้องการทราบผลเป็นวันนี้ 3. กดปุ่มเพิ่ม order แล้วกดปุ่ม Sign | G36: No Pass | I36: 1. ไม่สามารถพิมพ์ใบคำสั่ง Imaging ได้ "class": "ServiceUnavailable", - "message": "imaging order document template is unavailable: record not found"
A37: OPD/LAB | C37: ห้อง Lab / Img ทำรายการและส่งผลกลับ | E37: 1. Check-in ผู้ป่วยที่ Cortex Worklist 2. เก็บ Specimen / ฉายรังสี 3. Run Lab / IMG ไปยัง LIS / RIS 4. รับผลกลับเข้าระบบ | G37: No Pass | I37: Lab: 1. ไม่สามารถปริ้นป้ายติด Speciment ได้ {"error":{"class":"NotFound","message":"print template not found"}} 2. ไม่สามารถส่งผล Lab กลับมาได้ Imaging 1. ไม่สามารถพิมพ์ใบยิมยอมได้ไม่มี Template
A38: OPD/EMR | C38: แพทย์เจ้าของไข้ส่ง Consult ให้แพทย์ท่านอื่นอ่านผล | E38: 1. เลือกดูเมนู Consult ที่ Side bar ทางขวามือ 2. ระบบจะแสดงหน้ากรอกข้อมูลของ Consult ขึ้นมา 3. กรอกข้อมูลที่ต้องการลงไป 4. กดบันทึกเพื่อทำการส่งแบบฟอร์ม 5. ระบบจะแสดงสถานะ รอตอบกลับ | F38: Pass
A39: OPD/EMR | C39: แพทย์ท่านอื่นรับ Consult อ่านผล และตอบกลับ | E39: 1. กดปุ่มเมนู มุมบนขวา > เลือกเมนู ผู้ป่วยนอก > เลือกรายการปรึกษาแพทย์ 2. เลือกรับ Consult ระบบจะแสดงรายการที่มี Request เอาไว้ 3. เลือกรายการที่ต้องการตอบกลับ 4. เปิดดูผล Lab / IMG ของผู้ป่วย 5. กรอกข้อมูลที่ต้องการตอบกลับและกดปุ่มบันทึก 6. สถานะของรายการ Consult เปลี่ยนเป็นตอบแล้ว | F39: Pass | I39: 1. แพทย์ ไม่สามารถพิมพ์ สรุป ได้ "class": "IllegalArgumentException", "message": "Template not found: tmh_opd_summary", "detail": "INVALID_REQUEST"
A40: OPD/EMR | C40: แพทย์เจ้าของไข้ดูผลที่ตอบกลับและสรุปการรักษา | E40: 1. เลือก ส่ง Consult แล้วเลือกรายการที่สถานะ ตอบแล้ว 2. ระบบจะแสดงรายละเอียดการ Consult ที่แพทย์อีกท่านตอบกลับมา 3. ลง diagnosis เพิ่มเติม สั่งยากลับบ้าน และทำนัด FU 4. กดปุ่มตรวจเสร็จ | F40: Pass | I40: 1. ไม่สามารถพิิมพ์ใบสรุปใบให้คำปรึกษาได้ (ไม่มี Template) 2. ไม่สามารถพิมพ์ฟอร์มตอบกลับการให้คำปรึกษา (ไม่มี Template) 3. ไม่สามารถพิมพ์ OPD Slip (ไม่มี Template) - น่าจะหาย
...

Sheet List Flow E2E For BizSim(New)
A2: Use case Scenario
A3: Case_Id | B3: Scenario | C3: Status test | F3: NOTE
C4: Pass | D4: Fail | E4: N/A
A5: Appointment | B5: กลุ่ม Appointment - คนไข้มีนัดหมายล่วงหน้า (12 UC)
A6: APM-OPD-001 | B6: คนไข้มีนัดเข้ารับบริการปกติ (พบแพทย์ > ทำนัด FU > การเงิน > รับยา > กลับบ้าน)
A7: APM-OPD-002 | B7: คนไข้มีนัดเข้ารับบริการปกติ มีตรวจ LAB / IMG ก่อนพบแพทย์
A8: APM-OPD-003 | B8: คนไข้มีนัด แพทย์สั่งตรวจ LAB / IMG อ่านผลภายในวัน (แพทย์อ่านผลเอง / ฝากแพทย์ท่านอื่นอ่านผล)
A9: APM-OPD-005 | B9: คนไข้มีนัด ไม่มียากลับบ้าน
A10: APM-OPD-006 | B10: คนไข้มีนัด มียา co-pay / ยาที่ต้องมีเอกสารประกอบการสั่ง (DUE, PA) / CDSS แจ้งเตือน > จ่ายเงิน > รับยา
A11: APM-OPD-007 | B11: คนไข้มีนัด หมอสั่งยา Stat > จ่ายค่ายา > ฉีดยา > จ่ายเงิน > รับยากลับบ้าน
A12: APM-OPD-008 | B12: คนไข้มีนัด พบแพทย์ ทำหัตถการ (ภายในวัน / สั่งล่วงหน้า) > การเงิน > ห้องยา
A13: APM-OPD-009 | B13: คนไข้มีนัด พบแพทย์ หมอสั่ง Refill ยา
A14: APM-OPD-010 | B14: คนไข้ขอใบรับรองแพทย์ชนิดต่างๆ
A15: APM-OPD-011 | B15: คนไข้ขอเลื่อนนัดหมาย | G15: New
A16: APM-OPD-012 | B16: คนไข้ขอยกเลิกนัดหมาย | G16: New
A17: APM-OPD-013 | B17: คนไข้ไม่มาตามนัด (No-show) | G17: New
A18: Walk in | B18: กลุ่ม Walk in - คนไข้ไม่มีนัด หรือมาไม่ตรงนัด (5 UC)
A19: WLK-OPD-001 | B19: คนไข้ Walk in พบแพทย์ (พยาบาลทำ Pre-assessment จากหน้าคำขอ Walk-in · SBH-2699)
A20: WLK-OPD-002 | B20: คนไข้ Walk in ไม่ได้พบแพทย์ ทำนัดหมายแทน
A21: WLK-OPD-003 | B21: คนไข้มีนัด แต่มาไม่ตรงนัด
A22: WLK-OPD-004 | B22: คนไข้มาตรวจ Lab / IMG ล่วงหน้า (ก่อนวันนัดพบแพทย์)
A23: WLK-OPD-006 | B23: คนไข้ใหม่ (ยังไม่มี HN) ลงทะเบียนและเปิด Visit ครั้งแรก | G23: New
A24: Refill | B24: กลุ่ม Refill ยา - คนไข้มารับยาตามแผน Refill (2 UC)
A25: RFL-OPD-001 | B25: คนไข้มารับยา Refill ตรงวัน
A26: RFL-OPD-002 | B26: คนไข้มารับยา Refill ไม่ตรงวัน (มาก่อน / เลยกำหนด)
A27: Injection | B27: กลุ่มมีนัดฉีดยา / ฉีดวัคซีน / ทำแผล ไม่พบแพทย์ (1 UC)
A28: INJ-OPD-001 | B28: คนไข้มีนัดฉีดยา / ฉีดวัคซีน / ทำแผล ไม่พบแพทย์
A29: Admit | B29: กลุ่ม Admit - คนไข้ OPD ต้องนอนโรงพยาบาล (2 UC)
A30: ADM-OPD-001 | B30: คนไข้ Admit (ย้ายค่าใช้จ่ายจาก OPD ไป IPD)
A31: ADM-OPD-002 | B31: คนไข้ Admit สั่งตรวจก่อนขึ้น ward
A32: ODS | B32: กลุ่ม ODS - หัตถการ One Day Surgery (2 UC)
A33: ODS-OPD-001 | B33: คนไข้มาตรวจ หมอสั่ง ODS ภายในวัน
A34: ODS-OPD-002 | B34: หมอนัดมาทำ ODS วันอื่น
A35: Order | B35: กลุ่มคำสั่งการรักษา - Order Set / ยา Compound / รคส. / Remed / ค่าตรวจแพทย์ (5 UC)
A36: ORD-OPD-001 | B36: แพทย์สั่งการรักษาผ่าน Order Set (ยา + Lab + หัตถการ) > การเงิน > รับยา | G36: New
A37: ORD-OPD-002 | B37: แพทย์สั่งยา Compound (ยาผสม) > ห้องยา > การเงิน > รับยา | G37: New
A38: ORD-OPD-003 | B38: พยาบาลสั่ง Order แทนแพทย์ (รคส.) > แพทย์ยืนยันคำสั่ง > ห้องยา > การเงิน | G38: New
A39: ORD-OPD-004 | B39: พยาบาลทำ Med reconcile > แพทย์ Remed ยาเดิม > ห้องยา > การเงิน | G39: New
A40: ORD-OPD-005 | B40: แพทย์เพิ่มค่าตรวจแพทย์ (Doctor Fee) > ตรวจสอบที่การเงิน | G40: New
A41: Drug Label | B41: กลุ่มฉลากยา - ฉลากยาภาษาไทย / ภาษาอังกฤษ (2 UC)
...

Sheet Scenario-OPD BizSim(New)
A1: Case_id | B1: TOR_ID | C1: Use case Scenario | D1: Test case ID | E1: Test Step | F1: Status test | I1: NOTE
F2: Pass | G2: Fail | H2: N/A
A3: Appointment | C3: กลุ่ม Appointment - คนไข้มีนัดหมายล่วงหน้า
A4: APM-OPD-001 | C4: คนไข้มีนัดเข้ารับบริการปกติ (พบแพทย์ > ทำนัด FU > การเงิน > รับยา > กลับบ้าน)
A5: OPD/REG | C5: เปิด Visit ตามนัดหมาย | E5: 1. เข้าแอพ เวชระเบียน > ค้นหาผู้ป่วย 2. กรอก HN แล้วกด Enter 3. กดปุ่ม + Visit ใหม่ มุมขวาบน 4. ตรวจสอบข้อมูลนัดหมายของวันนี้ที่ระบบแสดง 5. ยืนยันสิทธิการรักษา 6. กดปุ่ม สร้าง 7. ตรวจสอบว่าได้เลข VN พิมพ์ใบนำทาง และได้เลขคิวห้องตรวจ
A6: OPD/EMR | C6: พยาบาลคัดกรองก่อนพบแพทย์ | E6: 1. เปิดผู้ป่วยจากหน้า รายการผู้ป่วยนอก 2. บันทึกสัญญาณชีพ (V/S) 3. เลือกดูเมนู ฟอร์มคัดกรอง ที่ Side bar ทางขวามือ 4. กรอกข้อมูลการคัดกรองและบันทึก 5. ตรวจสอบว่าค่า Vital sign แสดงบน Patient Banner
A7: OPD/EMR | C7: แพทย์เรียกคิวและลง OPD Note | E7: 1. กดเลือกคนไข้จากหน้า รายการผู้ป่วยนอก ที่สถานะพร้อมตรวจ 2. ระบบจะแสดง OPD Note ขึ้นมา 3. ลงข้อมูลการรักษา 4. ลง diagnosis 5. บันทึกข้อมูล
A8: OPD/CPOE | C8: แพทย์สั่งยากลับบ้าน (Home med) | E8: 1. ระบบจะแสดง Section ในส่วนของการ Order ขึ้นมา 2. ทำการสั่งยา เลือก Home med 3. ระบุวิธีการใช้ยา / จำนวนยาที่จ่าย / หมายเหตุอื่นๆ 4. กดปุ่ม เพิ่ม order 5. กดปุ่ม Sign เพื่อส่งคำสั่งไปห้องยา
A9: OPD/EMR | C9: แพทย์ทำนัดหมาย FU และกดตรวจเสร็จ | E9: 1. เลือกดูเมนู สร้างนัดหมาย ที่ Side bar ทางขวามือ 2. เลือก คลินิก แพทย์ ประเภทการนัดหมาย แล้ว Slot ที่ต้องการ 3. กดบันทึก 4. ตรวจสอบนัดหมายที่เมนู ประวัติการนัดหมาย 5. กดปุ่มตรวจเสร็จ
A10: OPD | C10: พยาบาล Discharge และปริ้นบัตรคิว | E10: 1. กดเลือกคนไข้จากหน้า รายการผู้ป่วยนอก ที่สถานะ ตรวจเสร็จ 2. เลือกประเภทการ Discharge เป็น กลับบ้าน 3. ปริ้นท์บัตรคิว การเงิน / ห้องยา ที่หน้า Discharge summary 4. ปริ้นท์บัตรนัดที่เมนู ประวัตินัดหมาย ที่ side bar ซ้ายมือ
A11: OPD/PHA | C11: ห้องยาสร้างใบยาก่อนชำระเงิน | E11: 1. ไปที่เมนูห้องยา > เลือกห้องยาชั้น 1 2. เลือกคนไข้และรายการยา แล้วกดปุ่มสร้างใบยา
A12: OPD/CASH | C12: คนไข้ชำระเงินที่การเงิน | E12: 1. เข้าหน้าการเงิน (Cashier) แล้วเปิดรายการของผู้ป่วยจากคิวการเงิน 2. ตรวจสอบ / แก้ไข Chart item สิทธิการรักษา และส่วนลด 3. สร้าง invoice 4. รับชำระเงินและออกใบเสร็จ 5. ปิดสิทธิ์ผ่าน EDC / End point
A13: OPD/PHA | C13: ห้องยาจัดยา เรียกคิว และจ่ายยา | E13: 1. ไปที่เมนูห้องยา > เลือกห้องยาชั้น 1 2. เลือกคนไข้และรายการยา 3. กดปุ่มจัดยาแล้ว 4. กดปุ่มยืนยันรอจ่าย 5. เรียกคิวคนไข้ที่ห้องยา 6. เลือก 3จุด ด้านหลังรายการยา แล้วเลือก ยืนยันจ่ายยา
A14: APM-OPD-002 | C14: คนไข้มีนัดเข้ารับบริการปกติ มีตรวจ LAB / IMG ก่อนพบแพทย์
A15: OPD/REG | C15: เปิด Visit ตามนัด และ Check-in ห้อง Lab / Img | E15: 1. เปิด Visit ตามนัดหมาย จนได้เลข VN 2. พิมพ์ใบนำทาง 3. กด Check-in ห้อง Lab / Img 4. ตรวจสอบเลขคิว Lab/X-ray ที่ระบบออกให้ 5. ตรวจสอบว่ารายการเข้าสู่ Worklist ของห้อง Lab/X-ray/Img
A16: OPD/LAB | C16: ห้อง Lab / Img รับรายการและออกผล | E16: 1. เข้า Cortex Worklist ของห้อง Lab/X-ray/Img 2. เลือกรายการผู้ป่วยแล้วกด Check-in 3. เก็บ Specimen และพิมพ์ Sticker (LN) ติด Tube (เฉพาะ Lab) 4. กด Run Lab / IMG ส่งไปยัง LIS / RIS 5. รับผลกลับเข้าระบบ 6. ให้แพทย์ Authorize ผล จนสถานะเป็นเสร็จสิ้น
A17: OPD/EMR | C17: พยาบาลคัดกรองและเช็คสถานะผล Lab / Img | E17: 1. บันทึกสัญญาณชีพ (V/S) และฟอร์มคัดกรอง 2. เลือกดูเมนู Lab Result / Imaging result ที่ Side bar ทางซ้ายมือ 3. ตรวจสอบว่าสถานะผลตรงกับสถานะจริงในห้อง Lab 4. ส่งผู้ป่วยเข้าคิวห้องตรวจ
A18: OPD/EMR | C18: แพทย์ดูผล Lab / IMG แล้วตรวจ | E18: 1. เรียกคิวผู้ป่วยเข้าห้องตรวจ 2. เลือกดูเมนู Lab Result และ Imaging result ที่ Side bar ทางซ้ายมือ 3. ตรวจสอบว่าผลตรงกับที่ห้อง Lab ส่งมา 4. ลง OPD Note และ diagnosis
A19: OPD/CPOE | C19: แพทย์สั่งยากลับบ้านและทำนัด FU | E19: 1. สั่งยา Home med และกด Sign 2. สร้างนัดหมาย FU 3. กดปุ่มตรวจเสร็จ
A20: OPD | C20: พยาบาล Discharge และปริ้นบัตรคิว | E20: 1. เลือกประเภทการ Discharge เป็น กลับบ้าน 2. ปริ้นท์บัตรคิว การเงิน / ห้องยา ที่หน้า Discharge summary 3. ปริ้นท์บัตรนัด
A21: OPD/CASH | C21: คนไข้ชำระเงิน (รวมค่า Lab / IMG) | E21: 1. เปิดรายการของผู้ป่วยจากคิวการเงิน 2. ตรวจสอบว่าค่า Lab / IMG ถูกรวมใน Chart item 3. สร้าง invoice และรับชำระเงิน 4. ปิดสิทธิ์ผ่าน EDC / End point
A22: OPD/PHA | C22: ห้องยาจัดยาและจ่ายยา | E22: 1. สร้างใบยา > จัดยา > ยืนยันรอจ่าย 2. เรียกคิวคนไข้ 3. ยืนยันจ่ายยา
A23: APM-OPD-003 | C23: คนไข้มีนัด แพทย์สั่งตรวจ LAB / IMG อ่านผลภายในวัน (แพทย์อ่านผลเอง / ฝากแพทย์ท่านอื่นอ่านผล)
A24: OPD/REG | C24: เปิด Visit ตามนัดหมาย | E24: 1. ค้นหาผู้ป่วยด้วย HN 2. กดปุ่ม + Visit ใหม่ และตรวจสอบนัดหมายของวันนี้ 3. ยืนยันสิทธิการรักษา แล้วกดปุ่ม สร้าง 4. พิมพ์ใบนำทางและเลขคิวห้องตรวจ
A25: OPD/EMR | C25: พยาบาลคัดกรองและแพทย์ตรวจ | E25: 1. บันทึก V/S และฟอร์มคัดกรอง 2. แพทย์เรียกคิวผู้ป่วยเข้าห้องตรวจ 3. ลงข้อมูลการรักษาและ diagnosis ใน OPD Note
A26: OPD/CPOE | C26: แพทย์สั่ง LAB ต้องการทราบผลภายในวันที่สั่ง | E26: 1. ค้นหารายการ lab ที่ต้องการสั่งใน order search 2. ระบบจะแสดงรายการที่กำหนดไว้ 3. เลือก Priority และ วันที่ต้องการทราบผลเป็นวันนี้ 4. ระบบจะไม่ให้เลือกวันที่เมื่อเลือกเป็นวันนี้ 5. กดปุ่มเพิ่ม order 6. กดปุ่ม Sign เพื่อส่งการสั่งไปยังห้องปฏิบัติการ
A27: OPD/CPOE | C27: แพทย์สั่ง IMG ต้องการทราบผลภายในวันที่สั่ง | E27: 1. ค้นหารายการ Img ที่ต้องการสั่งใน order search 2. เลือก Priority และ วันที่ต้องการทราบผลเป็นวันนี้ 3. กดปุ่มเพิ่ม order 4. กดปุ่ม Sign เพื่อส่งการสั่งไปยังห้องปฏิบัติการ
A28: OPD/LAB | C28: ห้อง Lab / Img ทำรายการและส่งผลกลับ | E28: 1. Check-in ผู้ป่วยที่ Cortex Worklist 2. เก็บ Specimen และพิมพ์ Sticker (เฉพาะ Lab) / ฉายรังสี (IMG) 3. กด Run Lab / IMG ส่งไปยัง LIS / RIS 4. รับผลกลับเข้าระบบ 5. แพทย์ Authorize ผล
A29: OPD/EMR | C29: กรณีแพทย์อ่านผลเอง: แพทย์อ่านผลและสรุปการรักษาภายในวัน | E29: 1. เรียกคนไข้กลับเข้าห้องตรวจ 2. เปิดดูผล Lab / IMG ที่ส่งกลับมา 3. ลง diagnosis เพิ่มเติมใน OPD Note 4. สั่งยากลับบ้าน 5. ทำนัดหมาย FU 6. กดปุ่มตรวจเสร็จ
